Workbook
Name methods: #REF!
Name Time: #REF!

Sheet Báo cáo hàng ngày
B1: Ngày kiểm tra | C1: 45597 | E1: Ngày giao dịch | F1: =TEXT(C1-1,"DD/mm/yyyy") -> 31/10/2024
B2: TEN_DOITAC | D2: KYAHAN | E2: SODU_QUYDOI | F2: LAISUAT | G2: Lãi suất tham chiếu | H2: Lãi suất tham chiếu lớn nhất | I2: Lãi suất tham chiếu nhỏ nhất
A3: STT | B3: Tên đối tác | C3: Hình thức giao dịch | D3: Kỳ hạn | E3: Giá trị (VND) | F3: Lãi suất giao dịch (%/năm) | G3: Lãi suất tham chiếu (%/năm) | H3: Lãi suất tham chiếu lớn nhất | I3: Lãi suất tham chiếu nhỏ nhất | J3: Hợp lý/Phi thị trường
A4: =ROW()-3 -> 1 | B4: =INDEX(Sheet1[#All],MATCH($F$1,Sheet1[[#All],[Ngày hiệu lực HĐ]],0),MATCH('Báo cáo hàng ngày'!$B$2,Sheet1[#Headers],0)) -> #N/A | D4: 7 | E4: 150000000000
B5: =INDEX(Sheet1[#All],MATCH($F$1,Sheet1[[#All],[Ngày hiệu lực HĐ]],0),MATCH('Báo cáo hàng ngày'!$B$2,Sheet1[#Headers],0)) -> #N/A | D5: 5 | E5: 150000000000
B6: =INDEX(Sheet1[#All],MATCH($F$1,Sheet1[[#All],[Ngày hiệu lực HĐ]],0),MATCH('Báo cáo hàng ngày'!$B$2,Sheet1[#Headers],0)) -> #N/A | D6: 6 | E6: 150000000000

Sheet Ghi chú
A1: Ghi chú
A5: Kiểm tra lãi suất phi thị trường đối với giao dịch MM (Sheet "Giao dịch MM")
A6: STT | B6: Nội dung | C6: Chi tiết
A7: Bước 1 | B7: Thu thập dữ liệu thị trường, giao dịch (Các sheet màu vàng) | C7: Dữ liệu thị trường: Thu thập dữ liệu Lãi suất VNIBOR từ Refinitive Dữ liệu giao dịch MM: Thu thập dữ liệu giao dịch MM của ngày báo cáo (Tên đối tác, loại tiền, Số tiền, Loại hình giao dịch, Kỳ hạn, Ngày giao dịch, Ngày đáo hạn,…)
A8: Bước 2 | B8: Xác định kỳ hạn chuẩn hay lẻ | C8: Căn cứ vào thông tin kỳ hạn của giao dịch Repo để xác định Kỳ hạn chuẩn/Lẻ theo Sheet "Bảng kỳ hạn" của kỳ hạn Repo
A9: Bước 3 | B9: Đối với kỳ hạn lẻ: Xác định Kỳ hạn VNIBOR chuẩn ngắn hơn (shorter) và Kỳ hạn VNIBOR chuẩn dài hơn (longer) Đối với kỳ hạn chuẩn: Chuyển sang bước 5 | C9: Nếu là kỳ hạn lẻ, căn cứ vào kỳ hạn của giao dịch MM để xác định Kỳ hạn VNIBOR chuẩn ngắn hơn (shorter) và Kỳ hạn VNIBOR chuẩn dài hơn (longer)
A10: Bước 4 | B10: Xác định Lãi suất của Kỳ hạn VNIBOR chuẩn ngắn hơn (shorter) và Kỳ hạn VNIBOR chuẩn dài hơn (longer) | C10: Sau khi xác định Kỳ hạn VNIBOR chuẩn ngắn hơn (shorter) và Kỳ hạn VNIBOR chuẩn dài hơn (longer)). Tiếp tục xác định Lãi suất của Kỳ hạn VNIBOR chuẩn (shorter) và Kỳ hạn VNIBOR chuẩn (longer) tại ngày báo cáo
A11: Bước 5 | B11: Tính toán Lãi suất tham chiếu | C11: Đối với kỳ hạn lẻ: Xác định bằng cách nội suy tuyến tính Lãi suất của Kỳ hạn VNIBOR chuẩn (shorter) và Kỳ hạn VNIBOR chuẩn (longer) Đối với kỳ hạn chuẩn: Lãi suất VNIBOR tại các thanh kỳ hạn chuẩn
A12: Bước 6 | B12: Xác định biên độ áp dụng cho từng kỳ hạn | C12: Đối với kỳ hạn lẻ: Xác định biên độ bằng cách nội suy tuyến tính Biên độ của Kỳ hạn VNIBOR chuẩn ngắn hơn (shorter) và Kỳ hạn VNIBOR chuẩn dài hơn (longer) tại Sheet "Biên độ áp dụng" Đối với kỳ hạn chuẩn: Biên độ của kỳ hạn chuẩn tại Sheet "Biên độ áp dụng" | D12: Biên độ áp dụng sẽ được tính toán định kỳ và áp dụng cho cả năm nên sẽ tính toán và nhập tay vào Sheet "Biên độ áp dụng"
A13: Bước 7 | B13: Xác định Khoảng lãi suất hợp lý | C13: Lãi suất tham chiếu lớn nhất: Lãi suất tham chiếu + Biên độ Lãi suất tham chiếu nhỏ nhất: Lãi suất tham chiếu - Biên độ
A14: Bước 8 | B14: Xác định xem giao dịch MM có nằm trong Khoảng lãi suất hợp lý hay không | C14: So sánh Lãi suất giao dịch với Khoảng lãi suất hợp lý: - Trường hợp 1: Nếu Lãi suất giao dịch nằm trong Khoảng lãi suất hợp lý => GD Hợp lý - Trường hợp 2: Lãi suất giao dịch thấp hơn Khoảng lãi suất hợp lý + Trường hợp 2.1: Nếu là giao dịch MM vay (VCBNeo đi vay/TCTD đi gửi MM cho VCBNeo) => GD có lợi cho VCBNeo + Trường hợp 2.2: Nếu là giao dịch MM gửi (VCBNeo đi gửi MM tại TCTD khác) => GD bất lợi cho VCBNeo - Trường hợp 3: Lãi suất giao dịch cao hơn Khoảng lãi suất hợp lý + Trường hợp 3.1: Nếu là giao dịch MM vay (VCBNeo đi vay/TCTD đi gửi MM cho VCBNeo) => GD bất lợi cho VCBNeo + Trường hợp 3.2: Nếu là giao dịch MM gửi (VCBNeo đi gửi MM tại TCTD khác) => GD có lợi cho VCBNeo
A15: Kiểm tra lãi suất phi thị trường đối với giao dịch Repo (Sheet "Giao dịch Repo")
A16: STT | B16: Nội dung | C16: Chi tiết
A17: Bước 1 | B17: Thu thập dữ liệu thị trường, giao dịch (Các sheet màu vàng) | C17: Dữ liệu thị trường: Thu thập dữ liệu Lãi suất Repo từ VBMA (VBMA’s short-term benchmark rates) do VBMA công bố tại trang web www.vbma.org.vn Dữ liệu giao dịch Repo: Thu thập dữ liệu giao dịch Repo của ngày báo cáo (Tên đối tác, loại tiền, Số tiền, Loại hình giao dịch, Kỳ hạn, Ngày giao dịch, Ngày đáo hạn,…)
A18: Bước 2 | B18: Xác định kỳ hạn chuẩn hay lẻ | C18: Căn cứ vào thông tin kỳ hạn của giao dịch Repo để xác định Kỳ hạn chuẩn/Lẻ theo Sheet "Bảng kỳ hạn" của kỳ hạn Repo
A19: Bước 3 | B19: Đối với kỳ hạn lẻ: Xác định Kỳ hạn Repo chuẩn ngắn hơn (shorter) và Kỳ hạn Repo chuẩn dài hơn (longer) Đối với kỳ hạn chuẩn: Chuyển sang bước 5 | C19: Nếu là kỳ hạn lẻ, căn cứ vào kỳ hạn của giao dịch Repo để xác định Kỳ hạn Repo chuẩn ngắn hơn (shorter) và Kỳ hạn Repo chuẩn dài hơn (longer)
A20: Bước 4 | B20: Xác định Lãi suất của Kỳ hạn Repo chuẩn ngắn hơn (shorter) và Kỳ hạn Repo chuẩn dài hơn (longer) | C20: Sau khi xác định Kỳ hạn Repo chuẩn ngắn hơn (shorter) và Kỳ hạn Repo chuẩn dài hơn (longer). Tiếp tục xác định Lãi suất của Kỳ hạn Repo chuẩn ngắn hơn (shorter) và Kỳ hạn Repo chuẩn dài hơn (longer) tại ngày báo cáo trong Sheet "Data Repo"
A21: Bước 5 | B21: Tính toán Lãi suất tham chiếu | C21: Đối với kỳ hạn lẻ: Xác định bằng cách nội suy tuyến tính Lãi suất của Kỳ hạn Repo chuẩn ngắn hơn (shorter) và Kỳ hạn Repo chuẩn dài hơn (longer) Đối với kỳ hạn chuẩn: Lãi suất Repo tại các thang kỳ hạn chuẩn tại Sheet "Data Repo"
A22: Bước 6 | B22: Xác định biên độ áp dụng cho từng kỳ hạn | C22: Đối với kỳ hạn lẻ: Xác định biên độ bằng cách nội suy tuyến tính Biên độ của Kỳ hạn Repo chuẩn ngắn hơn (shorter) và Kỳ hạn Repo chuẩn dài hơn (longer) tại Sheet "Biên độ áp dụng" Đối với kỳ hạn chuẩn: Biên độ của kỳ hạn chuẩn tại Sheet "Biên độ áp dụng"
A23: Bước 7 | B23: Xác định Khoảng lãi suất hợp lý | C23: Lãi suất tham chiếu lớn nhất: Lãi suất tham chiếu + Biên độ Lãi suất tham chiếu nhỏ nhất: Lãi suất tham chiếu - Biên độ
A24: Bước 8 | B24: Xác định xem giao dịch MM có nằm trong Khoảng lãi suất hợp lý hay không | C24: So sánh Lãi suất giao dịch với Khoảng lãi suất hợp lý: - Trường hợp 1: Nếu Lãi suất giao dịch nằm trong Khoảng lãi suất hợp lý => GD Hợp lý - Trường hợp 2: Lãi suất giao dịch thấp hơn Khoảng lãi suất hợp lý + Trường hợp 2.1: Nếu là giao dịch Repo => GD có lợi cho VCBNeo + Trường hợp 2.2: Nếu là giao dịch Reverse Repo => GD bất lợi cho VCBNeo - Trường hợp 3: Lãi suất giao dịch cao hơn Khoảng lãi suất hợp lý + Trường hợp 3.1: Nếu là giao dịch Repo => GD bất lợi cho VCBNeo + Trường hợp 3.2: Nếu là giao dịch Reverse Repo (VCBNeo đi gửi MM tại TCTD khác) => GD có lợi cho VCBNeo

Sheet Giao dịch MM
A1: Loại tiền | B1: Tên đối tác | C1: Số dư | D1: Hình thức giao dịch | E1: Kỳ hạn | F1: Lãi suất | G1: Ngày hiệu lực HĐ | H1: Ngày đáo hạn | I1: Mã kỳ hạn chuẩn | J1: Kỳ hạn VNIBOR chuẩn (shorter) | K1: Kỳ hạn VNIBOR chuẩn (longer) | L1: LS VNIBOR chuẩn (shorter) | M1: LS VNIBOR chuẩn (longer) | N1: Biên độ chuẩn (shorter) | O1: Biên độ chuẩn (longer) | P1: Biên độ | Q1: Lãi suất tham chiếu | R1: Lãi suất tham chiếu lớn nhất | S1: Lãi suất tham chiếu nhỏ nhất | T1: Đánh giá
A2: VND | B2: PV | C2: 200000000000 | D2: Lend | E2: 5 | F2: 4.2 | G2: 45771 | H2: 45776 | I2: =IFERROR(VLOOKUP(Sheet1[[#This Row],[Kỳ hạn]],'Thang kỳ hạn MM'!$A$1:$C$66,3,0),"Kỳ hạn lẻ") -> Kỳ hạn lẻ | J2: =IF(Sheet1[[#This Row],[Mã kỳ hạn chuẩn]]="Kỳ hạn lẻ",IFERROR( _xlfn.IFS(Sheet1[[#This Row],[Kỳ hạn]]>365,365, Sheet1[[#This Row],[Kỳ hạn]]>270,270, Sheet1[[#This Row],[Kỳ hạn]]>180,180, Sheet1[[#This Row],[Kỳ hạn]]>90,90, Sheet1[[#This Row],[Kỳ hạn]]>60,60, Sheet1[[#This Row],[Kỳ hạn]]>30,30, Sheet1[[#This Row],[Kỳ hạn]]>14,14, Sheet1[[#This Row],[Kỳ hạn]]>7,7, Sheet1[[#This Row],[Kỳ hạn]]>1,1),0),"") -> 1 | K2: =IF(Sheet1[[#This Row],[Mã kỳ hạn chuẩn]]="Kỳ hạn lẻ",IFERROR( _xlfn.IFS(Sheet1[[#This Row],[Kỳ hạn]]<1,1, Sheet1[[#This Row],[Kỳ hạn]]<7,7, Sheet1[[#This Row],[Kỳ hạn]]<14,14, Sheet1[[#This Row],[Kỳ hạn]]<30,30, Sheet1[[#This Row],[Kỳ hạn]]<60,60, Sheet1[[#This Row],[Kỳ hạn]]<90,90, Sheet1[[#This Row],[Kỳ hạn]]<180,180, Sheet1[[#This Row],[Kỳ hạn]]<270,270, Sheet1[[#This Row],[Kỳ hạn]]<365,365), 0),"") -> 7 | L2: =IF(Sheet1[[#This Row],[Mã kỳ hạn chuẩn]]="Kỳ hạn lẻ",_xlfn.SWITCH(Sheet1[[#This Row],[Kỳ hạn VNIBOR chuẩn (shorter)]],1,VLOOKUP(Sheet1[[#This Row],[Ngày hiệu lực HĐ]],'Data VNIBOR'!$A$1:$K$1254,3,0),7,VLOOKUP(Sheet1[[#This Row],[Ngày hiệu lực HĐ]],'Data VNIBOR'!$A$1:$K$1254,4,0),14,VLOOKUP(Sheet1[[#This Row],[Ngày hiệu lực HĐ]],'Data VNIBOR'!$A$1:$K$1254,5,0),30,VLOOKUP(Sheet1[[#This Row],[Ngày hiệu lực HĐ]],'Data VNIBOR'!$A$1:$K$1254,6,0),60,VLOOKUP(Sheet1[[#This Row],[Ngày hiệu lực HĐ]],'Data VNIBOR'!$A$1:$K$1254,7,0),90,VLOOKUP(Sheet1[[#This Row],[Ngày hiệu lực HĐ]],'Data VNIBOR'!$A$1:$K$1254,8,0),180,VLOOKUP(Sheet1[[#This Row],[Ngày hiệu lực HĐ]],'Data VNIBOR'!$A$1:$K$1254,9,0),270,VLOOKUP(Sheet1[[#This Row],[Ngày hiệu lực HĐ]],'Data VNIBOR'!$A$1:$K$1254,10,0),365,VLOOKUP(Sheet1[[#This Row],[Ngày hiệu lực HĐ]],'Data VNIBOR'!$A$1:$K$1254,11,0)),"") -> 3.33 | M2: =IF(Sheet1[[#This Row],[Mã kỳ hạn chuẩn]]="Kỳ hạn lẻ",_xlfn.SWITCH(Sheet1[[#This Row],[Kỳ hạn VNIBOR chuẩn (longer)]],1,VLOOKUP(Sheet1[[#This Row],[Ngày hiệu lực HĐ]],'Data VNIBOR'!$A$1:$K$1254,3,0),7,VLOOKUP(Sheet1[[#This Row],[Ngày hiệu lực HĐ]],'Data VNIBOR'!$A$1:$K$1254,4,0),14,VLOOKUP(Sheet1[[#This Row],[Ngày hiệu lực HĐ]],'Data VNIBOR'!$A$1:$K$1254,5,0),30,VLOOKUP(Sheet1[[#This Row],[Ngày hiệu lực HĐ]],'Data VNIBOR'!$A$1:$K$1254,6,0),60,VLOOKUP(Sheet1[[#This Row],[Ngày hiệu lực HĐ]],'Data VNIBOR'!$A$1:$K$1254,7,0),90,VLOOKUP(Sheet1[[#This Row],[Ngày hiệu lực HĐ]],'Data VNIBOR'!$A$1:$K$1254,8,0),180,VLOOKUP(Sheet1[[#This Row],[Ngày hiệu lực HĐ]],'Data VNIBOR'!$A$1:$K$1254,9,0),270,VLOOKUP(Sheet1[[#This Row],[Ngày hiệu lực HĐ]],'Data VNIBOR'!$A$1:$K$1254,10,0),365,VLOOKUP(Sheet1[[#This Row],[Ngày hiệu lực HĐ]],'Data VNIBOR'!$A$1:$K$1254,11,0)),"") -> 4.31 | N2: =IF(Sheet1[[#This Row],[Mã kỳ hạn chuẩn]]="Kỳ hạn lẻ",_xlfn.SWITCH(Sheet1[[#This Row],[Kỳ hạn VNIBOR chuẩn (shorter)]],1,'Biên độ MM, Repo'!$C$2,7,'Biên độ MM, Repo'!$C$3,14,'Biên độ MM, Repo'!$C$4,30,'Biên độ MM, Repo'!$C$5,60,'Biên độ MM, Repo'!$C$6,90,'Biên độ MM, Repo'!$C$7,180,'Biên độ MM, Repo'!$C$8,270,'Biên độ MM, Repo'!$C$9,365,'Biên độ MM, Repo'!$C$10),0) -> 1.035 | O2: =IF(Sheet1[[#This Row],[Mã kỳ hạn chuẩn]]="Kỳ hạn lẻ",_xlfn.SWITCH(Sheet1[[#This Row],[Kỳ hạn VNIBOR chuẩn (longer)]],1,'Biên độ MM, Repo'!$C$2,7,'Biên độ MM, Repo'!$C$3,14,'Biên độ MM, Repo'!$C$4,30,'Biên độ MM, Repo'!$C$5,60,'Biên độ MM, Repo'!$C$6,90,'Biên độ MM, Repo'!$C$7,180,'Biên độ MM, Repo'!$C$8,270,'Biên độ MM, Repo'!$C$9,365,'Biên độ MM, Repo'!$C$10),0) -> 0.86 | P2: =IF(Sheet1[[#This Row],[Mã kỳ hạn chuẩn]]="Kỳ hạn lẻ",_xlfn.FORECAST.LINEAR(Sheet1[[#This Row],[Kỳ hạn]],Sheet1[[#This Row],[Biên độ chuẩn (shorter)]:[Biên độ chuẩn (longer)]],Sheet1[[#This Row],[Kỳ hạn VNIBOR chuẩn (shorter)]:[Kỳ hạn VNIBOR chuẩn (longer)]]),VLOOKUP(Sheet1[[#This Row],[Mã kỳ hạn chuẩn]],'Biên độ MM, Repo'!$B$1:$D$10,2,0)) -> 0.91833333 | Q2: =IF(Sheet1[[#This Row],[Mã kỳ hạn chuẩn]]="Kỳ hạn lẻ",_xlfn.FORECAST.LINEAR(Sheet1[[#This Row],[Kỳ hạn]],Sheet1[[#This Row],[LS VNIBOR chuẩn (shorter)]:[LS VNIBOR chuẩn (longer)]],Sheet1[[#This Row],[Kỳ hạn VNIBOR chuẩn (shorter)]:[Kỳ hạn VNIBOR chuẩn (longer)]]),INDEX('Data VNIBOR'!$A$1:$K$1254,MATCH(Sheet1[[#This Row],[Ngày hiệu lực HĐ]],'Data VNIBOR'!$A$1:$A$1254,0),MATCH(Sheet1[[#This Row],[Mã kỳ hạn chuẩn]],'Data VNIBOR'!$A$1:$K$1,0))) -> 3.9833333 | R2: =Sheet1[[#This Row],[Lãi suất tham chiếu]]+Sheet1[[#This Row],[Biên độ]] -> 4.9016667 | S2: =Sheet1[[#This Row],[Lãi suất tham chiếu]]-Sheet1[[#This Row],[Biên độ]] -> 3.065 | T2: =IF(OR(Sheet1[[#This Row],[Lãi suất]]>Sheet1[[#This Row],[Lãi suất tham chiếu lớn nhất]],Sheet1[[#This Row],[Lãi suất]]<Sheet1[[#This Row],[Lãi suất tham chiếu nhỏ nhất]]),"Lãi suất phi thị trường","GD Hợp lý") -> GD Hợp lý
A3: VND | B3: VCB | C3: 200000000000 | D3: Lend | E3: 14 | F3: 4.2 | G3: 45772 | H3: 45786 | I3: =IFERROR(VLOOKUP(Sheet1[[#This Row],[Kỳ hạn]],'Thang kỳ hạn MM'!$A$1:$C$66,3,0),"Kỳ hạn lẻ") -> 2W | J3: =IF(Sheet1[[#This Row],[Mã kỳ hạn chuẩn]]="Kỳ hạn lẻ",IFERROR( _xlfn.IFS(Sheet1[[#This Row],[Kỳ hạn]]>365,365, Sheet1[[#This Row],[Kỳ hạn]]>270,270, Sheet1[[#This Row],[Kỳ hạn]]>180,180, Sheet1[[#This Row],[Kỳ hạn]]>90,90, Sheet1[[#This Row],[Kỳ hạn]]>60,60, Sheet1[[#This Row],[Kỳ hạn]]>30,30, Sheet1[[#This Row],[Kỳ hạn]]>14,14, Sheet1[[#This Row],[Kỳ hạn]]>7,7, Sheet1[[#This Row],[Kỳ hạn]]>1,1),0),"") | K3: =IF(Sheet1[[#This Row],[Mã kỳ hạn chuẩn]]="Kỳ hạn lẻ",IFERROR( _xlfn.IFS(Sheet1[[#This Row],[Kỳ hạn]]<1,1, Sheet1[[#This Row],[Kỳ hạn]]<7,7, Sheet1[[#This Row],[Kỳ hạn]]<14,14, Sheet1[[#This Row],[Kỳ hạn]]<30,30, Sheet1[[#This Row],[Kỳ hạn]]<60,60, Sheet1[[#This Row],[Kỳ hạn]]<90,90, Sheet1[[#This Row],[Kỳ hạn]]<180,180, Sheet1[[#This Row],[Kỳ hạn]]<270,270, Sheet1[[#This Row],[Kỳ hạn]]<365,365), 0),"") | L3: =IF(Sheet1[[#This Row],[Mã kỳ hạn chuẩn]]="Kỳ hạn lẻ",_xlfn.SWITCH(Sheet1[[#This Row],[Kỳ hạn VNIBOR chuẩn (shorter)]],1,VLOOKUP(Sheet1[[#This Row],[Ngày hiệu lực HĐ]],'Data VNIBOR'!$A$1:$K$1254,3,0),7,VLOOKUP(Sheet1[[#This Row],[Ngày hiệu lực HĐ]],'Data VNIBOR'!$A$1:$K$1254,4,0),14,VLOOKUP(Sheet1[[#This Row],[Ngày hiệu lực HĐ]],'Data VNIBOR'!$A$1:$K$1254,5,0),30,VLOOKUP(Sheet1[[#This Row],[Ngày hiệu lực HĐ]],'Data VNIBOR'!$A$1:$K$1254,6,0),60,VLOOKUP(Sheet1[[#This Row],[Ngày hiệu lực HĐ]],'Data VNIBOR'!$A$1:$K$1254,7,0),90,VLOOKUP(Sheet1[[#This Row],[Ngày hiệu lực HĐ]],'Data VNIBOR'!$A$1:$K$1254,8,0),180,VLOOKUP(Sheet1[[#This Row],[Ngày hiệu lực HĐ]],'Data VNIBOR'!$A$1:$K$1254,9,0),270,VLOOKUP(Sheet1[[#This Row],[Ngày hiệu lực HĐ]],'Data VNIBOR'!$A$1:$K$1254,10,0),365,VLOOKUP(Sheet1[[#This Row],[Ngày hiệu lực HĐ]],'Data VNIBOR'!$A$1:$K$1254,11,0)),"") | M3: =IF(Sheet1[[#This Row],[Mã kỳ hạn chuẩn]]="Kỳ hạn lẻ",_xlfn.SWITCH(Sheet1[[#This Row],[Kỳ hạn VNIBOR chuẩn (longer)]],1,VLOOKUP(Sheet1[[#This Row],[Ngày hiệu lực HĐ]],'Data VNIBOR'!$A$1:$K$1254,3,0),7,VLOOKUP(Sheet1[[#This Row],[Ngày hiệu lực HĐ]],'Data VNIBOR'!$A$1:$K$1254,4,0),14,VLOOKUP(Sheet1[[#This Row],[Ngày hiệu lực HĐ]],'Data VNIBOR'!$A$1:$K$1254,5,0),30,VLOOKUP(Sheet1[[#This Row],[Ngày hiệu lực HĐ]],'Data VNIBOR'!$A$1:$K$1254,6,0),60,VLOOKUP(Sheet1[[#This Row],[Ngày hiệu lực HĐ]],'Data VNIBOR'!$A$1:$K$1254,7,0),90,VLOOKUP(Sheet1[[#This Row],[Ngày hiệu lực HĐ]],'Data VNIBOR'!$A$1:$K$1254,8,0),180,VLOOKUP(Sheet1[[#This Row],[Ngày hiệu lực HĐ]],'Data VNIBOR'!$A$1:$K$1254,9,0),270,VLOOKUP(Sheet1[[#This Row],[Ngày hiệu lực HĐ]],'Data VNIBOR'!$A$1:$K$1254,10,0),365,VLOOKUP(Sheet1[[#This Row],[Ngày hiệu lực HĐ]],'Data VNIBOR'!$A$1:$K$1254,11,0)),"") | N3: =IF(Sheet1[[#This Row],[Mã kỳ hạn chuẩn]]="Kỳ hạn lẻ",_xlfn.SWITCH(Sheet1[[#This Row],[Kỳ hạn VNIBOR chuẩn (shorter)]],1,'Biên độ MM, Repo'!$C$2,7,'Biên độ MM, Repo'!$C$3,14,'Biên độ MM, Repo'!$C$4,30,'Biên độ MM, Repo'!$C$5,60,'Biên độ MM, Repo'!$C$6,90,'Biên độ MM, Repo'!$C$7,180,'Biên độ MM, Repo'!$C$8,270,'Biên độ MM, Repo'!$C$9,365,'Biên độ MM, Repo'!$C$10),0) -> 0 | O3: =IF(Sheet1[[#This Row],[Mã kỳ hạn chuẩn]]="Kỳ hạn lẻ",_xlfn.SWITCH(Sheet1[[#This Row],[Kỳ hạn VNIBOR chuẩn (longer)]],1,'Biên độ MM, Repo'!$C$2,7,'Biên độ MM, Repo'!$C$3,14,'Biên độ MM, Repo'!$C$4,30,'Biên độ MM, Repo'!$C$5,60,'Biên độ MM, Repo'!$C$6,90,'Biên độ MM, Repo'!$C$7,180,'Biên độ MM, Repo'!$C$8,270,'Biên độ MM, Repo'!$C$9,365,'Biên độ MM, Repo'!$C$10),0) -> 0 | P3: =IF(Sheet1[[#This Row],[Mã kỳ hạn chuẩn]]="Kỳ hạn lẻ",_xlfn.FORECAST.LINEAR(Sheet1[[#This Row],[Kỳ hạn]],Sheet1[[#This Row],[Biên độ chuẩn (shorter)]:[Biên độ chuẩn (longer)]],Sheet1[[#This Row],[Kỳ hạn VNIBOR chuẩn (shorter)]:[Kỳ hạn VNIBOR chuẩn (longer)]]),VLOOKUP(Sheet1[[#This Row],[Mã kỳ hạn chuẩn]],'Biên độ MM, Repo'!$B$1:$D$10,2,0)) -> 0.69 | Q3: =IF(Sheet1[[#This Row],[Mã kỳ hạn chuẩn]]="Kỳ hạn lẻ",_xlfn.FORECAST.LINEAR(Sheet1[[#This Row],[Kỳ hạn]],Sheet1[[#This Row],[LS VNIBOR chuẩn (shorter)]:[LS VNIBOR chuẩn (longer)]],Sheet1[[#This Row],[Kỳ hạn VNIBOR chuẩn (shorter)]:[Kỳ hạn VNIBOR chuẩn (longer)]]),INDEX('Data VNIBOR'!$A$1:$K$1254,MATCH(Sheet1[[#This Row],[Ngày hiệu lực HĐ]],'Data VNIBOR'!$A$1:$A$1254,0),MATCH(Sheet1[[#This Row],[Mã kỳ hạn chuẩn]],'Data VNIBOR'!$A$1:$K$1,0))) -> 4.28 | R3: =Sheet1[[#This Row],[Lãi suất tham chiếu]]+Sheet1[[#This Row],[Biên độ]] -> 4.97 | S3: =Sheet1[[#This Row],[Lãi suất tham chiếu]]-Sheet1[[#This Row],[Biên độ]] -> 3.59 | T3: =IF(OR(Sheet1[[#This Row],[Lãi suất]]>Sheet1[[#This Row],[Lãi suất tham chiếu lớn nhất]],Sheet1[[#This Row],[Lãi suất]]<Sheet1[[#This Row],[Lãi suất tham chiếu nhỏ nhất]]),"Lãi suất phi thị trường","GD Hợp lý") -> GD Hợp lý
A4: VND | B4: VIB | C4: 150000000000 | D4: Lend | E4: 1 | F4: 2.3 | G4: 45775 | H4: 45776 | I4: =IFERROR(VLOOKUP(Sheet1[[#This Row],[Kỳ hạn]],'Thang kỳ hạn MM'!$A$1:$C$66,3,0),"Kỳ hạn lẻ") -> ON | J4: =IF(Sheet1[[#This Row],[Mã kỳ hạn chuẩn]]="Kỳ hạn lẻ",IFERROR( _xlfn.IFS(Sheet1[[#This Row],[Kỳ hạn]]>365,365, Sheet1[[#This Row],[Kỳ hạn]]>270,270, Sheet1[[#This Row],[Kỳ hạn]]>180,180, Sheet1[[#This Row],[Kỳ hạn]]>90,90, Sheet1[[#This Row],[Kỳ hạn]]>60,60, Sheet1[[#This Row],[Kỳ hạn]]>30,30, Sheet1[[#This Row],[Kỳ hạn]]>14,14, Sheet1[[#This Row],[Kỳ hạn]]>7,7, Sheet1[[#This Row],[Kỳ hạn]]>1,1),0),"") | K4: =IF(Sheet1[[#This Row],[Mã kỳ hạn chuẩn]]="Kỳ hạn lẻ",IFERROR( _xlfn.IFS(Sheet1[[#This Row],[Kỳ hạn]]<1,1, Sheet1[[#This Row],[Kỳ hạn]]<7,7, Sheet1[[#This Row],[Kỳ hạn]]<14,14, Sheet1[[#This Row],[Kỳ hạn]]<30,30, Sheet1[[#This Row],[Kỳ hạn]]<60,60, Sheet1[[#This Row],[Kỳ hạn]]<90,90, Sheet1[[#This Row],[Kỳ hạn]]<180,180, Sheet1[[#This Row],[Kỳ hạn]]<270,270, Sheet1[[#This Row],[Kỳ hạn]]<365,365), 0),"") | L4: =IF(Sheet1[[#This Row],[Mã kỳ hạn chuẩn]]="Kỳ hạn lẻ",_xlfn.SWITCH(Sheet1[[#This Row],[Kỳ hạn VNIBOR chuẩn (shorter)]],1,VLOOKUP(Sheet1[[#This Row],[Ngày hiệu lực HĐ]],'Data VNIBOR'!$A$1:$K$1254,3,0),7,VLOOKUP(Sheet1[[#This Row],[Ngày hiệu lực HĐ]],'Data VNIBOR'!$A$1:$K$1254,4,0),14,VLOOKUP(Sheet1[[#This Row],[Ngày hiệu lực HĐ]],'Data VNIBOR'!$A$1:$K$1254,5,0),30,VLOOKUP(Sheet1[[#This Row],[Ngày hiệu lực HĐ]],'Data VNIBOR'!$A$1:$K$1254,6,0),60,VLOOKUP(Sheet1[[#This Row],[Ngày hiệu lực HĐ]],'Data VNIBOR'!$A$1:$K$1254,7,0),90,VLOOKUP(Sheet1[[#This Row],[Ngày hiệu lực HĐ]],'Data VNIBOR'!$A$1:$K$1254,8,0),180,VLOOKUP(Sheet1[[#This Row],[Ngày hiệu lực HĐ]],'Data VNIBOR'!$A$1:$K$1254,9,0),270,VLOOKUP(Sheet1[[#This Row],[Ngày hiệu lực HĐ]],'Data VNIBOR'!$A$1:$K$1254,10,0),365,VLOOKUP(Sheet1[[#This Row],[Ngày hiệu lực HĐ]],'Data VNIBOR'!$A$1:$K$1254,11,0)),"") | M4: =IF(Sheet1[[#This Row],[Mã kỳ hạn chuẩn]]="Kỳ hạn lẻ",_xlfn.SWITCH(Sheet1[[#This Row],[Kỳ hạn VNIBOR chuẩn (longer)]],1,VLOOKUP(Sheet1[[#This Row],[Ngày hiệu lực HĐ]],'Data VNIBOR'!$A$1:$K$1254,3,0),7,VLOOKUP(Sheet1[[#This Row],[Ngày hiệu lực HĐ]],'Data VNIBOR'!$A$1:$K$1254,4,0),14,VLOOKUP(Sheet1[[#This Row],[Ngày hiệu lực HĐ]],'Data VNIBOR'!$A$1:$K$1254,5,0),30,VLOOKUP(Sheet1[[#This Row],[Ngày hiệu lực HĐ]],'Data VNIBOR'!$A$1:$K$1254,6,0),60,VLOOKUP(Sheet1[[#This Row],[Ngày hiệu lực HĐ]],'Data VNIBOR'!$A$1:$K$1254,7,0),90,VLOOKUP(Sheet1[[#This Row],[Ngày hiệu lực HĐ]],'Data VNIBOR'!$A$1:$K$1254,8,0),180,VLOOKUP(Sheet1[[#This Row],[Ngày hiệu lực HĐ]],'Data VNIBOR'!$A$1:$K$1254,9,0),270,VLOOKUP(Sheet1[[#This Row],[Ngày hiệu lực HĐ]],'Data VNIBOR'!$A$1:$K$1254,10,0),365,VLOOKUP(Sheet1[[#This Row],[Ngày hiệu lực HĐ]],'Data VNIBOR'!$A$1:$K$1254,11,0)),"") | N4: =IF(Sheet1[[#This Row],[Mã kỳ hạn chuẩn]]="Kỳ hạn lẻ",_xlfn.SWITCH(Sheet1[[#This Row],[Kỳ hạn VNIBOR chuẩn (shorter)]],1,'Biên độ MM, Repo'!$C$2,7,'Biên độ MM, Repo'!$C$3,14,'Biên độ MM, Repo'!$C$4,30,'Biên độ MM, Repo'!$C$5,60,'Biên độ MM, Repo'!$C$6,90,'Biên độ MM, Repo'!$C$7,180,'Biên độ MM, Repo'!$C$8,270,'Biên độ MM, Repo'!$C$9,365,'Biên độ MM, Repo'!$C$10),0) -> 0 | O4: =IF(Sheet1[[#This Row],[Mã kỳ hạn chuẩn]]="Kỳ hạn lẻ",_xlfn.SWITCH(Sheet1[[#This Row],[Kỳ hạn VNIBOR chuẩn (longer)]],1,'Biên độ MM, Repo'!$C$2,7,'Biên độ MM, Repo'!$C$3,14,'Biên độ MM, Repo'!$C$4,30,'Biên độ MM, Repo'!$C$5,60,'Biên độ MM, Repo'!$C$6,90,'Biên độ MM, Repo'!$C$7,180,'Biên độ MM, Repo'!$C$8,270,'Biên độ MM, Repo'!$C$9,365,'Biên độ MM, Repo'!$C$10),0) -> 0 | P4: =IF(Sheet1[[#This Row],[Mã kỳ hạn chuẩn]]="Kỳ hạn lẻ",_xlfn.FORECAST.LINEAR(Sheet1[[#This Row],[Kỳ hạn]],Sheet1[[#This Row],[Biên độ chuẩn (shorter)]:[Biên độ chuẩn (longer)]],Sheet1[[#This Row],[Kỳ hạn VNIBOR chuẩn (shorter)]:[Kỳ hạn VNIBOR chuẩn (longer)]]),VLOOKUP(Sheet1[[#This Row],[Mã kỳ hạn chuẩn]],'Biên độ MM, Repo'!$B$1:$D$10,2,0)) -> 1.035 | Q4: =IF(Sheet1[[#This Row],[Mã kỳ hạn chuẩn]]="Kỳ hạn lẻ",_xlfn.FORECAST.LINEAR(Sheet1[[#This Row],[Kỳ hạn]],Sheet1[[#This Row],[LS VNIBOR chuẩn (shorter)]:[LS VNIBOR chuẩn (longer)]],Sheet1[[#This Row],[Kỳ hạn VNIBOR chuẩn (shorter)]:[Kỳ hạn VNIBOR chuẩn (longer)]]),INDEX('Data VNIBOR'!$A$1:$K$1254,MATCH(Sheet1[[#This Row],[Ngày hiệu lực HĐ]],'Data VNIBOR'!$A$1:$A$1254,0),MATCH(Sheet1[[#This Row],[Mã kỳ hạn chuẩn]],'Data VNIBOR'!$A$1:$K$1,0))) -> 2.5 | R4: =Sheet1[[#This Row],[Lãi suất tham chiếu]]+Sheet1[[#This Row],[Biên độ]] -> 3.535 | S4: =Sheet1[[#This Row],[Lãi suất tham chiếu]]-Sheet1[[#This Row],[Biên độ]] -> 1.465 | T4: =IF(OR(Sheet1[[#This Row],[Lãi suất]]>Sheet1[[#This Row],[Lãi suất tham chiếu lớn nhất]],Sheet1[[#This Row],[Lãi suất]]<Sheet1[[#This Row],[Lãi suất tham chiếu nhỏ nhất]]),"Lãi suất phi thị trường","GD Hợp lý") -> GD Hợp lý
A5: Thông tin giao dịch MM từ Sheet "Sao kê giao dịch MM" | I5: - Tìm mã kỳ hạn của GTCG theo Sheet "Thang kỳ hạn MM" | J5: =IF([@[Mã kỳ hạn chuẩn]]="Kỳ hạn lẻ";@IFERROR( IFS([@[Kỳ hạn]]>365;365; [@[Kỳ hạn]]>270;270; [@[Kỳ hạn]]>180;180; [@[Kỳ hạn]]>90;90; [@[Kỳ hạn]]>60;60; [@[Kỳ hạn]]>30;30; [@[Kỳ hạn]]>14;14; [@[Kỳ hạn]]>7;7; [@[Kỳ hạn]]>1;1);0);"") - Ý nghĩa: Tìm chặn dưới của Kỳ hạn (Cột E) (Ví dụ: Kỳ hạn là 5 thì chặn dưới là 1 và chặn trên là 7 dựa theo Sheet "Thang kỳ hạn MM") | K5: =IF([@[Mã kỳ hạn chuẩn]]="Kỳ hạn lẻ";@IFERROR( IFS([@[Kỳ hạn]]<1;1; [@[Kỳ hạn]]<7;7; [@[Kỳ hạn]]<14;14; [@[Kỳ hạn]]<30;30; [@[Kỳ hạn]]<60;60; [@[Kỳ hạn]]<90;90; [@[Kỳ hạn]]<180;180; [@[Kỳ hạn]]<270;270; [@[Kỳ hạn]]<365;365); 0);"") - Ý nghĩa: Tìm chặn trên của Kỳ hạn (Cột E) (Ví dụ: Kỳ hạn là 5 thì chặn dưới là 1 và chặn trên là 7 dựa theo Sheet "Thang kỳ hạn MM") | L5: - Tìm Lãi suất VNIBOR của Kỳ hạn VNIBOR chuẩn (shorter) tại Ngày hiệu lực HĐ (Cột G) trong Sheet "Data VNIBOR" | M5: - Tìm Lãi suất VNIBOR của Kỳ hạn VNIBOR chuẩn (longer) tại Ngày hiệu lực HĐ (Cột G) trong Sheet "Data VNIBOR" | N5: - Tìm biên độ MM của Kỳ hạn VNIBOR chuẩn (shorter) (Cột J) tại cột C trong Sheet "Biên độ MM, Repo" | O5: - Tìm biên độ MM của Kỳ hạn VNIBOR chuẩn (longer) (Cột K) tại cột C trong Sheet "Biên độ MM, Repo" | P5: - Kỳ hạn chuẩn: Lấy biên độ chuẩn tại Sheet "Biên độ MM, repo" - Kỳ hạn lẻ: Nội suy tuyến tính từ 2 biên độ phía trước =IF([@[Mã kỳ hạn chuẩn]]="Kỳ hạn lẻ";FORECAST.LINEAR([@[Kỳ hạn]];Sheet1[@[Biên độ chuẩn (shorter)]:[Biên độ chuẩn (longer)]];Sheet1[@[Kỳ hạn VNIBOR chuẩn (shorter)]:[Kỳ hạn VNIBOR chuẩn (longer)]]);VLOOKUP([@[Mã kỳ hạn chuẩn]];'Biên độ MM, Repo'!$B$1:$D$10;2;0)) | Q5: - Kỳ hạn lẻ: Nội suy tuyến tính từ Lãi suất VNIBOR (Shorter) và Lãi suất VNIBOR (Longer) đã tính phía trước - Kỳ hạn chuẩn: Tìm kiếm Lãi suất VNIBOR tại Ngày hiệu lực HĐ trong Sheet "Data VNIBOR" | R5: = Cột Q + biên độ | S5: = Cột Q - biên độ | T5: So sánh Lãi suất giao dịch với Khoảng lãi suất hợp lý: - Trường hợp 1: Nếu Lãi suất giao dịch nằm trong Khoảng lãi suất hợp lý => GD Hợp lý - Trường hợp 2: Lãi suất giao dịch thấp hơn Khoảng lãi suất hợp lý + Trường hợp 2.1: Nếu là giao dịch MM vay (VCBNeo đi vay/TCTD đi gửi MM cho VCBNeo) => GD có lợi cho VCBNeo + Trường hợp 2.2: Nếu là giao dịch MM gửi (VCBNeo đi gửi MM tại TCTD khác) => GD bất lợi cho VCBNeo - Trường hợp 3: Lãi suất giao dịch cao hơn Khoảng lãi suất hợp lý + Trường hợp 3.1: Nếu là giao dịch MM vay (VCBNeo đi vay/TCTD đi gửi MM cho VCBNeo) => GD bất lợi cho VCBNeo + Trường hợp 3.2: Nếu là giao dịch MM gửi (VCBNeo đi gửi MM tại TCTD khác) => GD có lợi cho VCBNeo
N14: A

Sheet Giao dịch Repo
A1: STT | B1: Loại giao dịch | C1: Mã GTCG | D1: Loại GTCG | E1: Loại tiền tệ | F1: Mệnh giá | G1: Ngày phát hành | H1: Ngày đáo hạn | I1: Kỳ hạn | J1: Đơn vị kỳ hạn | K1: Lãi suất phát hành | L1: Tên đối tác | M1: Số HĐMB | N1: Ngày hợp đồng | O1: Ngày giao dịch lần 1 | P1: Ngày thanh toán lần 1 | Q1: Số lượng mua/bán | R1: Tổng mệnh giá mua/bán | S1: Giá trị GDHD lần 1 | T1: Lãi suất repo | U1: Ngày giao dịch lần 2 | V1: Ngày thanh toán lần 2 | W1: Giá trị GDHD lần 2 | X1: Kỳ hạn còn lại | Y1: Mã kỳ hạn chuẩn | Z1: Kỳ hạn Repo chuẩn (shorter) | AA1: Kỳ hạn Repo chuẩn (longer) | AB1: LS Repo chuẩn (shorter) | AC1: LS Repo chuẩn (longer) | AD1: Biên độ chuẩn (shorter) | AE1: Biên độ chuẩn (longer) | AF1: Biên độ | AG1: Lãi suất tham chiếu | AH1: Lãi suất tham chiếu lớn nhất | AI1: Lãi suất tham chiếu nhỏ nhất | AJ1: Đánh giá QLRRTT
A2: 1 | B2: Hợp đồng bán có kỳ hạn GTCG | C2: HDBL2431009 | D2: Trái phiếu | E2: VND-Việt Nam đồng | F2: 1000000000 | G2: 45504 | H2: 48060 | I2: 7 | J2: Năm | K2: 7.475 | L2: 1000001002 - NH TMCP BAC A | M2: 28112024.04/REPO/BAB-CB | N2: 45624 | O2: 45624 | P2: 45624 | Q2: 50 | R2: 50000000000 | S2: 50947437000 | T2: 6.2 | U2: 45649 | V2: 45649 | W2: 51163198000 | X2: =Sheet_1[[#This Row],[Ngày giao dịch lần 2]]-Sheet_1[[#This Row],[Ngày giao dịch lần 1]] -> 25 | Y2: =IFERROR(VLOOKUP(Sheet_1[[#This Row],[Kỳ hạn còn lại]],'Thang kỳ hạn Repo'!$A$1:$B$63,2,0),"Kỳ hạn lẻ") -> Kỳ hạn lẻ | Z2: =IF(Sheet_1[[#This Row],[Mã kỳ hạn chuẩn]]="Kỳ hạn lẻ",IFERROR( _xlfn.IFS(Sheet_1[[#This Row],[Kỳ hạn còn lại]]>365,365, Sheet_1[[#This Row],[Kỳ hạn còn lại]]>270,270, Sheet_1[[#This Row],[Kỳ hạn còn lại]]>180,180, Sheet_1[[#This Row],[Kỳ hạn còn lại]]>90,90, Sheet_1[[#This Row],[Kỳ hạn còn lại]]>60,60, Sheet_1[[#This Row],[Kỳ hạn còn lại]]>30,30, Sheet_1[[#This Row],[Kỳ hạn còn lại]]>14,14, Sheet_1[[#This Row],[Kỳ hạn còn lại]]>7,7, Sheet_1[[#This Row],[Kỳ hạn còn lại]]>1,1),0),"") -> 14 | AA2: =IF(Sheet_1[[#This Row],[Mã kỳ hạn chuẩn]]="Kỳ hạn lẻ",IFERROR( _xlfn.IFS(Sheet_1[[#This Row],[Kỳ hạn còn lại]]<1,1, Sheet_1[[#This Row],[Kỳ hạn còn lại]]<7,7, Sheet_1[[#This Row],[Kỳ hạn còn lại]]<14,14, Sheet_1[[#This Row],[Kỳ hạn còn lại]]<30,30, Sheet_1[[#This Row],[Kỳ hạn còn lại]]<60,60, Sheet_1[[#This Row],[Kỳ hạn còn lại]]<90,90, Sheet_1[[#This Row],[Kỳ hạn còn lại]]<180,180, Sheet_1[[#This Row],[Kỳ hạn còn lại]]<270,270, Sheet_1[[#This Row],[Kỳ hạn còn lại]]<365,365), 0),"") -> 30 | AB2: =IF(Sheet_1[[#This Row],[Mã kỳ hạn chuẩn]]="Kỳ hạn lẻ",_xlfn.SWITCH(Sheet_1[[#This Row],[Kỳ hạn Repo chuẩn (shorter)]],14,VLOOKUP(Sheet_1[[#This Row],[Ngày giao dịch lần 1]],'Data Repo'!$A:$I,2,0),30,VLOOKUP(Sheet_1[[#This Row],[Ngày giao dịch lần 1]],'Data Repo'!$A:$I,3,0),60,VLOOKUP(Sheet_1[[#This Row],[Ngày giao dịch lần 1]],'Data Repo'!$A:$I,4,0),90,VLOOKUP(Sheet_1[[#This Row],[Ngày giao dịch lần 1]],'Data Repo'!$A:$I,5,0),180,VLOOKUP(Sheet_1[[#This Row],[Ngày giao dịch lần 1]],'Data Repo'!$A:$I,6,0),270,VLOOKUP(Sheet_1[[#This Row],[Ngày giao dịch lần 1]],'Data Repo'!$A:$I,7,0),365,VLOOKUP(Sheet_1[[#This Row],[Ngày giao dịch lần 1]],'Data Repo'!$A:$I,8,0)),"") -> 4.465 | AC2: =IF(Sheet_1[[#This Row],[Mã kỳ hạn chuẩn]]="Kỳ hạn lẻ",_xlfn.SWITCH(Sheet_1[[#This Row],[Kỳ hạn Repo chuẩn (longer)]],14,VLOOKUP(Sheet_1[[#This Row],[Ngày giao dịch lần 1]],'Data Repo'!$A:$I,2,0),30,VLOOKUP(Sheet_1[[#This Row],[Ngày giao dịch lần 1]],'Data Repo'!$A:$I,3,0),60,VLOOKUP(Sheet_1[[#This Row],[Ngày giao dịch lần 1]],'Data Repo'!$A:$I,4,0),90,VLOOKUP(Sheet_1[[#This Row],[Ngày giao dịch lần 1]],'Data Repo'!$A:$I,5,0),180,VLOOKUP(Sheet_1[[#This Row],[Ngày giao dịch lần 1]],'Data Repo'!$A:$I,6,0),270,VLOOKUP(Sheet_1[[#This Row],[Ngày giao dịch lần 1]],'Data Repo'!$A:$I,7,0),365,VLOOKUP(Sheet_1[[#This Row],[Ngày giao dịch lần 1]],'Data Repo'!$A:$I,8,0)),"") -> 4.468 | AD2: =IF(Sheet_1[[#This Row],[Mã kỳ hạn chuẩn]]="Kỳ hạn lẻ",_xlfn.SWITCH(Sheet_1[[#This Row],[Kỳ hạn Repo chuẩn (shorter)]],1,'Biên độ MM, Repo'!$D$2,7,'Biên độ MM, Repo'!$D$3,14,'Biên độ MM, Repo'!$D$4,21,'Biên độ MM, Repo'!#REF!,30,'Biên độ MM, Repo'!$D$5,60,'Biên độ MM, Repo'!$D$6,90,'Biên độ MM, Repo'!$D$7,180,'Biên độ MM, Repo'!$D$8,270,'Biên độ MM, Repo'!$D$9,365,'Biên độ MM, Repo'!$D$10),0) -> 0.516925 | AE2: =IF(Sheet_1[[#This Row],[Mã kỳ hạn chuẩn]]="Kỳ hạn lẻ",_xlfn.SWITCH(Sheet_1[[#This Row],[Kỳ hạn Repo chuẩn (longer)]],1,'Biên độ MM, Repo'!$D$2,7,'Biên độ MM, Repo'!$D$3,14,'Biên độ MM, Repo'!$D$4,21,'Biên độ MM, Repo'!#REF!,30,'Biên độ MM, Repo'!$D$5,60,'Biên độ MM, Repo'!$D$6,90,'Biên độ MM, Repo'!$D$7,180,'Biên độ MM, Repo'!$D$8,270,'Biên độ MM, Repo'!$D$9,365,'Biên độ MM, Repo'!$D$10),0) -> 0.48476818 | AF2: =IF(Sheet_1[[#This Row],[Mã kỳ hạn chuẩn]]="Kỳ hạn lẻ",_xlfn.FORECAST.LINEAR(Sheet_1[[#This Row],[Kỳ hạn còn lại]],Sheet_1[[#This Row],[Biên độ chuẩn (shorter)]:[Biên độ chuẩn (longer)]],Sheet_1[[#This Row],[Kỳ hạn Repo chuẩn (shorter)]:[Kỳ hạn Repo chuẩn (longer)]]),VLOOKUP(Sheet_1[[#This Row],[Mã kỳ hạn chuẩn]],'Biên độ MM, Repo'!$B$2:$D$10,3,0)) -> 0.49481719 | AG2: =IF(Sheet_1[[#This Row],[Mã kỳ hạn chuẩn]]="Kỳ hạn lẻ",_xlfn.FORECAST.LINEAR(Sheet_1[[#This Row],[Kỳ hạn còn lại]],Sheet_1[[#This Row],[LS Repo chuẩn (shorter)]:[LS Repo chuẩn (longer)]],Sheet_1[[#This Row],[Kỳ hạn Repo chuẩn (shorter)]:[Kỳ hạn Repo chuẩn (longer)]]),INDEX('Data Repo'!$A:$I,MATCH(Sheet_1[[#This Row],[Ngày giao dịch lần 1]],'Data Repo'!A:A,0),MATCH(Sheet_1[[#This Row],[Kỳ hạn còn lại]],'Data Repo'!$A$1:$I$1,0))) -> 4.4670625 | AH2: =Sheet_1[[#This Row],[Lãi suất tham chiếu]]+Sheet_1[[#This Row],[Biên độ]] -> 4.9618797 | AI2: =Sheet_1[[#This Row],[Lãi suất tham chiếu]]-Sheet_1[[#This Row],[Biên độ]] -> 3.9722453 | AJ2: =IF(Sheet_1[[#This Row],[Lãi suất repo]]>Sheet_1[[#This Row],[Lãi suất tham chiếu lớn nhất]],"Giao dịch bất lợi cho VCBNeo",IF(Sheet_1[[#This Row],[Lãi suất repo]]<Sheet_1[[#This Row],[Lãi suất tham chiếu nhỏ nhất]],"Giao dịch có lợi cho VCBNeo","GD Hợp lý")) -> Giao dịch bất lợi cho VCBNeo
A3: 2 | B3: Hợp đồng bán có kỳ hạn GTCG | C3: HDBL2431002 | D3: Trái phiếu | E3: VND-Việt Nam đồng | F3: 1000000000 | G3: 45450 | H3: 48006 | I3: 7 | J3: Năm | K3: 7.475 | L3: 1000001002 - NH TMCP BAC A | M3: 28112024.03/REPO/BAB-CB | N3: 45624 | O3: 45624 | P3: 45624 | Q3: 50 | R3: 50000000000 | S3: 51572712700 | T3: 6.2 | U3: 45649 | V3: 45649 | W3: 51791121750 | X3: =Sheet_1[[#This Row],[Ngày giao dịch lần 2]]-Sheet_1[[#This Row],[Ngày giao dịch lần 1]] -> 25 | Y3: =IFERROR(VLOOKUP(Sheet_1[[#This Row],[Kỳ hạn còn lại]],'Thang kỳ hạn Repo'!$A$1:$B$63,2,0),"Kỳ hạn lẻ") -> Kỳ hạn lẻ | Z3: =IF(Sheet_1[[#This Row],[Mã kỳ hạn chuẩn]]="Kỳ hạn lẻ",IFERROR( _xlfn.IFS(Sheet_1[[#This Row],[Kỳ hạn còn lại]]>365,365, Sheet_1[[#This Row],[Kỳ hạn còn lại]]>270,270, Sheet_1[[#This Row],[Kỳ hạn còn lại]]>180,180, Sheet_1[[#This Row],[Kỳ hạn còn lại]]>90,90, Sheet_1[[#This Row],[Kỳ hạn còn lại]]>60,60, Sheet_1[[#This Row],[Kỳ hạn còn lại]]>30,30, Sheet_1[[#This Row],[Kỳ hạn còn lại]]>14,14, Sheet_1[[#This Row],[Kỳ hạn còn lại]]>7,7, Sheet_1[[#This Row],[Kỳ hạn còn lại]]>1,1),0),"") -> 14 | AA3: =IF(Sheet_1[[#This Row],[Mã kỳ hạn chuẩn]]="Kỳ hạn lẻ",IFERROR( _xlfn.IFS(Sheet_1[[#This Row],[Kỳ hạn còn lại]]<1,1, Sheet_1[[#This Row],[Kỳ hạn còn lại]]<7,7, Sheet_1[[#This Row],[Kỳ hạn còn lại]]<14,14, Sheet_1[[#This Row],[Kỳ hạn còn lại]]<30,30, Sheet_1[[#This Row],[Kỳ hạn còn lại]]<60,60, Sheet_1[[#This Row],[Kỳ hạn còn lại]]<90,90, Sheet_1[[#This Row],[Kỳ hạn còn lại]]<180,180, Sheet_1[[#This Row],[Kỳ hạn còn lại]]<270,270, Sheet_1[[#This Row],[Kỳ hạn còn lại]]<365,365), 0),"") -> 30 | AB3: =IF(Sheet_1[[#This Row],[Mã kỳ hạn chuẩn]]="Kỳ hạn lẻ",_xlfn.SWITCH(Sheet_1[[#This Row],[Kỳ hạn Repo chuẩn (shorter)]],14,VLOOKUP(Sheet_1[[#This Row],[Ngày giao dịch lần 1]],'Data Repo'!$A:$I,2,0),30,VLOOKUP(Sheet_1[[#This Row],[Ngày giao dịch lần 1]],'Data Repo'!$A:$I,3,0),60,VLOOKUP(Sheet_1[[#This Row],[Ngày giao dịch lần 1]],'Data Repo'!$A:$I,4,0),90,VLOOKUP(Sheet_1[[#This Row],[Ngày giao dịch lần 1]],'Data Repo'!$A:$I,5,0),180,VLOOKUP(Sheet_1[[#This Row],[Ngày giao dịch lần 1]],'Data Repo'!$A:$I,6,0),270,VLOOKUP(Sheet_1[[#This Row],[Ngày giao dịch lần 1]],'Data Repo'!$A:$I,7,0),365,VLOOKUP(Sheet_1[[#This Row],[Ngày giao dịch lần 1]],'Data Repo'!$A:$I,8,0)),"") -> 4.465 | AC3: =IF(Sheet_1[[#This Row],[Mã kỳ hạn chuẩn]]="Kỳ hạn lẻ",_xlfn.SWITCH(Sheet_1[[#This Row],[Kỳ hạn Repo chuẩn (longer)]],14,VLOOKUP(Sheet_1[[#This Row],[Ngày giao dịch lần 1]],'Data Repo'!$A:$I,2,0),30,VLOOKUP(Sheet_1[[#This Row],[Ngày giao dịch lần 1]],'Data Repo'!$A:$I,3,0),60,VLOOKUP(Sheet_1[[#This Row],[Ngày giao dịch lần 1]],'Data Repo'!$A:$I,4,0),90,VLOOKUP(Sheet_1[[#This Row],[Ngày giao dịch lần 1]],'Data Repo'!$A:$I,5,0),180,VLOOKUP(Sheet_1[[#This Row],[Ngày giao dịch lần 1]],'Data Repo'!$A:$I,6,0),270,VLOOKUP(Sheet_1[[#This Row],[Ngày giao dịch lần 1]],'Data Repo'!$A:$I,7,0),365,VLOOKUP(Sheet_1[[#This Row],[Ngày giao dịch lần 1]],'Data Repo'!$A:$I,8,0)),"") -> 4.468 | AD3: =IF(Sheet_1[[#This Row],[Mã kỳ hạn chuẩn]]="Kỳ hạn lẻ",_xlfn.SWITCH(Sheet_1[[#This Row],[Kỳ hạn Repo chuẩn (shorter)]],1,'Biên độ MM, Repo'!$D$2,7,'Biên độ MM, Repo'!$D$3,14,'Biên độ MM, Repo'!$D$4,21,'Biên độ MM, Repo'!#REF!,30,'Biên độ MM, Repo'!$D$5,60,'Biên độ MM, Repo'!$D$6,90,'Biên độ MM, Repo'!$D$7,180,'Biên độ MM, Repo'!$D$8,270,'Biên độ MM, Repo'!$D$9,365,'Biên độ MM, Repo'!$D$10),0) -> 0.516925 | AE3: =IF(Sheet_1[[#This Row],[Mã kỳ hạn chuẩn]]="Kỳ hạn lẻ",_xlfn.SWITCH(Sheet_1[[#This Row],[Kỳ hạn Repo chuẩn (longer)]],1,'Biên độ MM, Repo'!$D$2,7,'Biên độ MM, Repo'!$D$3,14,'Biên độ MM, Repo'!$D$4,21,'Biên độ MM, Repo'!#REF!,30,'Biên độ MM, Repo'!$D$5,60,'Biên độ MM, Repo'!$D$6,90,'Biên độ MM, Repo'!$D$7,180,'Biên độ MM, Repo'!$D$8,270,'Biên độ MM, Repo'!$D$9,365,'Biên độ MM, Repo'!$D$10),0) -> 0.48476818 | AF3: =IF(Sheet_1[[#This Row],[Mã kỳ hạn chuẩn]]="Kỳ hạn lẻ",_xlfn.FORECAST.LINEAR(Sheet_1[[#This Row],[Kỳ hạn còn lại]],Sheet_1[[#This Row],[Biên độ chuẩn (shorter)]:[Biên độ chuẩn (longer)]],Sheet_1[[#This Row],[Kỳ hạn Repo chuẩn (shorter)]:[Kỳ hạn Repo chuẩn (longer)]]),VLOOKUP(Sheet_1[[#This Row],[Mã kỳ hạn chuẩn]],'Biên độ MM, Repo'!$B$2:$D$10,3,0)) -> 0.49481719 | AG3: =IF(Sheet_1[[#This Row],[Mã kỳ hạn chuẩn]]="Kỳ hạn lẻ",_xlfn.FORECAST.LINEAR(Sheet_1[[#This Row],[Kỳ hạn còn lại]],Sheet_1[[#This Row],[LS Repo chuẩn (shorter)]:[LS Repo chuẩn (longer)]],Sheet_1[[#This Row],[Kỳ hạn Repo chuẩn (shorter)]:[Kỳ hạn Repo chuẩn (longer)]]),INDEX('Data Repo'!$A:$I,MATCH(Sheet_1[[#This Row],[Ngày giao dịch lần 1]],'Data Repo'!A:A,0),MATCH(Sheet_1[[#This Row],[Kỳ hạn còn lại]],'Data Repo'!$A$1:$I$1,0))) -> 4.4670625 | AH3: =Sheet_1[[#This Row],[Lãi suất tham chiếu]]+Sheet_1[[#This Row],[Biên độ]] -> 4.9618797 | AI3: =Sheet_1[[#This Row],[Lãi suất tham chiếu]]-Sheet_1[[#This Row],[Biên độ]] -> 3.9722453 | AJ3: =IF(Sheet_1[[#This Row],[Lãi suất repo]]>Sheet_1[[#This Row],[Lãi suất tham chiếu lớn nhất]],"Giao dịch bất lợi cho VCBNeo",IF(Sheet_1[[#This Row],[Lãi suất repo]]<Sheet_1[[#This Row],[Lãi suất tham chiếu nhỏ nhất]],"Giao dịch có lợi cho VCBNeo","GD Hợp lý")) -> Giao dịch bất lợi cho VCBNeo
A4: 3 | B4: Hợp đồng bán có kỳ hạn GTCG | C4: HDBL2431002 | D4: Trái phiếu | E4: VND-Việt Nam đồng | F4: 1000000000 | G4: 45450 | H4: 48006 | I4: 7 | J4: Năm | K4: 7.475 | L4: 1000001002 - NH TMCP BAC A | M4: 28112024.03/ REPO/BAB-CB | N4: 45624 | O4: 45624 | P4: 45624 | Q4: 50 | R4: 50000000000 | S4: 51572712700 | T4: 6.2 | U4: 45649 | V4: 45649 | W4: 51791121750 | X4: =Sheet_1[[#This Row],[Ngày giao dịch lần 2]]-Sheet_1[[#This Row],[Ngày giao dịch lần 1]] -> 25 | Y4: =IFERROR(VLOOKUP(Sheet_1[[#This Row],[Kỳ hạn còn lại]],'Thang kỳ hạn Repo'!$A$1:$B$63,2,0),"Kỳ hạn lẻ") -> Kỳ hạn lẻ | Z4: =IF(Sheet_1[[#This Row],[Mã kỳ hạn chuẩn]]="Kỳ hạn lẻ",IFERROR( _xlfn.IFS(Sheet_1[[#This Row],[Kỳ hạn còn lại]]>365,365, Sheet_1[[#This Row],[Kỳ hạn còn lại]]>270,270, Sheet_1[[#This Row],[Kỳ hạn còn lại]]>180,180, Sheet_1[[#This Row],[Kỳ hạn còn lại]]>90,90, Sheet_1[[#This Row],[Kỳ hạn còn lại]]>60,60, Sheet_1[[#This Row],[Kỳ hạn còn lại]]>30,30, Sheet_1[[#This Row],[Kỳ hạn còn lại]]>14,14, Sheet_1[[#This Row],[Kỳ hạn còn lại]]>7,7, Sheet_1[[#This Row],[Kỳ hạn còn lại]]>1,1),0),"") -> 14 | AA4: =IF(Sheet_1[[#This Row],[Mã kỳ hạn chuẩn]]="Kỳ hạn lẻ",IFERROR( _xlfn.IFS(Sheet_1[[#This Row],[Kỳ hạn còn lại]]<1,1, Sheet_1[[#This Row],[Kỳ hạn còn lại]]<7,7, Sheet_1[[#This Row],[Kỳ hạn còn lại]]<14,14, Sheet_1[[#This Row],[Kỳ hạn còn lại]]<30,30, Sheet_1[[#This Row],[Kỳ hạn còn lại]]<60,60, Sheet_1[[#This Row],[Kỳ hạn còn lại]]<90,90, Sheet_1[[#This Row],[Kỳ hạn còn lại]]<180,180, Sheet_1[[#This Row],[Kỳ hạn còn lại]]<270,270, Sheet_1[[#This Row],[Kỳ hạn còn lại]]<365,365), 0),"") -> 30 | AB4: =IF(Sheet_1[[#This Row],[Mã kỳ hạn chuẩn]]="Kỳ hạn lẻ",_xlfn.SWITCH(Sheet_1[[#This Row],[Kỳ hạn Repo chuẩn (shorter)]],14,VLOOKUP(Sheet_1[[#This Row],[Ngày giao dịch lần 1]],'Data Repo'!$A:$I,2,0),30,VLOOKUP(Sheet_1[[#This Row],[Ngày giao dịch lần 1]],'Data Repo'!$A:$I,3,0),60,VLOOKUP(Sheet_1[[#This Row],[Ngày giao dịch lần 1]],'Data Repo'!$A:$I,4,0),90,VLOOKUP(Sheet_1[[#This Row],[Ngày giao dịch lần 1]],'Data Repo'!$A:$I,5,0),180,VLOOKUP(Sheet_1[[#This Row],[Ngày giao dịch lần 1]],'Data Repo'!$A:$I,6,0),270,VLOOKUP(Sheet_1[[#This Row],[Ngày giao dịch lần 1]],'Data Repo'!$A:$I,7,0),365,VLOOKUP(Sheet_1[[#This Row],[Ngày giao dịch lần 1]],'Data Repo'!$A:$I,8,0)),"") -> 4.465 | AC4: =IF(Sheet_1[[#This Row],[Mã kỳ hạn chuẩn]]="Kỳ hạn lẻ",_xlfn.SWITCH(Sheet_1[[#This Row],[Kỳ hạn Repo chuẩn (longer)]],14,VLOOKUP(Sheet_1[[#This Row],[Ngày giao dịch lần 1]],'Data Repo'!$A:$I,2,0),30,VLOOKUP(Sheet_1[[#This Row],[Ngày giao dịch lần 1]],'Data Repo'!$A:$I,3,0),60,VLOOKUP(Sheet_1[[#This Row],[Ngày giao dịch lần 1]],'Data Repo'!$A:$I,4,0),90,VLOOKUP(Sheet_1[[#This Row],[Ngày giao dịch lần 1]],'Data Repo'!$A:$I,5,0),180,VLOOKUP(Sheet_1[[#This Row],[Ngày giao dịch lần 1]],'Data Repo'!$A:$I,6,0),270,VLOOKUP(Sheet_1[[#This Row],[Ngày giao dịch lần 1]],'Data Repo'!$A:$I,7,0),365,VLOOKUP(Sheet_1[[#This Row],[Ngày giao dịch lần 1]],'Data Repo'!$A:$I,8,0)),"") -> 4.468 | AD4: =IF(Sheet_1[[#This Row],[Mã kỳ hạn chuẩn]]="Kỳ hạn lẻ",_xlfn.SWITCH(Sheet_1[[#This Row],[Kỳ hạn Repo chuẩn (shorter)]],1,'Biên độ MM, Repo'!$D$2,7,'Biên độ MM, Repo'!$D$3,14,'Biên độ MM, Repo'!$D$4,21,'Biên độ MM, Repo'!#REF!,30,'Biên độ MM, Repo'!$D$5,60,'Biên độ MM, Repo'!$D$6,90,'Biên độ MM, Repo'!$D$7,180,'Biên độ MM, Repo'!$D$8,270,'Biên độ MM, Repo'!$D$9,365,'Biên độ MM, Repo'!$D$10),0) -> 0.516925 | AE4: =IF(Sheet_1[[#This Row],[Mã kỳ hạn chuẩn]]="Kỳ hạn lẻ",_xlfn.SWITCH(Sheet_1[[#This Row],[Kỳ hạn Repo chuẩn (longer)]],1,'Biên độ MM, Repo'!$D$2,7,'Biên độ MM, Repo'!$D$3,14,'Biên độ MM, Repo'!$D$4,21,'Biên độ MM, Repo'!#REF!,30,'Biên độ MM, Repo'!$D$5,60,'Biên độ MM, Repo'!$D$6,90,'Biên độ MM, Repo'!$D$7,180,'Biên độ MM, Repo'!$D$8,270,'Biên độ MM, Repo'!$D$9,365,'Biên độ MM, Repo'!$D$10),0) -> 0.48476818 | AF4: =IF(Sheet_1[[#This Row],[Mã kỳ hạn chuẩn]]="Kỳ hạn lẻ",_xlfn.FORECAST.LINEAR(Sheet_1[[#This Row],[Kỳ hạn còn lại]],Sheet_1[[#This Row],[Biên độ chuẩn (shorter)]:[Biên độ chuẩn (longer)]],Sheet_1[[#This Row],[Kỳ hạn Repo chuẩn (shorter)]:[Kỳ hạn Repo chuẩn (longer)]]),VLOOKUP(Sheet_1[[#This Row],[Mã kỳ hạn chuẩn]],'Biên độ MM, Repo'!$B$2:$D$10,3,0)) -> 0.49481719 | AG4: =IF(Sheet_1[[#This Row],[Mã kỳ hạn chuẩn]]="Kỳ hạn lẻ",_xlfn.FORECAST.LINEAR(Sheet_1[[#This Row],[Kỳ hạn còn lại]],Sheet_1[[#This Row],[LS Repo chuẩn (shorter)]:[LS Repo chuẩn (longer)]],Sheet_1[[#This Row],[Kỳ hạn Repo chuẩn (shorter)]:[Kỳ hạn Repo chuẩn (longer)]]),INDEX('Data Repo'!$A:$I,MATCH(Sheet_1[[#This Row],[Ngày giao dịch lần 1]],'Data Repo'!A:A,0),MATCH(Sheet_1[[#This Row],[Kỳ hạn còn lại]],'Data Repo'!$A$1:$I$1,0))) -> 4.4670625 | AH4: =Sheet_1[[#This Row],[Lãi suất tham chiếu]]+Sheet_1[[#This Row],[Biên độ]] -> 4.9618797 | AI4: =Sheet_1[[#This Row],[Lãi suất tham chiếu]]-Sheet_1[[#This Row],[Biên độ]] -> 3.9722453 | AJ4: =IF(Sheet_1[[#This Row],[Lãi suất repo]]>Sheet_1[[#This Row],[Lãi suất tham chiếu lớn nhất]],"Giao dịch bất lợi cho VCBNeo",IF(Sheet_1[[#This Row],[Lãi suất repo]]<Sheet_1[[#This Row],[Lãi suất tham chiếu nhỏ nhất]],"Giao dịch có lợi cho VCBNeo","GD Hợp lý")) -> Giao dịch bất lợi cho VCBNeo
A5: 4 | B5: Hợp đồng bán có kỳ hạn GTCG | C5: LPBL2431001 | D5: Trái phiếu | E5: VND-Việt Nam đồng | F5: 1000000000 | G5: 45527 | H5: 48083 | I5: 7 | J5: Năm | K5: 7.575 | L5: 1000001002 - NH TMCP BAC A | M5: 25112024.01/REPO/BAB-CB | N5: 45621 | O5: 45621 | P5: 45621 | Q5: 150 | R5: 150000000000 | S5: 153202902750 | T5: 5.8 | U5: 45651 | V5: 45651 | W5: 153931244400 | X5: =Sheet_1[[#This Row],[Ngày giao dịch lần 2]]-Sheet_1[[#This Row],[Ngày giao dịch lần 1]] -> 30 | Y5: =IFERROR(VLOOKUP(Sheet_1[[#This Row],[Kỳ hạn còn lại]],'Thang kỳ hạn Repo'!$A$1:$B$63,2,0),"Kỳ hạn lẻ") -> 1M | Z5: =IF(Sheet_1[[#This Row],[Mã kỳ hạn chuẩn]]="Kỳ hạn lẻ",IFERROR( _xlfn.IFS(Sheet_1[[#This Row],[Kỳ hạn còn lại]]>365,365, Sheet_1[[#This Row],[Kỳ hạn còn lại]]>270,270, Sheet_1[[#This Row],[Kỳ hạn còn lại]]>180,180, Sheet_1[[#This Row],[Kỳ hạn còn lại]]>90,90, Sheet_1[[#This Row],[Kỳ hạn còn lại]]>60,60, Sheet_1[[#This Row],[Kỳ hạn còn lại]]>30,30, Sheet_1[[#This Row],[Kỳ hạn còn lại]]>14,14, Sheet_1[[#This Row],[Kỳ hạn còn lại]]>7,7, Sheet_1[[#This Row],[Kỳ hạn còn lại]]>1,1),0),"") | AA5: =IF(Sheet_1[[#This Row],[Mã kỳ hạn chuẩn]]="Kỳ hạn lẻ",IFERROR( _xlfn.IFS(Sheet_1[[#This Row],[Kỳ hạn còn lại]]<1,1, Sheet_1[[#This Row],[Kỳ hạn còn lại]]<7,7, Sheet_1[[#This Row],[Kỳ hạn còn lại]]<14,14, Sheet_1[[#This Row],[Kỳ hạn còn lại]]<30,30, Sheet_1[[#This Row],[Kỳ hạn còn lại]]<60,60, Sheet_1[[#This Row],[Kỳ hạn còn lại]]<90,90, Sheet_1[[#This Row],[Kỳ hạn còn lại]]<180,180, Sheet_1[[#This Row],[Kỳ hạn còn lại]]<270,270, Sheet_1[[#This Row],[Kỳ hạn còn lại]]<365,365), 0),"") | AB5: =IF(Sheet_1[[#This Row],[Mã kỳ hạn chuẩn]]="Kỳ hạn lẻ",_xlfn.SWITCH(Sheet_1[[#This Row],[Kỳ hạn Repo chuẩn (shorter)]],14,VLOOKUP(Sheet_1[[#This Row],[Ngày giao dịch lần 1]],'Data Repo'!$A:$I,2,0),30,VLOOKUP(Sheet_1[[#This Row],[Ngày giao dịch lần 1]],'Data Repo'!$A:$I,3,0),60,VLOOKUP(Sheet_1[[#This Row],[Ngày giao dịch lần 1]],'Data Repo'!$A:$I,4,0),90,VLOOKUP(Sheet_1[[#This Row],[Ngày giao dịch lần 1]],'Data Repo'!$A:$I,5,0),180,VLOOKUP(Sheet_1[[#This Row],[Ngày giao dịch lần 1]],'Data Repo'!$A:$I,6,0),270,VLOOKUP(Sheet_1[[#This Row],[Ngày giao dịch lần 1]],'Data Repo'!$A:$I,7,0),365,VLOOKUP(Sheet_1[[#This Row],[Ngày giao dịch lần 1]],'Data Repo'!$A:$I,8,0)),"") | AC5: =IF(Sheet_1[[#This Row],[Mã kỳ hạn chuẩn]]="Kỳ hạn lẻ",_xlfn.SWITCH(Sheet_1[[#This Row],[Kỳ hạn Repo chuẩn (longer)]],14,VLOOKUP(Sheet_1[[#This Row],[Ngày giao dịch lần 1]],'Data Repo'!$A:$I,2,0),30,VLOOKUP(Sheet_1[[#This Row],[Ngày giao dịch lần 1]],'Data Repo'!$A:$I,3,0),60,VLOOKUP(Sheet_1[[#This Row],[Ngày giao dịch lần 1]],'Data Repo'!$A:$I,4,0),90,VLOOKUP(Sheet_1[[#This Row],[Ngày giao dịch lần 1]],'Data Repo'!$A:$I,5,0),180,VLOOKUP(Sheet_1[[#This Row],[Ngày giao dịch lần 1]],'Data Repo'!$A:$I,6,0),270,VLOOKUP(Sheet_1[[#This Row],[Ngày giao dịch lần 1]],'Data Repo'!$A:$I,7,0),365,VLOOKUP(Sheet_1[[#This Row],[Ngày giao dịch lần 1]],'Data Repo'!$A:$I,8,0)),"") | AD5: =IF(Sheet_1[[#This Row],[Mã kỳ hạn chuẩn]]="Kỳ hạn lẻ",_xlfn.SWITCH(Sheet_1[[#This Row],[Kỳ hạn Repo chuẩn (shorter)]],1,'Biên độ MM, Repo'!$D$2,7,'Biên độ MM, Repo'!$D$3,14,'Biên độ MM, Repo'!$D$4,21,'Biên độ MM, Repo'!#REF!,30,'Biên độ MM, Repo'!$D$5,60,'Biên độ MM, Repo'!$D$6,90,'Biên độ MM, Repo'!$D$7,180,'Biên độ MM, Repo'!$D$8,270,'Biên độ MM, Repo'!$D$9,365,'Biên độ MM, Repo'!$D$10),0) -> 0 | AE5: =IF(Sheet_1[[#This Row],[Mã kỳ hạn chuẩn]]="Kỳ hạn lẻ",_xlfn.SWITCH(Sheet_1[[#This Row],[Kỳ hạn Repo chuẩn (longer)]],1,'Biên độ MM, Repo'!$D$2,7,'Biên độ MM, Repo'!$D$3,14,'Biên độ MM, Repo'!$D$4,21,'Biên độ MM, Repo'!#REF!,30,'Biên độ MM, Repo'!$D$5,60,'Biên độ MM, Repo'!$D$6,90,'Biên độ MM, Repo'!$D$7,180,'Biên độ MM, Repo'!$D$8,270,'Biên độ MM, Repo'!$D$9,365,'Biên độ MM, Repo'!$D$10),0) -> 0 | AF5: =IF(Sheet_1[[#This Row],[Mã kỳ hạn chuẩn]]="Kỳ hạn lẻ",_xlfn.FORECAST.LINEAR(Sheet_1[[#This Row],[Kỳ hạn còn lại]],Sheet_1[[#This Row],[Biên độ chuẩn (shorter)]:[Biên độ chuẩn (longer)]],Sheet_1[[#This Row],[Kỳ hạn Repo chuẩn (shorter)]:[Kỳ hạn Repo chuẩn (longer)]]),VLOOKUP(Sheet_1[[#This Row],[Mã kỳ hạn chuẩn]],'Biên độ MM, Repo'!$B$2:$D$10,3,0)) -> 0.48476818 | AG5: =IF(Sheet_1[[#This Row],[Mã kỳ hạn chuẩn]]="Kỳ hạn lẻ",_xlfn.FORECAST.LINEAR(Sheet_1[[#This Row],[Kỳ hạn còn lại]],Sheet_1[[#This Row],[LS Repo chuẩn (shorter)]:[LS Repo chuẩn (longer)]],Sheet_1[[#This Row],[Kỳ hạn Repo chuẩn (shorter)]:[Kỳ hạn Repo chuẩn (longer)]]),INDEX('Data Repo'!$A:$I,MATCH(Sheet_1[[#This Row],[Ngày giao dịch lần 1]],'Data Repo'!A:A,0),MATCH(Sheet_1[[#This Row],[Kỳ hạn còn lại]],'Data Repo'!$A$1:$I$1,0))) -> 4.567 | AH5: =Sheet_1[[#This Row],[Lãi suất tham chiếu]]+Sheet_1[[#This Row],[Biên độ]] -> 5.0517682 | AI5: =Sheet_1[[#This Row],[Lãi suất tham chiếu]]-Sheet_1[[#This Row],[Biên độ]] -> 4.0822318 | AJ5: =IF(Sheet_1[[#This Row],[Lãi suất repo]]>Sheet_1[[#This Row],[Lãi suất tham chiếu lớn nhất]],"Giao dịch bất lợi cho VCBNeo",IF(Sheet_1[[#This Row],[Lãi suất repo]]<Sheet_1[[#This Row],[Lãi suất tham chiếu nhỏ nhất]],"Giao dịch có lợi cho VCBNeo","GD Hợp lý")) -> Giao dịch bất lợi cho VCBNeo
A6: 5 | B6: Hợp đồng bán có kỳ hạn GTCG | C6: LPBL2431004 | D6: Trái phiếu | E6: VND-Việt Nam đồng | F6: 1000000000 | G6: 45565 | H6: 48121 | I6: 7 | J6: Năm | K6: 7.575 | L6: 1000001002 - NH TMCP BAC A | M6: HD: 25112024.02/REPO/BAB-CB | N6: 45621 | O6: 45621 | P6: 45621 | Q6: 100 | R6: 100000000000 | S6: 101195810200 | T6: 5.8 | U6: 45651 | V6: 45651 | W6: 101676905000 | X6: =Sheet_1[[#This Row],[Ngày giao dịch lần 2]]-Sheet_1[[#This Row],[Ngày giao dịch lần 1]] -> 30 | Y6: =IFERROR(VLOOKUP(Sheet_1[[#This Row],[Kỳ hạn còn lại]],'Thang kỳ hạn Repo'!$A$1:$B$63,2,0),"Kỳ hạn lẻ") -> 1M | Z6: =IF(Sheet_1[[#This Row],[Mã kỳ hạn chuẩn]]="Kỳ hạn lẻ",IFERROR( _xlfn.IFS(Sheet_1[[#This Row],[Kỳ hạn còn lại]]>365,365, Sheet_1[[#This Row],[Kỳ hạn còn lại]]>270,270, Sheet_1[[#This Row],[Kỳ hạn còn lại]]>180,180, Sheet_1[[#This Row],[Kỳ hạn còn lại]]>90,90, Sheet_1[[#This Row],[Kỳ hạn còn lại]]>60,60, Sheet_1[[#This Row],[Kỳ hạn còn lại]]>30,30, Sheet_1[[#This Row],[Kỳ hạn còn lại]]>14,14, Sheet_1[[#This Row],[Kỳ hạn còn lại]]>7,7, Sheet_1[[#This Row],[Kỳ hạn còn lại]]>1,1),0),"") | AA6: =IF(Sheet_1[[#This Row],[Mã kỳ hạn chuẩn]]="Kỳ hạn lẻ",IFERROR( _xlfn.IFS(Sheet_1[[#This Row],[Kỳ hạn còn lại]]<1,1, Sheet_1[[#This Row],[Kỳ hạn còn lại]]<7,7, Sheet_1[[#This Row],[Kỳ hạn còn lại]]<14,14, Sheet_1[[#This Row],[Kỳ hạn còn lại]]<30,30, Sheet_1[[#This Row],[Kỳ hạn còn lại]]<60,60, Sheet_1[[#This Row],[Kỳ hạn còn lại]]<90,90, Sheet_1[[#This Row],[Kỳ hạn còn lại]]<180,180, Sheet_1[[#This Row],[Kỳ hạn còn lại]]<270,270, Sheet_1[[#This Row],[Kỳ hạn còn lại]]<365,365), 0),"") | AB6: =IF(Sheet_1[[#This Row],[Mã kỳ hạn chuẩn]]="Kỳ hạn lẻ",_xlfn.SWITCH(Sheet_1[[#This Row],[Kỳ hạn Repo chuẩn (shorter)]],14,VLOOKUP(Sheet_1[[#This Row],[Ngày giao dịch lần 1]],'Data Repo'!$A:$I,2,0),30,VLOOKUP(Sheet_1[[#This Row],[Ngày giao dịch lần 1]],'Data Repo'!$A:$I,3,0),60,VLOOKUP(Sheet_1[[#This Row],[Ngày giao dịch lần 1]],'Data Repo'!$A:$I,4,0),90,VLOOKUP(Sheet_1[[#This Row],[Ngày giao dịch lần 1]],'Data Repo'!$A:$I,5,0),180,VLOOKUP(Sheet_1[[#This Row],[Ngày giao dịch lần 1]],'Data Repo'!$A:$I,6,0),270,VLOOKUP(Sheet_1[[#This Row],[Ngày giao dịch lần 1]],'Data Repo'!$A:$I,7,0),365,VLOOKUP(Sheet_1[[#This Row],[Ngày giao dịch lần 1]],'Data Repo'!$A:$I,8,0)),"") | AC6: =IF(Sheet_1[[#This Row],[Mã kỳ hạn chuẩn]]="Kỳ hạn lẻ",_xlfn.SWITCH(Sheet_1[[#This Row],[Kỳ hạn Repo chuẩn (longer)]],14,VLOOKUP(Sheet_1[[#This Row],[Ngày giao dịch lần 1]],'Data Repo'!$A:$I,2,0),30,VLOOKUP(Sheet_1[[#This Row],[Ngày giao dịch lần 1]],'Data Repo'!$A:$I,3,0),60,VLOOKUP(Sheet_1[[#This Row],[Ngày giao dịch lần 1]],'Data Repo'!$A:$I,4,0),90,VLOOKUP(Sheet_1[[#This Row],[Ngày giao dịch lần 1]],'Data Repo'!$A:$I,5,0),180,VLOOKUP(Sheet_1[[#This Row],[Ngày giao dịch lần 1]],'Data Repo'!$A:$I,6,0),270,VLOOKUP(Sheet_1[[#This Row],[Ngày giao dịch lần 1]],'Data Repo'!$A:$I,7,0),365,VLOOKUP(Sheet_1[[#This Row],[Ngày giao dịch lần 1]],'Data Repo'!$A:$I,8,0)),"") | AD6: =IF(Sheet_1[[#This Row],[Mã kỳ hạn chuẩn]]="Kỳ hạn lẻ",_xlfn.SWITCH(Sheet_1[[#This Row],[Kỳ hạn Repo chuẩn (shorter)]],1,'Biên độ MM, Repo'!$D$2,7,'Biên độ MM, Repo'!$D$3,14,'Biên độ MM, Repo'!$D$4,21,'Biên độ MM, Repo'!#REF!,30,'Biên độ MM, Repo'!$D$5,60,'Biên độ MM, Repo'!$D$6,90,'Biên độ MM, Repo'!$D$7,180,'Biên độ MM, Repo'!$D$8,270,'Biên độ MM, Repo'!$D$9,365,'Biên độ MM, Repo'!$D$10),0) -> 0 | AE6: =IF(Sheet_1[[#This Row],[Mã kỳ hạn chuẩn]]="Kỳ hạn lẻ",_xlfn.SWITCH(Sheet_1[[#This Row],[Kỳ hạn Repo chuẩn (longer)]],1,'Biên độ MM, Repo'!$D$2,7,'Biên độ MM, Repo'!$D$3,14,'Biên độ MM, Repo'!$D$4,21,'Biên độ MM, Repo'!#REF!,30,'Biên độ MM, Repo'!$D$5,60,'Biên độ MM, Repo'!$D$6,90,'Biên độ MM, Repo'!$D$7,180,'Biên độ MM, Repo'!$D$8,270,'Biên độ MM, Repo'!$D$9,365,'Biên độ MM, Repo'!$D$10),0) -> 0 | AF6: =IF(Sheet_1[[#This Row],[Mã kỳ hạn chuẩn]]="Kỳ hạn lẻ",_xlfn.FORECAST.LINEAR(Sheet_1[[#This Row],[Kỳ hạn còn lại]],Sheet_1[[#This Row],[Biên độ chuẩn (shorter)]:[Biên độ chuẩn (longer)]],Sheet_1[[#This Row],[Kỳ hạn Repo chuẩn (shorter)]:[Kỳ hạn Repo chuẩn (longer)]]),VLOOKUP(Sheet_1[[#This Row],[Mã kỳ hạn chuẩn]],'Biên độ MM, Repo'!$B$2:$D$10,3,0)) -> 0.48476818 | AG6: =IF(Sheet_1[[#This Row],[Mã kỳ hạn chuẩn]]="Kỳ hạn lẻ",_xlfn.FORECAST.LINEAR(Sheet_1[[#This Row],[Kỳ hạn còn lại]],Sheet_1[[#This Row],[LS Repo chuẩn (shorter)]:[LS Repo chuẩn (longer)]],Sheet_1[[#This Row],[Kỳ hạn Repo chuẩn (shorter)]:[Kỳ hạn Repo chuẩn (longer)]]),INDEX('Data Repo'!$A:$I,MATCH(Sheet_1[[#This Row],[Ngày giao dịch lần 1]],'Data Repo'!A:A,0),MATCH(Sheet_1[[#This Row],[Kỳ hạn còn lại]],'Data Repo'!$A$1:$I$1,0))) -> 4.567 | AH6: =Sheet_1[[#This Row],[Lãi suất tham chiếu]]+Sheet_1[[#This Row],[Biên độ]] -> 5.0517682 | AI6: =Sheet_1[[#This Row],[Lãi suất tham chiếu]]-Sheet_1[[#This Row],[Biên độ]] -> 4.0822318 | AJ6: =IF(Sheet_1[[#This Row],[Lãi suất repo]]>Sheet_1[[#This Row],[Lãi suất tham chiếu lớn nhất]],"Giao dịch bất lợi cho VCBNeo",IF(Sheet_1[[#This Row],[Lãi suất repo]]<Sheet_1[[#This Row],[Lãi suất tham chiếu nhỏ nhất]],"Giao dịch có lợi cho VCBNeo","GD Hợp lý")) -> Giao dịch bất lợi cho VCBNeo
P7: Thông tin giao dich repo trong Sheet "Sao kê giao dịch Repo" | Y7: - Tìm mã kỳ hạn của GTCG theo Sheet "Thang kỳ hạn Repo" | Z7: =IF([@[Mã kỳ hạn chuẩn]]="Kỳ hạn lẻ";@IFERROR( IFS([@[Kỳ hạn còn lại]]>365;365; [@[Kỳ hạn còn lại]]>270;270; [@[Kỳ hạn còn lại]]>180;180; [@[Kỳ hạn còn lại]]>90;90; [@[Kỳ hạn còn lại]]>60;60; [@[Kỳ hạn còn lại]]>30;30; [@[Kỳ hạn còn lại]]>14;14; [@[Kỳ hạn còn lại]]>7;7; [@[Kỳ hạn còn lại]]>1;1);0);"") - Ý nghĩa: Tìm chặn dưới của Kỳ hạn còn lại (Cột X) (Ví dụ: Kỳ hạn là 25 thì chặn dưới là 14 và chặn trên là 30 dựa theo Sheet "Thang kỳ hạn Repo") | AA7: =IF([@[Mã kỳ hạn chuẩn]]="Kỳ hạn lẻ";@IFERROR( IFS([@[Kỳ hạn còn lại]]<1;1; [@[Kỳ hạn còn lại]]<7;7; [@[Kỳ hạn còn lại]]<14;14; [@[Kỳ hạn còn lại]]<30;30; [@[Kỳ hạn còn lại]]<60;60; [@[Kỳ hạn còn lại]]<90;90; [@[Kỳ hạn còn lại]]<180;180; [@[Kỳ hạn còn lại]]<270;270; [@[Kỳ hạn còn lại]]<365;365); 0);"") - Ý nghĩa: Tìm chặn trên của Kỳ hạn còn lại (Cột X) (Ví dụ: Kỳ hạn là 25 thì chặn dưới là 14 và chặn trên là 30 dựa theo Sheet "Thang kỳ hạn Repo") | AB7: - Tìm Lãi suất Repo của Kỳ hạn Repo chuẩn (shorter) tại Ngày giao dịch lần 1 (Cột O) trong Sheet "Data Repo" | AC7: - Tìm Lãi suất Repo của Kỳ hạn Repo chuẩn (longer) tại Ngày giao dịch lần 1 (Cột O) trong Sheet "Data Repo" | AD7: - Tìm biên độ Repo của Kỳ hạn Repo chuẩn (shorter) (Cột Z) tại cột D trong Sheet "Biên độ MM, Repo" | AE7: - Tìm biên độ Repo của Kỳ hạn Repo chuẩn (longer) (Cột AA) tại cột D trong Sheet "Biên độ MM, Repo" | AF7: - Kỳ hạn chuẩn: Lấy biên độ chuẩn tại cột D trong Sheet "Biên độ MM, repo" - Kỳ hạn lẻ: Nội suy tuyến tính từ 2 biên độ phía trước =IF([@[Mã kỳ hạn chuẩn]]="Kỳ hạn lẻ";FORECAST.LINEAR([@[Kỳ hạn còn lại]];Sheet_1[@[Biên độ chuẩn (shorter)]:[Biên độ chuẩn (longer)]];Sheet_1[@[Kỳ hạn Repo chuẩn (shorter)]:[Kỳ hạn Repo chuẩn (longer)]]);VLOOKUP([@[Mã kỳ hạn chuẩn]];'Biên độ MM, Repo'!$B$2:$D$10;3;0)) | AG7: - Kỳ hạn lẻ: Nội suy tuyến tính từ Lãi suất Repo (Shorter) và Lãi suất Repo (Longer) đã tính phía trước - Kỳ hạn chuẩn: Tìm kiếm Lãi suất Repo tại Ngày giao dịch lần 1 (Cột O) trong Sheet "Data Repo" | AH7: = Cột AG + biên độ | AI7: = Cột AG - biên độ | AJ7: So sánh Lãi suất giao dịch với Khoảng lãi suất hợp lý: - Trường hợp 1: Nếu Lãi suất giao dịch nằm trong Khoảng lãi suất hợp lý => GD Hợp lý - Trường hợp 2: Lãi suất giao dịch thấp hơn Khoảng lãi suất hợp lý + Trường hợp 2.1: Nếu là giao dịch Repo => GD có lợi cho VCBNeo + Trường hợp 2.2: Nếu là giao dịch Reverse Repo => GD bất lợi cho VCBNeo - Trường hợp 3: Lãi suất giao dịch cao hơn Khoảng lãi suất hợp lý + Trường hợp 3.1: Nếu là giao dịch Repo => GD bất lợi cho VCBNeo + Trường hợp 3.2: Nếu là giao dịch Reverse Repo (VCBNeo đi gửi MM tại TCTD khác) => GD có lợi cho VCBNeo

Sheet Sao kê giao dịch Repo
A1: STT | B1: Loại giao dịch | C1: Mã GTCG | D1: Loại GTCG | E1: Loại tiền tệ | F1: Mệnh giá | G1: Ngày phát hành | H1: Ngày đáo hạn | I1: Kỳ hạn | J1: Đơn vị kỳ hạn | K1: Lãi suất phát hành | L1: Tên đối tác | M1: Số HĐMB | N1: Ngày hợp đồng | O1: Ngày giao dịch lần 1 | P1: Ngày thanh toán lần 1 | Q1: Số lượng mua/bán | R1: Tổng mệnh giá mua/bán | S1: Giá trị GDHD lần 1 | T1: Lãi suất repo | U1: Ngày giao dịch lần 2 | V1: Ngày thanh toán lần 2 | W1: Giá trị GDHD lần 2 | X1: Kỳ hạn còn lại
A2: 1 | B2: Hợp đồng bán có kỳ hạn GTCG | C2: HDBL2431009 | D2: Trái phiếu | E2: VND-Việt Nam đồng | F2: 1000000000 | G2: 45504 | H2: 48060 | I2: 7 | J2: Năm | K2: 7.475 | L2: 1000001002 - NH TMCP BAC A | M2: 28112024.04/REPO/BAB-CB | N2: 45624 | O2: 45624 | P2: 45624 | Q2: 50 | R2: 50000000000 | S2: 50947437000 | T2: 6.2 | U2: 45649 | V2: 45649 | W2: 51163198000 | X2: =Sheet_1[[#This Row],[Ngày giao dịch lần 2]]-Sheet_1[[#This Row],[Ngày giao dịch lần 1]] -> 25
A3: 2 | B3: Hợp đồng bán có kỳ hạn GTCG | C3: HDBL2431002 | D3: Trái phiếu | E3: VND-Việt Nam đồng | F3: 1000000000 | G3: 45450 | H3: 48006 | I3: 7 | J3: Năm | K3: 7.475 | L3: 1000001002 - NH TMCP BAC A | M3: 28112024.03/REPO/BAB-CB | N3: 45624 | O3: 45624 | P3: 45624 | Q3: 50 | R3: 50000000000 | S3: 51572712700 | T3: 6.2 | U3: 45649 | V3: 45649 | W3: 51791121750 | X3: =Sheet_1[[#This Row],[Ngày giao dịch lần 2]]-Sheet_1[[#This Row],[Ngày giao dịch lần 1]] -> 25
A4: 3 | B4: Hợp đồng bán có kỳ hạn GTCG | C4: HDBL2431002 | D4: Trái phiếu | E4: VND-Việt Nam đồng | F4: 1000000000 | G4: 45450 | H4: 48006 | I4: 7 | J4: Năm | K4: 7.475 | L4: 1000001002 - NH TMCP BAC A | M4: 28112024.03/ REPO/BAB-CB | N4: 45624 | O4: 45624 | P4: 45624 | Q4: 50 | R4: 50000000000 | S4: 51572712700 | T4: 6.2 | U4: 45649 | V4: 45649 | W4: 51791121750 | X4: =Sheet_1[[#This Row],[Ngày giao dịch lần 2]]-Sheet_1[[#This Row],[Ngày giao dịch lần 1]] -> 25
A5: 4 | B5: Hợp đồng bán có kỳ hạn GTCG | C5: LPBL2431001 | D5: Trái phiếu | E5: VND-Việt Nam đồng | F5: 1000000000 | G5: 45527 | H5: 48083 | I5: 7 | J5: Năm | K5: 7.575 | L5: 1000001002 - NH TMCP BAC A | M5: 25112024.01/REPO/BAB-CB | N5: 45621 | O5: 45621 | P5: 45621 | Q5: 150 | R5: 150000000000 | S5: 153202902750 | T5: 5.8 | U5: 45651 | V5: 45651 | W5: 153931244400 | X5: =Sheet_1[[#This Row],[Ngày giao dịch lần 2]]-Sheet_1[[#This Row],[Ngày giao dịch lần 1]] -> 30
A6: 5 | B6: Hợp đồng bán có kỳ hạn GTCG | C6: LPBL2431004 | D6: Trái phiếu | E6: VND-Việt Nam đồng | F6: 1000000000 | G6: 45565 | H6: 48121 | I6: 7 | J6: Năm | K6: 7.575 | L6: 1000001002 - NH TMCP BAC A | M6: HD: 25112024.02/REPO/BAB-CB | N6: 45621 | O6: 45621 | P6: 45621 | Q6: 100 | R6: 100000000000 | S6: 101195810200 | T6: 5.8 | U6: 45651 | V6: 45651 | W6: 101676905000 | X6: =Sheet_1[[#This Row],[Ngày giao dịch lần 2]]-Sheet_1[[#This Row],[Ngày giao dịch lần 1]] -> 30

Sheet Sao kê giao dịch MM
A1: Loại tiền | B1: Tên đối tác | C1: Số dư | D1: Hình thức giao dịch | E1: Kỳ hạn | F1: Lãi suất | G1: Ngày hiệu lực HĐ | H1: Ngày đáo hạn
A2: VND | B2: PV | C2: 200000000000 | D2: Lend | E2: 5 | F2: 4.2 | G2: 45771 | H2: 45776
A3: VND | B3: VCB | C3: 200000000000 | D3: Lend | E3: 14 | F3: 4.2 | G3: 45772 | H3: 45786
A4: VND | B4: VIB | C4: 150000000000 | D4: Lend | E4: 1 | F4: 2.3 | G4: 45775 | H4: 45776

Sheet Data VNIBOR
B1: Column1 | C1: ON | D1: 1W | E1: 2W | F1: 1M | G1: 2M | H1: 3M | I1: 6M | J1: 9M | K1: 1Y | X1: =_xlfn.PERCENTILE.EXC(N3:V1253,95%) -> #NUM!
B2: Timestamp | C2: FIXING_1 | D2: FIXING_1 | E2: FIXING_1 | F2: FIXING_1 | G2: FIXING_1 | H2: FIXING_1 | I2: FIXING_1 | J2: FIXING_1 | K2: FIXING_1
A3: 45776 | B3: 45776 | C3: 4 | D3: 4.2 | E3: 4.37 | F3: 4.54 | G3: 4.68 | H3: 4.73 | I3: 5 | J3: 5.18 | K3: 5.24 | X3: VNIVNDOND= | Y3: =N1 -> 0
A4: 45775 | B4: 45775 | C4: 2.5 | D4: 4.28 | E4: 4.34 | F4: 4.53 | G4: 4.68 | H4: 4.72 | I4: 4.96 | J4: 5.13 | K4: 5.15 | X4: VNIVNDSWD= | Y4: =O1 -> 0
A5: 45773 | B5: 45773 | C5: 2.53 | D5: 4.23 | E5: 4.35 | F5: 4.53 | G5: 4.7 | H5: 4.75 | I5: 5 | J5: 5.16 | K5: 5.24 | X5: VNIVND2WD= | Y5: =P1 -> 0
A6: 45772 | B6: 45772 | C6: 2.43 | D6: 4.13 | E6: 4.28 | F6: 4.55 | G6: 4.7 | H6: 4.73 | I6: 5.03 | J6: 5.18 | K6: 5.24 | X6: VNIVND1MD= | Y6: =Q1 -> 0
A7: 45771 | B7: 45771 | C7: 3.33 | D7: 4.31 | E7: 4.47 | F7: 4.61 | G7: 4.71 | H7: 4.77 | I7: 5.04 | J7: 5.2 | K7: 5.25 | X7: VNIVND2MD= | Y7: =R1 -> 0
A8: 45770 | B8: 45770 | C8: 3.97 | D8: 4.53 | E8: 4.63 | F8: 4.73 | G8: 4.78 | H8: 4.83 | I8: 5.05 | J8: 5.22 | K8: 5.26 | X8: VNIVND3MD= | Y8: =S1 -> 0
A9: 45769 | B9: 45769 | C9: 4.47 | D9: 4.57 | E9: 4.69 | F9: 4.76 | G9: 4.79 | H9: 4.84 | I9: 5.04 | J9: 5.2 | K9: 5.25 | X9: VNIVND6MD= | Y9: =T1 -> 0
A10: 45768 | B10: 45768 | C10: 4.56 | D10: 4.62 | E10: 4.72 | F10: 4.74 | G10: 4.82 | H10: 4.86 | I10: 5.06 | J10: 5.18 | K10: 5.25 | X10: VNIVND9MD= | Y10: =U1 -> 0
A11: 45765 | B11: 45765 | C11: 4.18 | D11: 4.36 | E11: 4.54 | F11: 4.6 | G11: 4.72 | H11: 4.76 | I11: 4.96 | J11: 5.13 | K11: 5.15 | X11: VNIVND1YD= | Y11: =V1 -> 0
A12: 45764 | B12: 45764 | C12: 4.1 | D12: 4.33 | E12: 4.48 | F12: 4.6 | G12: 4.73 | H12: 4.78 | I12: 5.08 | J12: 5.22 | K12: 5.26
A13: 45763 | B13: 45763 | C13: 4.06 | D13: 4.3 | E13: 4.46 | F13: 4.62 | G13: 4.74 | H13: 4.8 | I13: 5 | J13: 5.18 | K13: 5.23
A14: 45762 | B14: 45762 | C14: 4.08 | D14: 4.34 | E14: 4.48 | F14: 4.6 | G14: 4.68 | H14: 4.74 | I14: 5.04 | J14: 5.18 | K14: 5.25
A15: 45761 | B15: 45761 | C15: 4.1 | D15: 4.34 | E15: 4.48 | F15: 4.62 | G15: 4.72 | H15: 4.76 | I15: 5.1 | J15: 5.26 | K15: 5.29
A16: 45758 | B16: 45758 | C16: 4.08 | D16: 4.33 | E16: 4.5 | F16: 4.63 | G16: 4.7 | H16: 4.75 | I16: 4.98 | J16: 5.12 | K16: 5.18
A17: 45757 | B17: 45757 | C17: 4.07 | D17: 4.28 | E17: 4.48 | F17: 4.62 | G17: 4.72 | H17: 4.77 | I17: 5.03 | J17: 5.18 | K17: 5.24
A18: 45756 | B18: 45756 | C18: 4.18 | D18: 4.42 | E18: 4.55 | F18: 4.62 | G18: 4.72 | H18: 4.77 | I18: 5.03 | J18: 5.2 | K18: 5.24
A19: 45755 | B19: 45755 | C19: 4.18 | D19: 4.42 | E19: 4.54 | F19: 4.62 | G19: 4.7 | H19: 4.72 | I19: 5.02 | J19: 5.16 | K19: 5.2
A20: 45751 | B20: 45751 | C20: 4.06 | D20: 4.3 | E20: 4.4 | F20: 4.56 | G20: 4.68 | H20: 4.72 | I20: 5.1 | J20: 5.23 | K20: 5.25
A21: 45750 | B21: 45750 | C21: 4 | D21: 4.32 | E21: 4.54 | F21: 4.62 | G21: 4.7 | H21: 4.74 | I21: 5 | J21: 5.18 | K21: 5.23
A22: 45749 | B22: 45749 | C22: 4.04 | D22: 4.3 | E22: 4.48 | F22: 4.58 | G22: 4.68 | H22: 4.72 | I22: 5 | J22: 5.18 | K22: 5.23
A23: 45748 | B23: 45748 | C23: 4.52 | D23: 4.65 | E23: 4.7 | F23: 4.72 | G23: 4.75 | H23: 4.78 | I23: 5.05 | J23: 5.2 | K23: 5.24
