Workbook

Sheet BRD
A3: STT | B3: Nội dung | C3: Ghi chú
A4: Bước 1 | B4: Thu thập số dư phát sinh trong ngày làm việc của từng đối tác trong 03 tháng gần nhất (bao gồm tháng báo cáo và 02 tháng gần nhất liền trước tháng báo cáo)
A5: Bước 2 | B5: Xác định Tỷ trọng đối tác giao dịch cho từng ngày làm việc trong 03 tháng gần nhất theo công thức Lưu ý: Trường hợp mẫu số tại bất kỳ tỷ trọng quy định tại Điểm a), b), c) Bước này bằng 0 thì tỷ trọng đó sẽ bằng 0%.
A6: Bước 3 | B6: Tỷ trọng đối tác giao dịch được xác định bằng trung bình số học tỷ trọng đối tác giao dịch của tất cả các ngày làm việc trong 03 tháng gần nhất (bao gồm tháng báo cáo và 02 tháng gần nhất liền trước tháng báo cáo). | C6: Trung bình số học của các tỷ trọng được tính ở Bước 2
A7: Bước 4 | B7: So sánh Tỷ trọng đối tác giao dịch với hạn mức RRTTr TD theo đối tác giao dịch được ban hành trong từng thời kỳ

Sheet Hạn mức RRTTr TD
A1: Tên khách hàng | B1: Ngày 02/01/2025 | C1: Ngày 03/01/2025 | D1: Ngày 06/01/2025 | E1: Ngày 07/01/2025 | F1: Ngày 08/01/2025 | G1: Ngày 09/01/2025 | H1: Ngày 10/01/2025 | I1: Ngày 13/01/2025 | J1: Ngày 14/01/2025 | K1: Ngày 15/01/2025 | L1: Ngày 16/01/2025 | M1: Ngày 17/01/2025 | N1: Ngày 20/01/2025 | O1: Ngày 21/01/2025 | P1: Ngày 22/01/2025 | Q1: Ngày 23/01/2025 | R1: Ngày 24/01/2025 | S1: Ngày 03/02/2025 | T1: Ngày 04/02/2025 | U1: Ngày 05/02/2025 | V1: Ngày 07/02/2025 | W1: Ngày 10/02/2025 | X1: Ngày 11/02/2025 | Y1: Ngày 12/02/2025 | Z1: Ngày 13/02/2025 | AA1: Ngày 14/02/2025 | AB1: Ngày 17/02/2025 | AC1: Ngày 18/02/2025 | AD1: Ngày 19/02/2025 | AE1: Ngày 20/02/2025 | AF1: Ngày 21/02/2025 | AG1: Ngày 24/02/2025 | AH1: Ngày 25/02/2025 | AI1: Ngày 26/02/2025 | AJ1: Ngày 27/02/2025 | AK1: Ngày 28/02/2025 | AL1: Ngày 03/03/2025 | AM1: Ngày 04/03/2025 | AN1: Ngày 05/03/2025 | AO1: Ngày 06/03/2025 | AP1: Ngày 07/03/2025 | AQ1: Ngày 10/03/2025 | AR1: Ngày 11/03/2025 | AS1: Ngày 12/03/2025 | AT1: Ngày 13/03/2025 | AU1: Ngày 14/03/2025 | AV1: Ngày 17/03/2025 | AW1: Ngày 18/03/2025 | AX1: Ngày 19/03/2025 | AY1: Ngày 20/03/2025 | AZ1: Ngày 21/03/2025 | BA1: Ngày 24/03/2025 | BB1: Ngày 25/03/2025 | BC1: Ngày 26/03/2025 | BD1: Ngày 27/03/2025 | BE1: Ngày 28/03/2025 | BF1: Ngày 31/03/2025 | BG1: Ngày 01/04/2025 | BH1: Ngày 02/04/2025 | BI1: Ngày 03/04/2025 | BJ1: Ngày 04/04/2025 | BK1: Ngày 08/04/2025 | BL1: Ngày 09/04/2025 | BM1: Ngày 10/04/2025 | BN1: Ngày 11/04/2025 | BO1: Ngày 14/04/2025 | BP1: Ngày 15/04/2025 | BQ1: Ngày 16/04/2025 | BR1: Ngày Báo cáo T - 1
A3: NH NN&PTNT VN (Agribank) | B3: =SUM('Tỷ lệ'!B3:BL3)/COUNT('Tỷ lệ'!B3:BL3) -> 0 | C3: =SUM('Tỷ lệ'!B3:BM3)/COUNT('Tỷ lệ'!B3:BM3) -> 0 | D3: =SUM('Tỷ lệ'!B3:BN3)/COUNT('Tỷ lệ'!B3:BN3) -> 0 | E3: =SUM('Tỷ lệ'!B3:BO3)/COUNT('Tỷ lệ'!B3:BO3) -> 0 | F3: =SUM('Tỷ lệ'!B3:BP3)/COUNT('Tỷ lệ'!B3:BP3) -> 0 | G3: =SUM('Tỷ lệ'!B3:BQ3)/COUNT('Tỷ lệ'!B3:BQ3) -> 0 | H3: =SUM('Tỷ lệ'!B3:BR3)/COUNT('Tỷ lệ'!B3:BR3) -> 0 | I3: =SUM('Tỷ lệ'!B3:BS3)/COUNT('Tỷ lệ'!B3:BS3) -> 0 | J3: =SUM('Tỷ lệ'!B3:BT3)/COUNT('Tỷ lệ'!B3:BT3) -> 0 | K3: =SUM('Tỷ lệ'!B3:BU3)/COUNT('Tỷ lệ'!B3:BU3) -> 0 | L3: =SUM('Tỷ lệ'!B3:BV3)/COUNT('Tỷ lệ'!B3:BV3) -> 0 | M3: =SUM('Tỷ lệ'!B3:BW3)/COUNT('Tỷ lệ'!B3:BW3) -> 0 | N3: =SUM('Tỷ lệ'!B3:BX3)/COUNT('Tỷ lệ'!B3:BX3) -> 0 | O3: =SUM('Tỷ lệ'!B3:BY3)/COUNT('Tỷ lệ'!B3:BY3) -> 0 | P3: =SUM('Tỷ lệ'!B3:BZ3)/COUNT('Tỷ lệ'!B3:BZ3) -> 0 | Q3: =SUM('Tỷ lệ'!B3:CA3)/COUNT('Tỷ lệ'!B3:CA3) -> 0 | R3: =SUM('Tỷ lệ'!B3:CB3)/COUNT('Tỷ lệ'!B3:CB3) -> 0 | S3: 0 | T3: 0 | U3: 0 | V3: 0 | W3: 0 | X3: 0 | Y3: 0 | Z3: 0 | AA3: 0 | AB3: 0 | AC3: 0 | AD3: 0 | AE3: 0 | AF3: 0 | AG3: 0 | AH3: 0 | AI3: 0 | AJ3: 0 | AK3: 0 | AL3: =SUM('Tỷ lệ'!B3:AK3)/COUNT('Tỷ lệ'!B3:AK3) -> 0 | AM3: 0 | AN3: 0 | AO3: =SUM('Tỷ lệ'!$BK$3:CX3)/COUNT('Tỷ lệ'!$BK$3:CX3) -> 0 | AP3: =SUM('Tỷ lệ'!$BK$3:CY3)/COUNT('Tỷ lệ'!$BK$3:CY3) -> 0 | AQ3: =SUM('Tỷ lệ'!$BK$3:CZ3)/COUNT('Tỷ lệ'!$BK$3:CZ3) -> 0 | AR3: =SUM('Tỷ lệ'!$BK$3:DA3)/COUNT('Tỷ lệ'!$BK$3:DA3) -> 0 | AS3: =SUM('Tỷ lệ'!$BK$3:DB3)/COUNT('Tỷ lệ'!$BK$3:DB3) -> 0 | AT3: =SUM('Tỷ lệ'!$BK$3:DC3)/COUNT('Tỷ lệ'!$BK$3:DC3) -> 0 | AU3: =SUM('Tỷ lệ'!$BK$3:DD3)/COUNT('Tỷ lệ'!$BK$3:DD3) -> 0 | AV3: =SUM('Tỷ lệ'!$BK$3:DE3)/COUNT('Tỷ lệ'!$BK$3:DE3) -> 0 | ... BF3: =SUM('Tỷ lệ'!$BK$3:DO3)/COUNT('Tỷ lệ'!$BK$3:DO3) -> 0 | BG3: 0 | BH3: 0 | BI3: 0 | BJ3: 0 | BK3: 0 | BL3: 0 | BM3: 0 | BN3: 0 | BO3: 0 | BP3: 0 | BQ3: 0 | BR3: - Trung bình cộng của 2 tháng trước tháng báo cáo và các ngày trong tháng báo cáo sau khi tính tỷ lệ giao dịch của từng đối tác tại Sheet "Tỷ lệ" ' =SUM('Tỷ lệ'!$BK$3:DM3) (Tổng tỷ lệ giao dịch của từng đối tác) /COUNT('Tỷ lệ'!$BK$3:DM3) (Số ngày tính trung bình của từng đối tác)
A4: NH TMCP An Bình (ABB) | B4: =SUM('Tỷ lệ'!B4:BL4)/COUNT('Tỷ lệ'!B4:BL4) -> 0 | C4: =SUM('Tỷ lệ'!B4:BM4)/COUNT('Tỷ lệ'!B4:BM4) -> 0 | D4: =SUM('Tỷ lệ'!B4:BN4)/COUNT('Tỷ lệ'!B4:BN4) -> 0 | E4: =SUM('Tỷ lệ'!B4:BO4)/COUNT('Tỷ lệ'!B4:BO4) -> 0 | F4: =SUM('Tỷ lệ'!B4:BP4)/COUNT('Tỷ lệ'!B4:BP4) -> 0 | G4: =SUM('Tỷ lệ'!B4:BQ4)/COUNT('Tỷ lệ'!B4:BQ4) -> 0 | H4: =SUM('Tỷ lệ'!B4:BR4)/COUNT('Tỷ lệ'!B4:BR4) -> 0 | I4: =SUM('Tỷ lệ'!B4:BS4)/COUNT('Tỷ lệ'!B4:BS4) -> 0 | J4: =SUM('Tỷ lệ'!B4:BT4)/COUNT('Tỷ lệ'!B4:BT4) -> 0 | K4: =SUM('Tỷ lệ'!B4:BU4)/COUNT('Tỷ lệ'!B4:BU4) -> 0 | L4: =SUM('Tỷ lệ'!B4:BV4)/COUNT('Tỷ lệ'!B4:BV4) -> 0 | M4: =SUM('Tỷ lệ'!B4:BW4)/COUNT('Tỷ lệ'!B4:BW4) -> 0 | N4: =SUM('Tỷ lệ'!B4:BX4)/COUNT('Tỷ lệ'!B4:BX4) -> 0 | O4: =SUM('Tỷ lệ'!B4:BY4)/COUNT('Tỷ lệ'!B4:BY4) -> 0 | P4: =SUM('Tỷ lệ'!B4:BZ4)/COUNT('Tỷ lệ'!B4:BZ4) -> 0 | Q4: =SUM('Tỷ lệ'!B4:CA4)/COUNT('Tỷ lệ'!B4:CA4) -> 0 | R4: =SUM('Tỷ lệ'!B4:CB4)/COUNT('Tỷ lệ'!B4:CB4) -> 0 | S4: 0 | T4: 0 | U4: 0 | V4: 0 | W4: 0 | X4: 0 | Y4: 0 | Z4: 0 | AA4: 0 | AB4: 0 | AC4: 0 | AD4: 0 | AE4: 0 | AF4: 0 | AG4: 0 | AH4: 0 | AI4: 0 | AJ4: 0 | AK4: 0 | AL4: =SUM('Tỷ lệ'!B4:AK4)/COUNT('Tỷ lệ'!B4:AK4) -> 0 | AM4: 0 | AN4: 0 | AO4: =SUM('Tỷ lệ'!$BK$3:CX4)/COUNT('Tỷ lệ'!$BK$3:CX4) -> 0 | AP4: =SUM('Tỷ lệ'!$BK$3:CY4)/COUNT('Tỷ lệ'!$BK$3:CY4) -> 0 | AQ4: =SUM('Tỷ lệ'!$BK$3:CZ4)/COUNT('Tỷ lệ'!$BK$3:CZ4) -> 0 | AR4: =SUM('Tỷ lệ'!$BK$3:DA4)/COUNT('Tỷ lệ'!$BK$3:DA4) -> 0 | AS4: =SUM('Tỷ lệ'!$BK$3:DB4)/COUNT('Tỷ lệ'!$BK$3:DB4) -> 0 | AT4: =SUM('Tỷ lệ'!$BK$3:DC4)/COUNT('Tỷ lệ'!$BK$3:DC4) -> 0 | AU4: =SUM('Tỷ lệ'!$BK$3:DD4)/COUNT('Tỷ lệ'!$BK$3:DD4) -> 0 | AV4: =SUM('Tỷ lệ'!$BK$3:DE4)/COUNT('Tỷ lệ'!$BK$3:DE4) -> 0 | ... BF4: =SUM('Tỷ lệ'!$BK$3:DO4)/COUNT('Tỷ lệ'!$BK$3:DO4) -> 0 | BG4: 0 | BH4: 0 | BI4: 0 | BJ4: 0 | BK4: 0 | BL4: 0 | BM4: 0 | BN4: 0 | BO4: 0 | BP4: 0 | BQ4: 0
A5: NH TMCP Bắc Á | B5: =SUM('Tỷ lệ'!B5:BL5)/COUNT('Tỷ lệ'!B5:BL5) -> 0 | C5: =SUM('Tỷ lệ'!B5:BM5)/COUNT('Tỷ lệ'!B5:BM5) -> 0 | D5: =SUM('Tỷ lệ'!B5:BN5)/COUNT('Tỷ lệ'!B5:BN5) -> 0 | E5: =SUM('Tỷ lệ'!B5:BO5)/COUNT('Tỷ lệ'!B5:BO5) -> 0 | F5: =SUM('Tỷ lệ'!B5:BP5)/COUNT('Tỷ lệ'!B5:BP5) -> 0 | G5: =SUM('Tỷ lệ'!B5:BQ5)/COUNT('Tỷ lệ'!B5:BQ5) -> 0 | H5: =SUM('Tỷ lệ'!B5:BR5)/COUNT('Tỷ lệ'!B5:BR5) -> 0 | I5: =SUM('Tỷ lệ'!B5:BS5)/COUNT('Tỷ lệ'!B5:BS5) -> 0 | J5: =SUM('Tỷ lệ'!B5:BT5)/COUNT('Tỷ lệ'!B5:BT5) -> 0 | K5: =SUM('Tỷ lệ'!B5:BU5)/COUNT('Tỷ lệ'!B5:BU5) -> 0 | L5: =SUM('Tỷ lệ'!B5:BV5)/COUNT('Tỷ lệ'!B5:BV5) -> 0 | M5: =SUM('Tỷ lệ'!B5:BW5)/COUNT('Tỷ lệ'!B5:BW5) -> 0 | N5: =SUM('Tỷ lệ'!B5:BX5)/COUNT('Tỷ lệ'!B5:BX5) -> 0 | O5: =SUM('Tỷ lệ'!B5:BY5)/COUNT('Tỷ lệ'!B5:BY5) -> 0 | P5: =SUM('Tỷ lệ'!B5:BZ5)/COUNT('Tỷ lệ'!B5:BZ5) -> 0 | Q5: =SUM('Tỷ lệ'!B5:CA5)/COUNT('Tỷ lệ'!B5:CA5) -> 0 | R5: =SUM('Tỷ lệ'!B5:CB5)/COUNT('Tỷ lệ'!B5:CB5) -> 0 | S5: 0 | T5: 0 | U5: 0 | V5: 0 | W5: 0 | X5: 0 | Y5: 0 | Z5: 0 | AA5: 0 | AB5: 0 | AC5: 0 | AD5: 0 | AE5: 0 | AF5: 0 | AG5: 0 | AH5: 0 | AI5: 0 | AJ5: 0 | AK5: 0 | AL5: =SUM('Tỷ lệ'!B5:AK5)/COUNT('Tỷ lệ'!B5:AK5) -> 0 | AM5: 0 | AN5: 0 | AO5: =SUM('Tỷ lệ'!$BK$3:CX5)/COUNT('Tỷ lệ'!$BK$3:CX5) -> 0 | AP5: =SUM('Tỷ lệ'!$BK$3:CY5)/COUNT('Tỷ lệ'!$BK$3:CY5) -> 0 | AQ5: =SUM('Tỷ lệ'!$BK$3:CZ5)/COUNT('Tỷ lệ'!$BK$3:CZ5) -> 0 | AR5: =SUM('Tỷ lệ'!$BK$3:DA5)/COUNT('Tỷ lệ'!$BK$3:DA5) -> 0 | AS5: =SUM('Tỷ lệ'!$BK$3:DB5)/COUNT('Tỷ lệ'!$BK$3:DB5) -> 0 | AT5: =SUM('Tỷ lệ'!$BK$3:DC5)/COUNT('Tỷ lệ'!$BK$3:DC5) -> 0 | AU5: =SUM('Tỷ lệ'!$BK$3:DD5)/COUNT('Tỷ lệ'!$BK$3:DD5) -> 0 | AV5: =SUM('Tỷ lệ'!$BK$3:DE5)/COUNT('Tỷ lệ'!$BK$3:DE5) -> 0 | ... BF5: =SUM('Tỷ lệ'!$BK$3:DO5)/COUNT('Tỷ lệ'!$BK$3:DO5) -> 0 | BG5: 0 | BH5: 0 | BI5: 0 | BJ5: 0 | BK5: 0 | BL5: 0 | BM5: 0 | BN5: 0 | BO5: 0 | BP5: 0 | BQ5: 0
A6: NH TMCP Bản Việt | B6: =SUM('Tỷ lệ'!B6:BL6)/COUNT('Tỷ lệ'!B6:BL6) -> 0 | C6: =SUM('Tỷ lệ'!B6:BM6)/COUNT('Tỷ lệ'!B6:BM6) -> 0 | D6: =SUM('Tỷ lệ'!B6:BN6)/COUNT('Tỷ lệ'!B6:BN6) -> 0 | E6: =SUM('Tỷ lệ'!B6:BO6)/COUNT('Tỷ lệ'!B6:BO6) -> 0 | F6: =SUM('Tỷ lệ'!B6:BP6)/COUNT('Tỷ lệ'!B6:BP6) -> 0 | G6: =SUM('Tỷ lệ'!B6:BQ6)/COUNT('Tỷ lệ'!B6:BQ6) -> 0 | H6: =SUM('Tỷ lệ'!B6:BR6)/COUNT('Tỷ lệ'!B6:BR6) -> 0 | I6: =SUM('Tỷ lệ'!B6:BS6)/COUNT('Tỷ lệ'!B6:BS6) -> 0 | J6: =SUM('Tỷ lệ'!B6:BT6)/COUNT('Tỷ lệ'!B6:BT6) -> 0 | K6: =SUM('Tỷ lệ'!B6:BU6)/COUNT('Tỷ lệ'!B6:BU6) -> 0 | L6: =SUM('Tỷ lệ'!B6:BV6)/COUNT('Tỷ lệ'!B6:BV6) -> 0 | M6: =SUM('Tỷ lệ'!B6:BW6)/COUNT('Tỷ lệ'!B6:BW6) -> 0 | N6: =SUM('Tỷ lệ'!B6:BX6)/COUNT('Tỷ lệ'!B6:BX6) -> 0 | O6: =SUM('Tỷ lệ'!B6:BY6)/COUNT('Tỷ lệ'!B6:BY6) -> 0 | P6: =SUM('Tỷ lệ'!B6:BZ6)/COUNT('Tỷ lệ'!B6:BZ6) -> 0 | Q6: =SUM('Tỷ lệ'!B6:CA6)/COUNT('Tỷ lệ'!B6:CA6) -> 0 | R6: =SUM('Tỷ lệ'!B6:CB6)/COUNT('Tỷ lệ'!B6:CB6) -> 0 | S6: 0 | T6: 0 | U6: 0 | V6: 0 | W6: 0 | X6: 0 | Y6: 0 | Z6: 0 | AA6: 0 | AB6: 0 | AC6: 0 | AD6: 0 | AE6: 0 | AF6: 0 | AG6: 0 | AH6: 0 | AI6: 0 | AJ6: 0 | AK6: 0 | AL6: =SUM('Tỷ lệ'!B6:AK6)/COUNT('Tỷ lệ'!B6:AK6) -> 0 | AM6: 0 | AN6: 0 | AO6: =SUM('Tỷ lệ'!$BK$3:CX6)/COUNT('Tỷ lệ'!$BK$3:CX6) -> 0 | AP6: =SUM('Tỷ lệ'!$BK$3:CY6)/COUNT('Tỷ lệ'!$BK$3:CY6) -> 0 | AQ6: =SUM('Tỷ lệ'!$BK$3:CZ6)/COUNT('Tỷ lệ'!$BK$3:CZ6) -> 0 | AR6: =SUM('Tỷ lệ'!$BK$3:DA6)/COUNT('Tỷ lệ'!$BK$3:DA6) -> 0 | AS6: =SUM('Tỷ lệ'!$BK$3:DB6)/COUNT('Tỷ lệ'!$BK$3:DB6) -> 0 | AT6: =SUM('Tỷ lệ'!$BK$3:DC6)/COUNT('Tỷ lệ'!$BK$3:DC6) -> 0 | AU6: =SUM('Tỷ lệ'!$BK$3:DD6)/COUNT('Tỷ lệ'!$BK$3:DD6) -> 0 | AV6: =SUM('Tỷ lệ'!$BK$3:DE6)/COUNT('Tỷ lệ'!$BK$3:DE6) -> 0 | ... BF6: =SUM('Tỷ lệ'!$BK$3:DO6)/COUNT('Tỷ lệ'!$BK$3:DO6) -> 0 | BG6: 0 | BH6: 0 | BI6: 0 | BJ6: 0 | BK6: 0 | BL6: 0 | BM6: 0 | BN6: 0 | BO6: 0 | BP6: 0 | BQ6: 0
A7: NH TMCP Đầu tư và Phát triển VN (BIDV) | B7: =SUM('Tỷ lệ'!B7:BL7)/COUNT('Tỷ lệ'!B7:BL7) -> 0 | C7: =SUM('Tỷ lệ'!B7:BM7)/COUNT('Tỷ lệ'!B7:BM7) -> 0 | D7: =SUM('Tỷ lệ'!B7:BN7)/COUNT('Tỷ lệ'!B7:BN7) -> 0 | E7: =SUM('Tỷ lệ'!B7:BO7)/COUNT('Tỷ lệ'!B7:BO7) -> 0 | F7: =SUM('Tỷ lệ'!B7:BP7)/COUNT('Tỷ lệ'!B7:BP7) -> 0 | G7: =SUM('Tỷ lệ'!B7:BQ7)/COUNT('Tỷ lệ'!B7:BQ7) -> 0 | H7: =SUM('Tỷ lệ'!B7:BR7)/COUNT('Tỷ lệ'!B7:BR7) -> 0 | I7: =SUM('Tỷ lệ'!B7:BS7)/COUNT('Tỷ lệ'!B7:BS7) -> 0 | J7: =SUM('Tỷ lệ'!B7:BT7)/COUNT('Tỷ lệ'!B7:BT7) -> 0 | K7: =SUM('Tỷ lệ'!B7:BU7)/COUNT('Tỷ lệ'!B7:BU7) -> 0 | L7: =SUM('Tỷ lệ'!B7:BV7)/COUNT('Tỷ lệ'!B7:BV7) -> 0 | M7: =SUM('Tỷ lệ'!B7:BW7)/COUNT('Tỷ lệ'!B7:BW7) -> 0 | N7: =SUM('Tỷ lệ'!B7:BX7)/COUNT('Tỷ lệ'!B7:BX7) -> 0 | O7: =SUM('Tỷ lệ'!B7:BY7)/COUNT('Tỷ lệ'!B7:BY7) -> 0 | P7: =SUM('Tỷ lệ'!B7:BZ7)/COUNT('Tỷ lệ'!B7:BZ7) -> 0 | Q7: =SUM('Tỷ lệ'!B7:CA7)/COUNT('Tỷ lệ'!B7:CA7) -> 0 | R7: =SUM('Tỷ lệ'!B7:CB7)/COUNT('Tỷ lệ'!B7:CB7) -> 0 | S7: 0 | T7: 0 | U7: 0 | V7: 0 | W7: 0 | X7: 0 | Y7: 0 | Z7: 0 | AA7: 0 | AB7: 0 | AC7: 0 | AD7: 0 | AE7: 0 | AF7: 0 | AG7: 0 | AH7: 0 | AI7: 0 | AJ7: 0 | AK7: 0 | AL7: =SUM('Tỷ lệ'!B7:AK7)/COUNT('Tỷ lệ'!B7:AK7) -> 0 | AM7: 0 | AN7: 0 | AO7: =SUM('Tỷ lệ'!$BK$3:CX7)/COUNT('Tỷ lệ'!$BK$3:CX7) -> 0 | AP7: =SUM('Tỷ lệ'!$BK$3:CY7)/COUNT('Tỷ lệ'!$BK$3:CY7) -> 0 | AQ7: =SUM('Tỷ lệ'!$BK$3:CZ7)/COUNT('Tỷ lệ'!$BK$3:CZ7) -> 0 | AR7: =SUM('Tỷ lệ'!$BK$3:DA7)/COUNT('Tỷ lệ'!$BK$3:DA7) -> 0 | AS7: =SUM('Tỷ lệ'!$BK$3:DB7)/COUNT('Tỷ lệ'!$BK$3:DB7) -> 0 | AT7: =SUM('Tỷ lệ'!$BK$3:DC7)/COUNT('Tỷ lệ'!$BK$3:DC7) -> 0 | AU7: =SUM('Tỷ lệ'!$BK$3:DD7)/COUNT('Tỷ lệ'!$BK$3:DD7) -> 0 | AV7: =SUM('Tỷ lệ'!$BK$3:DE7)/COUNT('Tỷ lệ'!$BK$3:DE7) -> 0 | ... BF7: =SUM('Tỷ lệ'!$BK$3:DO7)/COUNT('Tỷ lệ'!$BK$3:DO7) -> 0 | BG7: 0 | BH7: 0 | BI7: 0 | BJ7: 0 | BK7: 0 | BL7: 0 | BM7: 0 | BN7: 0 | BO7: 0 | BP7: 0 | BQ7: 0
A8: Công ty tài chính cổ phần Điện lực (EVNFC) | B8: =SUM('Tỷ lệ'!B8:BL8)/COUNT('Tỷ lệ'!B8:BL8) -> 0 | C8: =SUM('Tỷ lệ'!B8:BM8)/COUNT('Tỷ lệ'!B8:BM8) -> 0 | D8: =SUM('Tỷ lệ'!B8:BN8)/COUNT('Tỷ lệ'!B8:BN8) -> 0 | E8: =SUM('Tỷ lệ'!B8:BO8)/COUNT('Tỷ lệ'!B8:BO8) -> 0 | F8: =SUM('Tỷ lệ'!B8:BP8)/COUNT('Tỷ lệ'!B8:BP8) -> 0 | G8: =SUM('Tỷ lệ'!B8:BQ8)/COUNT('Tỷ lệ'!B8:BQ8) -> 0 | H8: =SUM('Tỷ lệ'!B8:BR8)/COUNT('Tỷ lệ'!B8:BR8) -> 0 | I8: =SUM('Tỷ lệ'!B8:BS8)/COUNT('Tỷ lệ'!B8:BS8) -> 0 | J8: =SUM('Tỷ lệ'!B8:BT8)/COUNT('Tỷ lệ'!B8:BT8) -> 0 | K8: =SUM('Tỷ lệ'!B8:BU8)/COUNT('Tỷ lệ'!B8:BU8) -> 0 | L8: =SUM('Tỷ lệ'!B8:BV8)/COUNT('Tỷ lệ'!B8:BV8) -> 0 | M8: =SUM('Tỷ lệ'!B8:BW8)/COUNT('Tỷ lệ'!B8:BW8) -> 0 | N8: =SUM('Tỷ lệ'!B8:BX8)/COUNT('Tỷ lệ'!B8:BX8) -> 0 | O8: =SUM('Tỷ lệ'!B8:BY8)/COUNT('Tỷ lệ'!B8:BY8) -> 0 | P8: =SUM('Tỷ lệ'!B8:BZ8)/COUNT('Tỷ lệ'!B8:BZ8) -> 0 | Q8: =SUM('Tỷ lệ'!B8:CA8)/COUNT('Tỷ lệ'!B8:CA8) -> 0 | R8: =SUM('Tỷ lệ'!B8:CB8)/COUNT('Tỷ lệ'!B8:CB8) -> 0 | S8: 0 | T8: 0 | U8: 0 | V8: 0 | W8: 0 | X8: 0 | Y8: 0 | Z8: 0 | AA8: 0 | AB8: 0 | AC8: 0 | AD8: 0 | AE8: 0 | AF8: 0 | AG8: 0 | AH8: 0 | AI8: 0 | AJ8: 0 | AK8: 0 | AL8: =SUM('Tỷ lệ'!B8:AK8)/COUNT('Tỷ lệ'!B8:AK8) -> 0 | AM8: 0 | AN8: 0 | AO8: =SUM('Tỷ lệ'!$BK$3:CX8)/COUNT('Tỷ lệ'!$BK$3:CX8) -> 0 | AP8: =SUM('Tỷ lệ'!$BK$3:CY8)/COUNT('Tỷ lệ'!$BK$3:CY8) -> 0 | AQ8: =SUM('Tỷ lệ'!$BK$3:CZ8)/COUNT('Tỷ lệ'!$BK$3:CZ8) -> 0 | AR8: =SUM('Tỷ lệ'!$BK$3:DA8)/COUNT('Tỷ lệ'!$BK$3:DA8) -> 0 | AS8: =SUM('Tỷ lệ'!$BK$3:DB8)/COUNT('Tỷ lệ'!$BK$3:DB8) -> 0 | AT8: =SUM('Tỷ lệ'!$BK$3:DC8)/COUNT('Tỷ lệ'!$BK$3:DC8) -> 0 | AU8: =SUM('Tỷ lệ'!$BK$3:DD8)/COUNT('Tỷ lệ'!$BK$3:DD8) -> 0 | AV8: =SUM('Tỷ lệ'!$BK$3:DE8)/COUNT('Tỷ lệ'!$BK$3:DE8) -> 0 | ... BF8: =SUM('Tỷ lệ'!$BK$3:DO8)/COUNT('Tỷ lệ'!$BK$3:DO8) -> 0 | BG8: 0 | BH8: 0 | BI8: 0 | BJ8: 0 | BK8: 0 | BL8: 0 | BM8: 0 | BN8: 0 | BO8: 0 | BP8: 0 | BQ8: 0
A9: Công ty Tài Chính Cổ phần Tín Việt (VietCredit) | B9: =SUM('Tỷ lệ'!B9:BL9)/COUNT('Tỷ lệ'!B9:BL9) -> 0 | C9: =SUM('Tỷ lệ'!B9:BM9)/COUNT('Tỷ lệ'!B9:BM9) -> 0 | D9: =SUM('Tỷ lệ'!B9:BN9)/COUNT('Tỷ lệ'!B9:BN9) -> 0 | E9: =SUM('Tỷ lệ'!B9:BO9)/COUNT('Tỷ lệ'!B9:BO9) -> 0 | F9: =SUM('Tỷ lệ'!B9:BP9)/COUNT('Tỷ lệ'!B9:BP9) -> 0 | G9: =SUM('Tỷ lệ'!B9:BQ9)/COUNT('Tỷ lệ'!B9:BQ9) -> 0 | H9: =SUM('Tỷ lệ'!B9:BR9)/COUNT('Tỷ lệ'!B9:BR9) -> 0 | I9: =SUM('Tỷ lệ'!B9:BS9)/COUNT('Tỷ lệ'!B9:BS9) -> 0 | J9: =SUM('Tỷ lệ'!B9:BT9)/COUNT('Tỷ lệ'!B9:BT9) -> 0 | K9: =SUM('Tỷ lệ'!B9:BU9)/COUNT('Tỷ lệ'!B9:BU9) -> 0 | L9: =SUM('Tỷ lệ'!B9:BV9)/COUNT('Tỷ lệ'!B9:BV9) -> 0 | M9: =SUM('Tỷ lệ'!B9:BW9)/COUNT('Tỷ lệ'!B9:BW9) -> 0 | N9: =SUM('Tỷ lệ'!B9:BX9)/COUNT('Tỷ lệ'!B9:BX9) -> 0 | O9: =SUM('Tỷ lệ'!B9:BY9)/COUNT('Tỷ lệ'!B9:BY9) -> 0 | P9: =SUM('Tỷ lệ'!B9:BZ9)/COUNT('Tỷ lệ'!B9:BZ9) -> 0 | Q9: =SUM('Tỷ lệ'!B9:CA9)/COUNT('Tỷ lệ'!B9:CA9) -> 0 | R9: =SUM('Tỷ lệ'!B9:CB9)/COUNT('Tỷ lệ'!B9:CB9) -> 0 | S9: 0 | T9: 0 | U9: 0 | V9: 0 | W9: 0 | X9: 0 | Y9: 0 | Z9: 0 | AA9: 0 | AB9: 0 | AC9: 0 | AD9: 0 | AE9: 0 | AF9: 0 | AG9: 0 | AH9: 0 | AI9: 0 | AJ9: 0 | AK9: 0 | AL9: =SUM('Tỷ lệ'!B9:AK9)/COUNT('Tỷ lệ'!B9:AK9) -> 0 | AM9: 0 | AN9: 0 | AO9: =SUM('Tỷ lệ'!$BK$3:CX9)/COUNT('Tỷ lệ'!$BK$3:CX9) -> 0 | AP9: =SUM('Tỷ lệ'!$BK$3:CY9)/COUNT('Tỷ lệ'!$BK$3:CY9) -> 0 | AQ9: =SUM('Tỷ lệ'!$BK$3:CZ9)/COUNT('Tỷ lệ'!$BK$3:CZ9) -> 0 | AR9: =SUM('Tỷ lệ'!$BK$3:DA9)/COUNT('Tỷ lệ'!$BK$3:DA9) -> 0 | AS9: =SUM('Tỷ lệ'!$BK$3:DB9)/COUNT('Tỷ lệ'!$BK$3:DB9) -> 0 | AT9: =SUM('Tỷ lệ'!$BK$3:DC9)/COUNT('Tỷ lệ'!$BK$3:DC9) -> 0 | AU9: =SUM('Tỷ lệ'!$BK$3:DD9)/COUNT('Tỷ lệ'!$BK$3:DD9) -> 0 | AV9: =SUM('Tỷ lệ'!$BK$3:DE9)/COUNT('Tỷ lệ'!$BK$3:DE9) -> 0 | ... BF9: =SUM('Tỷ lệ'!$BK$3:DO9)/COUNT('Tỷ lệ'!$BK$3:DO9) -> 0 | BG9: 0 | BH9: 0 | BI9: 0 | BJ9: 0 | BK9: 0 | BL9: 0 | BM9: 0 | BN9: 0 | BO9: 0 | BP9: 0 | BQ9: 0
A10: Công ty Tài chính TNHH HD SaiSon (HDSS) | B10: =SUM('Tỷ lệ'!B10:BL10)/COUNT('Tỷ lệ'!B10:BL10) -> 0 | C10: =SUM('Tỷ lệ'!B10:BM10)/COUNT('Tỷ lệ'!B10:BM10) -> 0 | D10: =SUM('Tỷ lệ'!B10:BN10)/COUNT('Tỷ lệ'!B10:BN10) -> 0 | E10: =SUM('Tỷ lệ'!B10:BO10)/COUNT('Tỷ lệ'!B10:BO10) -> 0 | F10: =SUM('Tỷ lệ'!B10:BP10)/COUNT('Tỷ lệ'!B10:BP10) -> 0 | G10: =SUM('Tỷ lệ'!B10:BQ10)/COUNT('Tỷ lệ'!B10:BQ10) -> 0 | H10: =SUM('Tỷ lệ'!B10:BR10)/COUNT('Tỷ lệ'!B10:BR10) -> 0 | I10: =SUM('Tỷ lệ'!B10:BS10)/COUNT('Tỷ lệ'!B10:BS10) -> 0 | J10: =SUM('Tỷ lệ'!B10:BT10)/COUNT('Tỷ lệ'!B10:BT10) -> 0 | K10: =SUM('Tỷ lệ'!B10:BU10)/COUNT('Tỷ lệ'!B10:BU10) -> 0 | L10: =SUM('Tỷ lệ'!B10:BV10)/COUNT('Tỷ lệ'!B10:BV10) -> 0 | M10: =SUM('Tỷ lệ'!B10:BW10)/COUNT('Tỷ lệ'!B10:BW10) -> 0 | N10: =SUM('Tỷ lệ'!B10:BX10)/COUNT('Tỷ lệ'!B10:BX10) -> 0 | O10: =SUM('Tỷ lệ'!B10:BY10)/COUNT('Tỷ lệ'!B10:BY10) -> 0 | P10: =SUM('Tỷ lệ'!B10:BZ10)/COUNT('Tỷ lệ'!B10:BZ10) -> 0 | Q10: =SUM('Tỷ lệ'!B10:CA10)/COUNT('Tỷ lệ'!B10:CA10) -> 0 | R10: =SUM('Tỷ lệ'!B10:CB10)/COUNT('Tỷ lệ'!B10:CB10) -> 0 | S10: 0 | T10: 0 | U10: 0 | V10: 0 | W10: 0 | X10: 0 | Y10: 0 | Z10: 0 | AA10: 0 | AB10: 0 | AC10: 0 | AD10: 0 | AE10: 0 | AF10: 0 | AG10: 0 | AH10: 0 | AI10: 0 | AJ10: 0 | AK10: 0 | AL10: =SUM('Tỷ lệ'!B10:AK10)/COUNT('Tỷ lệ'!B10:AK10) -> 0 | AM10: 0 | AN10: 0 | AO10: =SUM('Tỷ lệ'!$BK$3:CX10)/COUNT('Tỷ lệ'!$BK$3:CX10) -> 0 | AP10: =SUM('Tỷ lệ'!$BK$3:CY10)/COUNT('Tỷ lệ'!$BK$3:CY10) -> 0 | AQ10: =SUM('Tỷ lệ'!$BK$3:CZ10)/COUNT('Tỷ lệ'!$BK$3:CZ10) -> 0 | AR10: =SUM('Tỷ lệ'!$BK$3:DA10)/COUNT('Tỷ lệ'!$BK$3:DA10) -> 0 | AS10: =SUM('Tỷ lệ'!$BK$3:DB10)/COUNT('Tỷ lệ'!$BK$3:DB10) -> 0 | AT10: =SUM('Tỷ lệ'!$BK$3:DC10)/COUNT('Tỷ lệ'!$BK$3:DC10) -> 0 | AU10: =SUM('Tỷ lệ'!$BK$3:DD10)/COUNT('Tỷ lệ'!$BK$3:DD10) -> 0 | AV10: =SUM('Tỷ lệ'!$BK$3:DE10)/COUNT('Tỷ lệ'!$BK$3:DE10) -> 0 | ... BF10: =SUM('Tỷ lệ'!$BK$3:DO10)/COUNT('Tỷ lệ'!$BK$3:DO10) -> 0 | BG10: 0 | BH10: 0 | BI10: 0 | BJ10: 0 | BK10: 0 | BL10: 0 | BM10: 0 | BN10: 0 | BO10: 0 | BP10: 0 | BQ10: 0
A11: Công ty tài chính TNHH MTV Home Credit VN (HCVN) | B11: =SUM('Tỷ lệ'!B11:BL11)/COUNT('Tỷ lệ'!B11:BL11) -> 0 | C11: =SUM('Tỷ lệ'!B11:BM11)/COUNT('Tỷ lệ'!B11:BM11) -> 0 | D11: =SUM('Tỷ lệ'!B11:BN11)/COUNT('Tỷ lệ'!B11:BN11) -> 0 | E11: =SUM('Tỷ lệ'!B11:BO11)/COUNT('Tỷ lệ'!B11:BO11) -> 0 | F11: =SUM('Tỷ lệ'!B11:BP11)/COUNT('Tỷ lệ'!B11:BP11) -> 0 | G11: =SUM('Tỷ lệ'!B11:BQ11)/COUNT('Tỷ lệ'!B11:BQ11) -> 0 | H11: =SUM('Tỷ lệ'!B11:BR11)/COUNT('Tỷ lệ'!B11:BR11) -> 0 | I11: =SUM('Tỷ lệ'!B11:BS11)/COUNT('Tỷ lệ'!B11:BS11) -> 0 | J11: =SUM('Tỷ lệ'!B11:BT11)/COUNT('Tỷ lệ'!B11:BT11) -> 0 | K11: =SUM('Tỷ lệ'!B11:BU11)/COUNT('Tỷ lệ'!B11:BU11) -> 0 | L11: =SUM('Tỷ lệ'!B11:BV11)/COUNT('Tỷ lệ'!B11:BV11) -> 0 | M11: =SUM('Tỷ lệ'!B11:BW11)/COUNT('Tỷ lệ'!B11:BW11) -> 0 | N11: =SUM('Tỷ lệ'!B11:BX11)/COUNT('Tỷ lệ'!B11:BX11) -> 0 | O11: =SUM('Tỷ lệ'!B11:BY11)/COUNT('Tỷ lệ'!B11:BY11) -> 0 | P11: =SUM('Tỷ lệ'!B11:BZ11)/COUNT('Tỷ lệ'!B11:BZ11) -> 0 | Q11: =SUM('Tỷ lệ'!B11:CA11)/COUNT('Tỷ lệ'!B11:CA11) -> 0 | R11: =SUM('Tỷ lệ'!B11:CB11)/COUNT('Tỷ lệ'!B11:CB11) -> 0 | S11: 0 | T11: 0 | U11: 0 | V11: 0 | W11: 0 | X11: 0 | Y11: 0 | Z11: 0 | AA11: 0 | AB11: 0 | AC11: 0 | AD11: 0 | AE11: 0 | AF11: 0 | AG11: 0 | AH11: 0 | AI11: 0 | AJ11: 0 | AK11: 0 | AL11: =SUM('Tỷ lệ'!B11:AK11)/COUNT('Tỷ lệ'!B11:AK11) -> 0 | AM11: 0 | AN11: 0 | AO11: =SUM('Tỷ lệ'!$BK$3:CX11)/COUNT('Tỷ lệ'!$BK$3:CX11) -> 0 | AP11: =SUM('Tỷ lệ'!$BK$3:CY11)/COUNT('Tỷ lệ'!$BK$3:CY11) -> 0 | AQ11: =SUM('Tỷ lệ'!$BK$3:CZ11)/COUNT('Tỷ lệ'!$BK$3:CZ11) -> 0 | AR11: =SUM('Tỷ lệ'!$BK$3:DA11)/COUNT('Tỷ lệ'!$BK$3:DA11) -> 0 | AS11: =SUM('Tỷ lệ'!$BK$3:DB11)/COUNT('Tỷ lệ'!$BK$3:DB11) -> 0 | AT11: =SUM('Tỷ lệ'!$BK$3:DC11)/COUNT('Tỷ lệ'!$BK$3:DC11) -> 0 | AU11: =SUM('Tỷ lệ'!$BK$3:DD11)/COUNT('Tỷ lệ'!$BK$3:DD11) -> 0 | AV11: =SUM('Tỷ lệ'!$BK$3:DE11)/COUNT('Tỷ lệ'!$BK$3:DE11) -> 0 | ... BF11: =SUM('Tỷ lệ'!$BK$3:DO11)/COUNT('Tỷ lệ'!$BK$3:DO11) -> 0 | BG11: 0 | BH11: 0 | BI11: 0 | BJ11: 0 | BK11: 0 | BL11: 0 | BM11: 0 | BN11: 0 | BO11: 0 | BP11: 0 | BQ11: 0
A12: Công ty tài chính TNHH MTV Ngân hàng TMCP Sài Gòn-Hà Nội (SHBF) | B12: =SUM('Tỷ lệ'!B12:BL12)/COUNT('Tỷ lệ'!B12:BL12) -> 0 | C12: =SUM('Tỷ lệ'!B12:BM12)/COUNT('Tỷ lệ'!B12:BM12) -> 0 | D12: =SUM('Tỷ lệ'!B12:BN12)/COUNT('Tỷ lệ'!B12:BN12) -> 0 | E12: =SUM('Tỷ lệ'!B12:BO12)/COUNT('Tỷ lệ'!B12:BO12) -> 0 | F12: =SUM('Tỷ lệ'!B12:BP12)/COUNT('Tỷ lệ'!B12:BP12) -> 0 | G12: =SUM('Tỷ lệ'!B12:BQ12)/COUNT('Tỷ lệ'!B12:BQ12) -> 0 | H12: =SUM('Tỷ lệ'!B12:BR12)/COUNT('Tỷ lệ'!B12:BR12) -> 0 | I12: =SUM('Tỷ lệ'!B12:BS12)/COUNT('Tỷ lệ'!B12:BS12) -> 0 | J12: =SUM('Tỷ lệ'!B12:BT12)/COUNT('Tỷ lệ'!B12:BT12) -> 0 | K12: =SUM('Tỷ lệ'!B12:BU12)/COUNT('Tỷ lệ'!B12:BU12) -> 0 | L12: =SUM('Tỷ lệ'!B12:BV12)/COUNT('Tỷ lệ'!B12:BV12) -> 0 | M12: =SUM('Tỷ lệ'!B12:BW12)/COUNT('Tỷ lệ'!B12:BW12) -> 0 | N12: =SUM('Tỷ lệ'!B12:BX12)/COUNT('Tỷ lệ'!B12:BX12) -> 0 | O12: =SUM('Tỷ lệ'!B12:BY12)/COUNT('Tỷ lệ'!B12:BY12) -> 0 | P12: =SUM('Tỷ lệ'!B12:BZ12)/COUNT('Tỷ lệ'!B12:BZ12) -> 0 | Q12: =SUM('Tỷ lệ'!B12:CA12)/COUNT('Tỷ lệ'!B12:CA12) -> 0 | R12: =SUM('Tỷ lệ'!B12:CB12)/COUNT('Tỷ lệ'!B12:CB12) -> 0 | S12: 0 | T12: 0 | U12: 0 | V12: 0 | W12: 0 | X12: 0 | Y12: 0 | Z12: 0 | AA12: 0 | AB12: 0 | AC12: 0 | AD12: 0 | AE12: 0 | AF12: 0 | AG12: 0 | AH12: 0 | AI12: 0 | AJ12: 0 | AK12: 0 | AL12: =SUM('Tỷ lệ'!B12:AK12)/COUNT('Tỷ lệ'!B12:AK12) -> 0 | AM12: 0 | AN12: 0 | AO12: =SUM('Tỷ lệ'!$BK$3:CX12)/COUNT('Tỷ lệ'!$BK$3:CX12) -> 0 | AP12: =SUM('Tỷ lệ'!$BK$3:CY12)/COUNT('Tỷ lệ'!$BK$3:CY12) -> 0 | AQ12: =SUM('Tỷ lệ'!$BK$3:CZ12)/COUNT('Tỷ lệ'!$BK$3:CZ12) -> 0 | AR12: =SUM('Tỷ lệ'!$BK$3:DA12)/COUNT('Tỷ lệ'!$BK$3:DA12) -> 0 | AS12: =SUM('Tỷ lệ'!$BK$3:DB12)/COUNT('Tỷ lệ'!$BK$3:DB12) -> 0 | AT12: =SUM('Tỷ lệ'!$BK$3:DC12)/COUNT('Tỷ lệ'!$BK$3:DC12) -> 0 | AU12: =SUM('Tỷ lệ'!$BK$3:DD12)/COUNT('Tỷ lệ'!$BK$3:DD12) -> 0 | AV12: =SUM('Tỷ lệ'!$BK$3:DE12)/COUNT('Tỷ lệ'!$BK$3:DE12) -> 0 | ... BF12: =SUM('Tỷ lệ'!$BK$3:DO12)/COUNT('Tỷ lệ'!$BK$3:DO12) -> 0 | BG12: 0 | BH12: 0 | BI12: 0 | BJ12: 0 | BK12: 0 | BL12: 0 | BM12: 0 | BN12: 0 | BO12: 0 | BP12: 0 | BQ12: 0
A13: Công ty tài chính TNHH MB Shinsei (Mcredit) | B13: =SUM('Tỷ lệ'!B13:BL13)/COUNT('Tỷ lệ'!B13:BL13) -> 0 | C13: =SUM('Tỷ lệ'!B13:BM13)/COUNT('Tỷ lệ'!B13:BM13) -> 0 | D13: =SUM('Tỷ lệ'!B13:BN13)/COUNT('Tỷ lệ'!B13:BN13) -> 0 | E13: =SUM('Tỷ lệ'!B13:BO13)/COUNT('Tỷ lệ'!B13:BO13) -> 0 | F13: =SUM('Tỷ lệ'!B13:BP13)/COUNT('Tỷ lệ'!B13:BP13) -> 0 | G13: =SUM('Tỷ lệ'!B13:BQ13)/COUNT('Tỷ lệ'!B13:BQ13) -> 0 | H13: =SUM('Tỷ lệ'!B13:BR13)/COUNT('Tỷ lệ'!B13:BR13) -> 0 | I13: =SUM('Tỷ lệ'!B13:BS13)/COUNT('Tỷ lệ'!B13:BS13) -> 0 | J13: =SUM('Tỷ lệ'!B13:BT13)/COUNT('Tỷ lệ'!B13:BT13) -> 0 | K13: =SUM('Tỷ lệ'!B13:BU13)/COUNT('Tỷ lệ'!B13:BU13) -> 0 | L13: =SUM('Tỷ lệ'!B13:BV13)/COUNT('Tỷ lệ'!B13:BV13) -> 0 | M13: =SUM('Tỷ lệ'!B13:BW13)/COUNT('Tỷ lệ'!B13:BW13) -> 0 | N13: =SUM('Tỷ lệ'!B13:BX13)/COUNT('Tỷ lệ'!B13:BX13) -> 0 | O13: =SUM('Tỷ lệ'!B13:BY13)/COUNT('Tỷ lệ'!B13:BY13) -> 0 | P13: =SUM('Tỷ lệ'!B13:BZ13)/COUNT('Tỷ lệ'!B13:BZ13) -> 0 | Q13: =SUM('Tỷ lệ'!B13:CA13)/COUNT('Tỷ lệ'!B13:CA13) -> 0 | R13: =SUM('Tỷ lệ'!B13:CB13)/COUNT('Tỷ lệ'!B13:CB13) -> 0 | S13: 0 | T13: 0 | U13: 0 | V13: 0 | W13: 0 | X13: 0 | Y13: 0 | Z13: 0 | AA13: 0 | AB13: 0 | AC13: 0 | AD13: 0 | AE13: 0 | AF13: 0 | AG13: 0 | AH13: 0 | AI13: 0 | AJ13: 0 | AK13: 0 | AL13: =SUM('Tỷ lệ'!B13:AK13)/COUNT('Tỷ lệ'!B13:AK13) -> 0 | AM13: 0 | AN13: 0 | AO13: =SUM('Tỷ lệ'!$BK$3:CX13)/COUNT('Tỷ lệ'!$BK$3:CX13) -> 0 | AP13: =SUM('Tỷ lệ'!$BK$3:CY13)/COUNT('Tỷ lệ'!$BK$3:CY13) -> 0 | AQ13: =SUM('Tỷ lệ'!$BK$3:CZ13)/COUNT('Tỷ lệ'!$BK$3:CZ13) -> 0 | AR13: =SUM('Tỷ lệ'!$BK$3:DA13)/COUNT('Tỷ lệ'!$BK$3:DA13) -> 0 | AS13: =SUM('Tỷ lệ'!$BK$3:DB13)/COUNT('Tỷ lệ'!$BK$3:DB13) -> 0 | AT13: =SUM('Tỷ lệ'!$BK$3:DC13)/COUNT('Tỷ lệ'!$BK$3:DC13) -> 0 | AU13: =SUM('Tỷ lệ'!$BK$3:DD13)/COUNT('Tỷ lệ'!$BK$3:DD13) -> 0 | AV13: =SUM('Tỷ lệ'!$BK$3:DE13)/COUNT('Tỷ lệ'!$BK$3:DE13) -> 0 | ... BF13: =SUM('Tỷ lệ'!$BK$3:DO13)/COUNT('Tỷ lệ'!$BK$3:DO13) -> 0 | BG13: 0 | BH13: 0 | BI13: 0 | BJ13: 0 | BK13: 0 | BL13: 0 | BM13: 0 | BN13: 0 | BO13: 0 | BP13: 0 | BQ13: 0
A14: NH TMCP Đại Chúng VN (PVC) | B14: =SUM('Tỷ lệ'!B14:BL14)/COUNT('Tỷ lệ'!B14:BL14) -> 0 | C14: =SUM('Tỷ lệ'!B14:BM14)/COUNT('Tỷ lệ'!B14:BM14) -> 0 | D14: =SUM('Tỷ lệ'!B14:BN14)/COUNT('Tỷ lệ'!B14:BN14) -> 0 | E14: =SUM('Tỷ lệ'!B14:BO14)/COUNT('Tỷ lệ'!B14:BO14) -> 0 | F14: =SUM('Tỷ lệ'!B14:BP14)/COUNT('Tỷ lệ'!B14:BP14) -> 0 | G14: =SUM('Tỷ lệ'!B14:BQ14)/COUNT('Tỷ lệ'!B14:BQ14) -> 0 | H14: =SUM('Tỷ lệ'!B14:BR14)/COUNT('Tỷ lệ'!B14:BR14) -> 0 | I14: =SUM('Tỷ lệ'!B14:BS14)/COUNT('Tỷ lệ'!B14:BS14) -> 0 | J14: =SUM('Tỷ lệ'!B14:BT14)/COUNT('Tỷ lệ'!B14:BT14) -> 0 | K14: =SUM('Tỷ lệ'!B14:BU14)/COUNT('Tỷ lệ'!B14:BU14) -> 0 | L14: =SUM('Tỷ lệ'!B14:BV14)/COUNT('Tỷ lệ'!B14:BV14) -> 0 | M14: =SUM('Tỷ lệ'!B14:BW14)/COUNT('Tỷ lệ'!B14:BW14) -> 0 | N14: =SUM('Tỷ lệ'!B14:BX14)/COUNT('Tỷ lệ'!B14:BX14) -> 0 | O14: =SUM('Tỷ lệ'!B14:BY14)/COUNT('Tỷ lệ'!B14:BY14) -> 0 | P14: =SUM('Tỷ lệ'!B14:BZ14)/COUNT('Tỷ lệ'!B14:BZ14) -> 0 | Q14: =SUM('Tỷ lệ'!B14:CA14)/COUNT('Tỷ lệ'!B14:CA14) -> 0 | R14: =SUM('Tỷ lệ'!B14:CB14)/COUNT('Tỷ lệ'!B14:CB14) -> 0 | S14: 0 | T14: 0 | U14: 0 | V14: 0 | W14: 0 | X14: 0 | Y14: 0 | Z14: 0 | AA14: 0 | AB14: 0 | AC14: 0 | AD14: 0 | AE14: 0 | AF14: 0 | AG14: 0 | AH14: 0 | AI14: 0 | AJ14: 0 | AK14: 0 | AL14: =SUM('Tỷ lệ'!B14:AK14)/COUNT('Tỷ lệ'!B14:AK14) -> 0 | AM14: 0 | AN14: 0 | AO14: =SUM('Tỷ lệ'!$BK$3:CX14)/COUNT('Tỷ lệ'!$BK$3:CX14) -> 0 | AP14: =SUM('Tỷ lệ'!$BK$3:CY14)/COUNT('Tỷ lệ'!$BK$3:CY14) -> 0 | AQ14: =SUM('Tỷ lệ'!$BK$3:CZ14)/COUNT('Tỷ lệ'!$BK$3:CZ14) -> 0 | AR14: =SUM('Tỷ lệ'!$BK$3:DA14)/COUNT('Tỷ lệ'!$BK$3:DA14) -> 0 | AS14: =SUM('Tỷ lệ'!$BK$3:DB14)/COUNT('Tỷ lệ'!$BK$3:DB14) -> 0 | AT14: =SUM('Tỷ lệ'!$BK$3:DC14)/COUNT('Tỷ lệ'!$BK$3:DC14) -> 0 | AU14: =SUM('Tỷ lệ'!$BK$3:DD14)/COUNT('Tỷ lệ'!$BK$3:DD14) -> 0 | AV14: =SUM('Tỷ lệ'!$BK$3:DE14)/COUNT('Tỷ lệ'!$BK$3:DE14) -> 0 | ... BF14: =SUM('Tỷ lệ'!$BK$3:DO14)/COUNT('Tỷ lệ'!$BK$3:DO14) -> 0 | BG14: 0 | BH14: 0 | BI14: 0 | BJ14: 0 | BK14: 0 | BL14: 0 | BM14: 0 | BN14: 0 | BO14: 0 | BP14: 0 | BQ14: 0
A15: NH TMCP Đông Nam Á (SeaBank) | B15: =SUM('Tỷ lệ'!B15:BL15)/COUNT('Tỷ lệ'!B15:BL15) -> 0 | C15: =SUM('Tỷ lệ'!B15:BM15)/COUNT('Tỷ lệ'!B15:BM15) -> 0 | D15: =SUM('Tỷ lệ'!B15:BN15)/COUNT('Tỷ lệ'!B15:BN15) -> 0 | E15: =SUM('Tỷ lệ'!B15:BO15)/COUNT('Tỷ lệ'!B15:BO15) -> 0 | F15: =SUM('Tỷ lệ'!B15:BP15)/COUNT('Tỷ lệ'!B15:BP15) -> 0 | G15: =SUM('Tỷ lệ'!B15:BQ15)/COUNT('Tỷ lệ'!B15:BQ15) -> 0 | H15: =SUM('Tỷ lệ'!B15:BR15)/COUNT('Tỷ lệ'!B15:BR15) -> 0 | I15: =SUM('Tỷ lệ'!B15:BS15)/COUNT('Tỷ lệ'!B15:BS15) -> 0 | J15: =SUM('Tỷ lệ'!B15:BT15)/COUNT('Tỷ lệ'!B15:BT15) -> 0 | K15: =SUM('Tỷ lệ'!B15:BU15)/COUNT('Tỷ lệ'!B15:BU15) -> 0 | L15: =SUM('Tỷ lệ'!B15:BV15)/COUNT('Tỷ lệ'!B15:BV15) -> 0 | M15: =SUM('Tỷ lệ'!B15:BW15)/COUNT('Tỷ lệ'!B15:BW15) -> 0 | N15: =SUM('Tỷ lệ'!B15:BX15)/COUNT('Tỷ lệ'!B15:BX15) -> 0 | O15: =SUM('Tỷ lệ'!B15:BY15)/COUNT('Tỷ lệ'!B15:BY15) -> 0 | P15: =SUM('Tỷ lệ'!B15:BZ15)/COUNT('Tỷ lệ'!B15:BZ15) -> 0 | Q15: =SUM('Tỷ lệ'!B15:CA15)/COUNT('Tỷ lệ'!B15:CA15) -> 0 | R15: =SUM('Tỷ lệ'!B15:CB15)/COUNT('Tỷ lệ'!B15:CB15) -> 0 | S15: 0 | T15: 0 | U15: 0 | V15: 0 | W15: 0 | X15: 0 | Y15: 0 | Z15: 0 | AA15: 0 | AB15: 0 | AC15: 0 | AD15: 0 | AE15: 0 | AF15: 0 | AG15: 0 | AH15: 0 | AI15: 0 | AJ15: 0 | AK15: 0 | AL15: =SUM('Tỷ lệ'!B15:AK15)/COUNT('Tỷ lệ'!B15:AK15) -> 0 | AM15: 0 | AN15: 0 | AO15: =SUM('Tỷ lệ'!$BK$3:CX15)/COUNT('Tỷ lệ'!$BK$3:CX15) -> 0 | AP15: =SUM('Tỷ lệ'!$BK$3:CY15)/COUNT('Tỷ lệ'!$BK$3:CY15) -> 0 | AQ15: =SUM('Tỷ lệ'!$BK$3:CZ15)/COUNT('Tỷ lệ'!$BK$3:CZ15) -> 0 | AR15: =SUM('Tỷ lệ'!$BK$3:DA15)/COUNT('Tỷ lệ'!$BK$3:DA15) -> 0 | AS15: =SUM('Tỷ lệ'!$BK$3:DB15)/COUNT('Tỷ lệ'!$BK$3:DB15) -> 0 | AT15: =SUM('Tỷ lệ'!$BK$3:DC15)/COUNT('Tỷ lệ'!$BK$3:DC15) -> 0 | AU15: =SUM('Tỷ lệ'!$BK$3:DD15)/COUNT('Tỷ lệ'!$BK$3:DD15) -> 0 | AV15: =SUM('Tỷ lệ'!$BK$3:DE15)/COUNT('Tỷ lệ'!$BK$3:DE15) -> 0 | ... BF15: =SUM('Tỷ lệ'!$BK$3:DO15)/COUNT('Tỷ lệ'!$BK$3:DO15) -> 0 | BG15: 0 | BH15: 0 | BI15: 0 | BJ15: 0 | BK15: 0 | BL15: 0 | BM15: 0 | BN15: 0 | BO15: 0 | BP15: 0 | BQ15: 0
... A21: NH TMCP Nam Á | B21: =SUM('Tỷ lệ'!B21:BL21)/COUNT('Tỷ lệ'!B21:BL21) -> 0 | C21: =SUM('Tỷ lệ'!B21:BM21)/COUNT('Tỷ lệ'!B21:BM21) -> 0 | D21: =SUM('Tỷ lệ'!B21:BN21)/COUNT('Tỷ lệ'!B21:BN21) -> 0 | E21: =SUM('Tỷ lệ'!B21:BO21)/COUNT('Tỷ lệ'!B21:BO21) -> 0 | F21: =SUM('Tỷ lệ'!B21:BP21)/COUNT('Tỷ lệ'!B21:BP21) -> 0 | G21: =SUM('Tỷ lệ'!B21:BQ21)/COUNT('Tỷ lệ'!B21:BQ21) -> 0 | H21: =SUM('Tỷ lệ'!B21:BR21)/COUNT('Tỷ lệ'!B21:BR21) -> 0 | I21: =SUM('Tỷ lệ'!B21:BS21)/COUNT('Tỷ lệ'!B21:BS21) -> 0 | J21: =SUM('Tỷ lệ'!B21:BT21)/COUNT('Tỷ lệ'!B21:BT21) -> 0 | K21: =SUM('Tỷ lệ'!B21:BU21)/COUNT('Tỷ lệ'!B21:BU21) -> 0 | L21: =SUM('Tỷ lệ'!B21:BV21)/COUNT('Tỷ lệ'!B21:BV21) -> 0 | M21: =SUM('Tỷ lệ'!B21:BW21)/COUNT('Tỷ lệ'!B21:BW21) -> 0 | N21: =SUM('Tỷ lệ'!B21:BX21)/COUNT('Tỷ lệ'!B21:BX21) -> 0 | O21: =SUM('Tỷ lệ'!B21:BY21)/COUNT('Tỷ lệ'!B21:BY21) -> 0 | P21: =SUM('Tỷ lệ'!B21:BZ21)/COUNT('Tỷ lệ'!B21:BZ21) -> 0 | Q21: =SUM('Tỷ lệ'!B21:CA21)/COUNT('Tỷ lệ'!B21:CA21) -> 0 | R21: =SUM('Tỷ lệ'!B21:CB21)/COUNT('Tỷ lệ'!B21:CB21) -> 0 | S21: 0 | T21: 0 | U21: 0 | V21: 0 | W21: 0 | X21: 0 | Y21: 0 | Z21: 0 | AA21: 0 | AB21: 0 | AC21: 0 | AD21: 0 | AE21: 0 | AF21: 0 | AG21: 0 | AH21: 0 | AI21: 0 | AJ21: 0 | AK21: 0 | AL21: =SUM('Tỷ lệ'!B21:AK21)/COUNT('Tỷ lệ'!B21:AK21) -> 0 | AM21: 0 | AN21: 0 | AO21: =SUM('Tỷ lệ'!$BK$3:CX21)/COUNT('Tỷ lệ'!$BK$3:CX21) -> 0 | AP21: =SUM('Tỷ lệ'!$BK$3:CY21)/COUNT('Tỷ lệ'!$BK$3:CY21) -> 0 | AQ21: =SUM('Tỷ lệ'!$BK$3:CZ21)/COUNT('Tỷ lệ'!$BK$3:CZ21) -> 0 | AR21: =SUM('Tỷ lệ'!$BK$3:DA21)/COUNT('Tỷ lệ'!$BK$3:DA21) -> 0 | AS21: =SUM('Tỷ lệ'!$BK$3:DB21)/COUNT('Tỷ lệ'!$BK$3:DB21) -> 0 | AT21: =SUM('Tỷ lệ'!$BK$3:DC21)/COUNT('Tỷ lệ'!$BK$3:DC21) -> 0 | AU21: =SUM('Tỷ lệ'!$BK$3:DD21)/COUNT('Tỷ lệ'!$BK$3:DD21) -> 0 | AV21: =SUM('Tỷ lệ'!$BK$3:DE21)/COUNT('Tỷ lệ'!$BK$3:DE21) -> 0 | ... BF21: =SUM('Tỷ lệ'!$BK$3:DO21)/COUNT('Tỷ lệ'!$BK$3:DO21) -> 0 | BG21: 0 | BH21: 0 | BI21: 0 | BJ21: 0 | BK21: 0 | BL21: 0 | BM21: 0 | BN21: 0 | BO21: 0 | BP21: 0 | BQ21: 0
A22: NH TMCP Phát triển TPHCM (HDB) | B22: =SUM('Tỷ lệ'!B22:BL22)/COUNT('Tỷ lệ'!B22:BL22) -> 0.031746032 | C22: =SUM('Tỷ lệ'!B22:BM22)/COUNT('Tỷ lệ'!B22:BM22) -> 0.03125 | D22: =SUM('Tỷ lệ'!B22:BN22)/COUNT('Tỷ lệ'!B22:BN22) -> 0.030769231 | E22: =SUM('Tỷ lệ'!B22:BO22)/COUNT('Tỷ lệ'!B22:BO22) -> 0.03030303 | F22: =SUM('Tỷ lệ'!B22:BP22)/COUNT('Tỷ lệ'!B22:BP22) -> 0.029850746 | G22: =SUM('Tỷ lệ'!B22:BQ22)/COUNT('Tỷ lệ'!B22:BQ22) -> 0.029411765 | H22: =SUM('Tỷ lệ'!B22:BR22)/COUNT('Tỷ lệ'!B22:BR22) -> 0.028985507 | I22: =SUM('Tỷ lệ'!B22:BS22)/COUNT('Tỷ lệ'!B22:BS22) -> 0.028571429 | J22: =SUM('Tỷ lệ'!B22:BT22)/COUNT('Tỷ lệ'!B22:BT22) -> 0.028169014 | K22: =SUM('Tỷ lệ'!B22:BU22)/COUNT('Tỷ lệ'!B22:BU22) -> 0.027777778 | L22: =SUM('Tỷ lệ'!B22:BV22)/COUNT('Tỷ lệ'!B22:BV22) -> 0.02739726 | M22: =SUM('Tỷ lệ'!B22:BW22)/COUNT('Tỷ lệ'!B22:BW22) -> 0.027027027 | N22: =SUM('Tỷ lệ'!B22:BX22)/COUNT('Tỷ lệ'!B22:BX22) -> 0.026666667 | O22: =SUM('Tỷ lệ'!B22:BY22)/COUNT('Tỷ lệ'!B22:BY22) -> 0.026315789 | P22: =SUM('Tỷ lệ'!B22:BZ22)/COUNT('Tỷ lệ'!B22:BZ22) -> 0.025974026 | Q22: =SUM('Tỷ lệ'!B22:CA22)/COUNT('Tỷ lệ'!B22:CA22) -> 0.025641026 | R22: =SUM('Tỷ lệ'!B22:CB22)/COUNT('Tỷ lệ'!B22:CB22) -> 0.025316456 | S22: 0.025 | T22: 0.024691358 | U22: 0.024390244 | V22: 0.024096386 | W22: 0.023809524 | X22: 0 | Y22: 0 | Z22: 0 | AA22: 0 | AB22: 0 | AC22: 0 | AD22: 0 | AE22: 0 | AF22: 0 | AG22: 0 | AH22: 0 | AI22: 0 | AJ22: 0 | AK22: 0 | AL22: 0 | AM22: 0 | AN22: 0 | AO22: =SUM('Tỷ lệ'!$BK$3:CX22)/COUNT('Tỷ lệ'!$BK$3:CX22) -> 0 | AP22: =SUM('Tỷ lệ'!$BK$3:CY22)/COUNT('Tỷ lệ'!$BK$3:CY22) -> 0 | AQ22: =SUM('Tỷ lệ'!$BK$3:CZ22)/COUNT('Tỷ lệ'!$BK$3:CZ22) -> 0 | AR22: =SUM('Tỷ lệ'!$BK$3:DA22)/COUNT('Tỷ lệ'!$BK$3:DA22) -> 0 | AS22: =SUM('Tỷ lệ'!$BK$3:DB22)/COUNT('Tỷ lệ'!$BK$3:DB22) -> 0 | AT22: =SUM('Tỷ lệ'!$BK$3:DC22)/COUNT('Tỷ lệ'!$BK$3:DC22) -> 0 | AU22: =SUM('Tỷ lệ'!$BK$3:DD22)/COUNT('Tỷ lệ'!$BK$3:DD22) -> 0 | AV22: =SUM('Tỷ lệ'!$BK$3:DE22)/COUNT('Tỷ lệ'!$BK$3:DE22) -> 0 | ... BF22: =SUM('Tỷ lệ'!$BK$3:DO22)/COUNT('Tỷ lệ'!$BK$3:DO22) -> 0 | BG22: 0 | BH22: 0 | BI22: 0 | BJ22: 0 | BK22: 0 | BL22: 0 | BM22: 0 | BN22: 0 | BO22: 0 | BP22: 0 | BQ22: 0
A23: NH TMCP Phương Đông (OCB) | B23: =SUM('Tỷ lệ'!B23:BL23)/COUNT('Tỷ lệ'!B23:BL23) -> 0 | C23: =SUM('Tỷ lệ'!B23:BM23)/COUNT('Tỷ lệ'!B23:BM23) -> 0 | D23: =SUM('Tỷ lệ'!B23:BN23)/COUNT('Tỷ lệ'!B23:BN23) -> 0 | E23: =SUM('Tỷ lệ'!B23:BO23)/COUNT('Tỷ lệ'!B23:BO23) -> 0 | F23: =SUM('Tỷ lệ'!B23:BP23)/COUNT('Tỷ lệ'!B23:BP23) -> 0 | G23: =SUM('Tỷ lệ'!B23:BQ23)/COUNT('Tỷ lệ'!B23:BQ23) -> 0 | H23: =SUM('Tỷ lệ'!B23:BR23)/COUNT('Tỷ lệ'!B23:BR23) -> 0 | I23: =SUM('Tỷ lệ'!B23:BS23)/COUNT('Tỷ lệ'!B23:BS23) -> 0 | J23: =SUM('Tỷ lệ'!B23:BT23)/COUNT('Tỷ lệ'!B23:BT23) -> 0 | K23: =SUM('Tỷ lệ'!B23:BU23)/COUNT('Tỷ lệ'!B23:BU23) -> 0 | L23: =SUM('Tỷ lệ'!B23:BV23)/COUNT('Tỷ lệ'!B23:BV23) -> 0 | M23: =SUM('Tỷ lệ'!B23:BW23)/COUNT('Tỷ lệ'!B23:BW23) -> 0 | N23: =SUM('Tỷ lệ'!B23:BX23)/COUNT('Tỷ lệ'!B23:BX23) -> 0 | O23: =SUM('Tỷ lệ'!B23:BY23)/COUNT('Tỷ lệ'!B23:BY23) -> 0 | P23: =SUM('Tỷ lệ'!B23:BZ23)/COUNT('Tỷ lệ'!B23:BZ23) -> 0 | Q23: =SUM('Tỷ lệ'!B23:CA23)/COUNT('Tỷ lệ'!B23:CA23) -> 0 | R23: =SUM('Tỷ lệ'!B23:CB23)/COUNT('Tỷ lệ'!B23:CB23) -> 0 | S23: 0 | T23: 0 | U23: 0 | V23: 0 | W23: 0 | X23: 0 | Y23: 0 | Z23: 0 | AA23: 0 | AB23: 0 | AC23: 0 | AD23: 0 | AE23: 0 | AF23: 0 | AG23: 0 | AH23: 0 | AI23: 0 | AJ23: 0 | AK23: 0 | AL23: =SUM('Tỷ lệ'!B23:AK23)/COUNT('Tỷ lệ'!B23:AK23) -> 0 | AM23: 0 | AN23: 0 | AO23: =SUM('Tỷ lệ'!$BK$3:CX23)/COUNT('Tỷ lệ'!$BK$3:CX23) -> 0 | AP23: =SUM('Tỷ lệ'!$BK$3:CY23)/COUNT('Tỷ lệ'!$BK$3:CY23) -> 0 | AQ23: =SUM('Tỷ lệ'!$BK$3:CZ23)/COUNT('Tỷ lệ'!$BK$3:CZ23) -> 0 | AR23: =SUM('Tỷ lệ'!$BK$3:DA23)/COUNT('Tỷ lệ'!$BK$3:DA23) -> 0 | AS23: =SUM('Tỷ lệ'!$BK$3:DB23)/COUNT('Tỷ lệ'!$BK$3:DB23) -> 0 | AT23: =SUM('Tỷ lệ'!$BK$3:DC23)/COUNT('Tỷ lệ'!$BK$3:DC23) -> 0 | AU23: =SUM('Tỷ lệ'!$BK$3:DD23)/COUNT('Tỷ lệ'!$BK$3:DD23) -> 0 | AV23: =SUM('Tỷ lệ'!$BK$3:DE23)/COUNT('Tỷ lệ'!$BK$3:DE23) -> 0 | ... BF23: =SUM('Tỷ lệ'!$BK$3:DO23)/COUNT('Tỷ lệ'!$BK$3:DO23) -> 0 | BG23: 0 | BH23: 0 | BI23: 0 | BJ23: 0 | BK23: 0 | BL23: 0 | BM23: 0 | BN23: 0 | BO23: 0 | BP23: 0 | BQ23: 0
A24: NH TMCP Quân đội (MBB) | B24: =SUM('Tỷ lệ'!B24:BL24)/COUNT('Tỷ lệ'!B24:BL24) -> 0 | C24: =SUM('Tỷ lệ'!B24:BM24)/COUNT('Tỷ lệ'!B24:BM24) -> 0 | D24: =SUM('Tỷ lệ'!B24:BN24)/COUNT('Tỷ lệ'!B24:BN24) -> 0 | E24: =SUM('Tỷ lệ'!B24:BO24)/COUNT('Tỷ lệ'!B24:BO24) -> 0 | F24: =SUM('Tỷ lệ'!B24:BP24)/COUNT('Tỷ lệ'!B24:BP24) -> 0 | G24: =SUM('Tỷ lệ'!B24:BQ24)/COUNT('Tỷ lệ'!B24:BQ24) -> 0 | H24: =SUM('Tỷ lệ'!B24:BR24)/COUNT('Tỷ lệ'!B24:BR24) -> 0 | I24: =SUM('Tỷ lệ'!B24:BS24)/COUNT('Tỷ lệ'!B24:BS24) -> 0 | J24: =SUM('Tỷ lệ'!B24:BT24)/COUNT('Tỷ lệ'!B24:BT24) -> 0 | K24: =SUM('Tỷ lệ'!B24:BU24)/COUNT('Tỷ lệ'!B24:BU24) -> 0 | L24: =SUM('Tỷ lệ'!B24:BV24)/COUNT('Tỷ lệ'!B24:BV24) -> 0 | M24: =SUM('Tỷ lệ'!B24:BW24)/COUNT('Tỷ lệ'!B24:BW24) -> 0 | N24: =SUM('Tỷ lệ'!B24:BX24)/COUNT('Tỷ lệ'!B24:BX24) -> 0 | O24: =SUM('Tỷ lệ'!B24:BY24)/COUNT('Tỷ lệ'!B24:BY24) -> 0 | P24: =SUM('Tỷ lệ'!B24:BZ24)/COUNT('Tỷ lệ'!B24:BZ24) -> 0 | Q24: =SUM('Tỷ lệ'!B24:CA24)/COUNT('Tỷ lệ'!B24:CA24) -> 0 | R24: =SUM('Tỷ lệ'!B24:CB24)/COUNT('Tỷ lệ'!B24:CB24) -> 0 | S24: 0 | T24: 0 | U24: 0 | V24: 0 | W24: 0 | X24: 0 | Y24: 0 | Z24: 0 | AA24: 0 | AB24: 0 | AC24: 0 | AD24: 0 | AE24: 0 | AF24: 0 | AG24: 0 | AH24: 0 | AI24: 0 | AJ24: 0 | AK24: 0 | AL24: =SUM('Tỷ lệ'!B24:AK24)/COUNT('Tỷ lệ'!B24:AK24) -> 0 | AM24: 0 | AN24: 0 | AO24: =SUM('Tỷ lệ'!$BK$3:CX24)/COUNT('Tỷ lệ'!$BK$3:CX24) -> 0 | AP24: =SUM('Tỷ lệ'!$BK$3:CY24)/COUNT('Tỷ lệ'!$BK$3:CY24) -> 0 | AQ24: =SUM('Tỷ lệ'!$BK$3:CZ24)/COUNT('Tỷ lệ'!$BK$3:CZ24) -> 0 | AR24: =SUM('Tỷ lệ'!$BK$3:DA24)/COUNT('Tỷ lệ'!$BK$3:DA24) -> 0 | AS24: =SUM('Tỷ lệ'!$BK$3:DB24)/COUNT('Tỷ lệ'!$BK$3:DB24) -> 0 | AT24: =SUM('Tỷ lệ'!$BK$3:DC24)/COUNT('Tỷ lệ'!$BK$3:DC24) -> 0 | AU24: =SUM('Tỷ lệ'!$BK$3:DD24)/COUNT('Tỷ lệ'!$BK$3:DD24) -> 0 | AV24: =SUM('Tỷ lệ'!$BK$3:DE24)/COUNT('Tỷ lệ'!$BK$3:DE24) -> 0 | ... BF24: =SUM('Tỷ lệ'!$BK$3:DO24)/COUNT('Tỷ lệ'!$BK$3:DO24) -> 0 | BG24: 0 | BH24: 0 | BI24: 0 | BJ24: 0 | BK24: 0 | BL24: 0 | BM24: 0 | BN24: 0 | BO24: 0 | BP24: 0 | BQ24: 0
A25: NH TMCP Quốc dân (NCB) | B25: =SUM('Tỷ lệ'!B25:BL25)/COUNT('Tỷ lệ'!B25:BL25) -> 0 | C25: =SUM('Tỷ lệ'!B25:BM25)/COUNT('Tỷ lệ'!B25:BM25) -> 0 | D25: =SUM('Tỷ lệ'!B25:BN25)/COUNT('Tỷ lệ'!B25:BN25) -> 0 | E25: =SUM('Tỷ lệ'!B25:BO25)/COUNT('Tỷ lệ'!B25:BO25) -> 0 | F25: =SUM('Tỷ lệ'!B25:BP25)/COUNT('Tỷ lệ'!B25:BP25) -> 0 | G25: =SUM('Tỷ lệ'!B25:BQ25)/COUNT('Tỷ lệ'!B25:BQ25) -> 0 | H25: =SUM('Tỷ lệ'!B25:BR25)/COUNT('Tỷ lệ'!B25:BR25) -> 0 | I25: =SUM('Tỷ lệ'!B25:BS25)/COUNT('Tỷ lệ'!B25:BS25) -> 0 | J25: =SUM('Tỷ lệ'!B25:BT25)/COUNT('Tỷ lệ'!B25:BT25) -> 0 | K25: =SUM('Tỷ lệ'!B25:BU25)/COUNT('Tỷ lệ'!B25:BU25) -> 0 | L25: =SUM('Tỷ lệ'!B25:BV25)/COUNT('Tỷ lệ'!B25:BV25) -> 0 | M25: =SUM('Tỷ lệ'!B25:BW25)/COUNT('Tỷ lệ'!B25:BW25) -> 0 | N25: =SUM('Tỷ lệ'!B25:BX25)/COUNT('Tỷ lệ'!B25:BX25) -> 0 | O25: =SUM('Tỷ lệ'!B25:BY25)/COUNT('Tỷ lệ'!B25:BY25) -> 0 | P25: =SUM('Tỷ lệ'!B25:BZ25)/COUNT('Tỷ lệ'!B25:BZ25) -> 0 | Q25: =SUM('Tỷ lệ'!B25:CA25)/COUNT('Tỷ lệ'!B25:CA25) -> 0 | R25: =SUM('Tỷ lệ'!B25:CB25)/COUNT('Tỷ lệ'!B25:CB25) -> 0 | S25: 0 | T25: 0 | U25: 0 | V25: 0 | W25: 0 | X25: 0 | Y25: 0 | Z25: 0 | AA25: 0 | AB25: 0 | AC25: 0 | AD25: 0 | AE25: 0 | AF25: 0 | AG25: 0 | AH25: 0 | AI25: 0 | AJ25: 0 | AK25: 0 | AL25: =SUM('Tỷ lệ'!B25:AK25)/COUNT('Tỷ lệ'!B25:AK25) -> 0 | AM25: 0 | AN25: 0 | AO25: =SUM('Tỷ lệ'!$BK$3:CX25)/COUNT('Tỷ lệ'!$BK$3:CX25) -> 0 | AP25: =SUM('Tỷ lệ'!$BK$3:CY25)/COUNT('Tỷ lệ'!$BK$3:CY25) -> 0 | AQ25: =SUM('Tỷ lệ'!$BK$3:CZ25)/COUNT('Tỷ lệ'!$BK$3:CZ25) -> 0 | AR25: =SUM('Tỷ lệ'!$BK$3:DA25)/COUNT('Tỷ lệ'!$BK$3:DA25) -> 0 | AS25: =SUM('Tỷ lệ'!$BK$3:DB25)/COUNT('Tỷ lệ'!$BK$3:DB25) -> 0 | AT25: =SUM('Tỷ lệ'!$BK$3:DC25)/COUNT('Tỷ lệ'!$BK$3:DC25) -> 0 | AU25: =SUM('Tỷ lệ'!$BK$3:DD25)/COUNT('Tỷ lệ'!$BK$3:DD25) -> 0 | AV25: =SUM('Tỷ lệ'!$BK$3:DE25)/COUNT('Tỷ lệ'!$BK$3:DE25) -> 0 | ... BF25: =SUM('Tỷ lệ'!$BK$3:DO25)/COUNT('Tỷ lệ'!$BK$3:DO25) -> 0 | BG25: 0 | BH25: 0 | BI25: 0 | BJ25: 0 | BK25: 0 | BL25: 0 | BM25: 0 | BN25: 0 | BO25: 0 | BP25: 0 | BQ25: 0
A26: NH TMCP Quốc tế VN (VIB) | B26: =SUM('Tỷ lệ'!B26:BL26)/COUNT('Tỷ lệ'!B26:BL26) -> 0 | C26: =SUM('Tỷ lệ'!B26:BM26)/COUNT('Tỷ lệ'!B26:BM26) -> 0 | D26: =SUM('Tỷ lệ'!B26:BN26)/COUNT('Tỷ lệ'!B26:BN26) -> 0 | E26: =SUM('Tỷ lệ'!B26:BO26)/COUNT('Tỷ lệ'!B26:BO26) -> 0 | F26: =SUM('Tỷ lệ'!B26:BP26)/COUNT('Tỷ lệ'!B26:BP26) -> 0 | G26: =SUM('Tỷ lệ'!B26:BQ26)/COUNT('Tỷ lệ'!B26:BQ26) -> 0 | H26: =SUM('Tỷ lệ'!B26:BR26)/COUNT('Tỷ lệ'!B26:BR26) -> 0 | I26: =SUM('Tỷ lệ'!B26:BS26)/COUNT('Tỷ lệ'!B26:BS26) -> 0 | J26: =SUM('Tỷ lệ'!B26:BT26)/COUNT('Tỷ lệ'!B26:BT26) -> 0 | K26: =SUM('Tỷ lệ'!B26:BU26)/COUNT('Tỷ lệ'!B26:BU26) -> 0 | L26: =SUM('Tỷ lệ'!B26:BV26)/COUNT('Tỷ lệ'!B26:BV26) -> 0 | M26: =SUM('Tỷ lệ'!B26:BW26)/COUNT('Tỷ lệ'!B26:BW26) -> 0 | N26: =SUM('Tỷ lệ'!B26:BX26)/COUNT('Tỷ lệ'!B26:BX26) -> 0 | O26: =SUM('Tỷ lệ'!B26:BY26)/COUNT('Tỷ lệ'!B26:BY26) -> 0 | P26: =SUM('Tỷ lệ'!B26:BZ26)/COUNT('Tỷ lệ'!B26:BZ26) -> 0 | Q26: =SUM('Tỷ lệ'!B26:CA26)/COUNT('Tỷ lệ'!B26:CA26) -> 0 | R26: =SUM('Tỷ lệ'!B26:CB26)/COUNT('Tỷ lệ'!B26:CB26) -> 0 | S26: 0 | T26: 0 | U26: 0 | V26: 0 | W26: 0 | X26: 0 | Y26: 0 | Z26: 0 | AA26: 0 | AB26: 0 | AC26: 0 | AD26: 0 | AE26: 0 | AF26: 0 | AG26: 0 | AH26: 0 | AI26: 0 | AJ26: 0 | AK26: 0 | AL26: =SUM('Tỷ lệ'!B26:AK26)/COUNT('Tỷ lệ'!B26:AK26) -> 0 | AM26: 0 | AN26: 0 | AO26: =SUM('Tỷ lệ'!$BK$3:CX26)/COUNT('Tỷ lệ'!$BK$3:CX26) -> 0 | AP26: =SUM('Tỷ lệ'!$BK$3:CY26)/COUNT('Tỷ lệ'!$BK$3:CY26) -> 0 | AQ26: =SUM('Tỷ lệ'!$BK$3:CZ26)/COUNT('Tỷ lệ'!$BK$3:CZ26) -> 0 | AR26: =SUM('Tỷ lệ'!$BK$3:DA26)/COUNT('Tỷ lệ'!$BK$3:DA26) -> 0 | AS26: =SUM('Tỷ lệ'!$BK$3:DB26)/COUNT('Tỷ lệ'!$BK$3:DB26) -> 0 | AT26: =SUM('Tỷ lệ'!$BK$3:DC26)/COUNT('Tỷ lệ'!$BK$3:DC26) -> 0 | AU26: =SUM('Tỷ lệ'!$BK$3:DD26)/COUNT('Tỷ lệ'!$BK$3:DD26) -> 0 | AV26: =SUM('Tỷ lệ'!$BK$3:DE26)/COUNT('Tỷ lệ'!$BK$3:DE26) -> 0 | ... BF26: =SUM('Tỷ lệ'!$BK$3:DO26)/COUNT('Tỷ lệ'!$BK$3:DO26) -> 0 | BG26: 0 | BH26: 0 | BI26: 0 | BJ26: 0 | BK26: 0 | BL26: 0 | BM26: 0 | BN26: 0 | BO26: 0 | BP26: 0 | BQ26: 0
A27: NH TMCP Sài Gòn Thương Tín (Sacombank) | B27: =SUM('Tỷ lệ'!B27:BL27)/COUNT('Tỷ lệ'!B27:BL27) -> 0 | C27: =SUM('Tỷ lệ'!B27:BM27)/COUNT('Tỷ lệ'!B27:BM27) -> 0 | D27: =SUM('Tỷ lệ'!B27:BN27)/COUNT('Tỷ lệ'!B27:BN27) -> 0 | E27: =SUM('Tỷ lệ'!B27:BO27)/COUNT('Tỷ lệ'!B27:BO27) -> 0 | F27: =SUM('Tỷ lệ'!B27:BP27)/COUNT('Tỷ lệ'!B27:BP27) -> 0 | G27: =SUM('Tỷ lệ'!B27:BQ27)/COUNT('Tỷ lệ'!B27:BQ27) -> 0 | H27: =SUM('Tỷ lệ'!B27:BR27)/COUNT('Tỷ lệ'!B27:BR27) -> 0 | I27: =SUM('Tỷ lệ'!B27:BS27)/COUNT('Tỷ lệ'!B27:BS27) -> 0 | J27: =SUM('Tỷ lệ'!B27:BT27)/COUNT('Tỷ lệ'!B27:BT27) -> 0 | K27: =SUM('Tỷ lệ'!B27:BU27)/COUNT('Tỷ lệ'!B27:BU27) -> 0 | L27: =SUM('Tỷ lệ'!B27:BV27)/COUNT('Tỷ lệ'!B27:BV27) -> 0 | M27: =SUM('Tỷ lệ'!B27:BW27)/COUNT('Tỷ lệ'!B27:BW27) -> 0 | N27: =SUM('Tỷ lệ'!B27:BX27)/COUNT('Tỷ lệ'!B27:BX27) -> 0 | O27: =SUM('Tỷ lệ'!B27:BY27)/COUNT('Tỷ lệ'!B27:BY27) -> 0 | P27: =SUM('Tỷ lệ'!B27:BZ27)/COUNT('Tỷ lệ'!B27:BZ27) -> 0 | Q27: =SUM('Tỷ lệ'!B27:CA27)/COUNT('Tỷ lệ'!B27:CA27) -> 0 | R27: =SUM('Tỷ lệ'!B27:CB27)/COUNT('Tỷ lệ'!B27:CB27) -> 0 | S27: 0 | T27: 0 | U27: 0 | V27: 0 | W27: 0 | X27: 0 | Y27: 0 | Z27: 0 | AA27: 0 | AB27: 0 | AC27: 0 | AD27: 0 | AE27: 0 | AF27: 0 | AG27: 0 | AH27: 0 | AI27: 0 | AJ27: 0 | AK27: 0 | AL27: =SUM('Tỷ lệ'!B27:AK27)/COUNT('Tỷ lệ'!B27:AK27) -> 0 | AM27: 0 | AN27: 0 | AO27: =SUM('Tỷ lệ'!$BK$3:CX27)/COUNT('Tỷ lệ'!$BK$3:CX27) -> 0 | AP27: =SUM('Tỷ lệ'!$BK$3:CY27)/COUNT('Tỷ lệ'!$BK$3:CY27) -> 0 | AQ27: =SUM('Tỷ lệ'!$BK$3:CZ27)/COUNT('Tỷ lệ'!$BK$3:CZ27) -> 0 | AR27: =SUM('Tỷ lệ'!$BK$3:DA27)/COUNT('Tỷ lệ'!$BK$3:DA27) -> 0 | AS27: =SUM('Tỷ lệ'!$BK$3:DB27)/COUNT('Tỷ lệ'!$BK$3:DB27) -> 0 | AT27: =SUM('Tỷ lệ'!$BK$3:DC27)/COUNT('Tỷ lệ'!$BK$3:DC27) -> 0 | AU27: =SUM('Tỷ lệ'!$BK$3:DD27)/COUNT('Tỷ lệ'!$BK$3:DD27) -> 0 | AV27: =SUM('Tỷ lệ'!$BK$3:DE27)/COUNT('Tỷ lệ'!$BK$3:DE27) -> 0 | ... BF27: =SUM('Tỷ lệ'!$BK$3:DO27)/COUNT('Tỷ lệ'!$BK$3:DO27) -> 0 | BG27: 0 | BH27: 0 | BI27: 0 | BJ27: 0 | BK27: 0 | BL27: 0 | BM27: 0 | BN27: 0 | BO27: 0 | BP27: 0 | BQ27: 0
A28: NH TMCP Sài Gòn - Hà Nội (SHB) | B28: =SUM('Tỷ lệ'!B28:BL28)/COUNT('Tỷ lệ'!B28:BL28) -> 0 | C28: =SUM('Tỷ lệ'!B28:BM28)/COUNT('Tỷ lệ'!B28:BM28) -> 0 | D28: =SUM('Tỷ lệ'!B28:BN28)/COUNT('Tỷ lệ'!B28:BN28) -> 0 | E28: =SUM('Tỷ lệ'!B28:BO28)/COUNT('Tỷ lệ'!B28:BO28) -> 0 | F28: =SUM('Tỷ lệ'!B28:BP28)/COUNT('Tỷ lệ'!B28:BP28) -> 0 | G28: =SUM('Tỷ lệ'!B28:BQ28)/COUNT('Tỷ lệ'!B28:BQ28) -> 0 | H28: =SUM('Tỷ lệ'!B28:BR28)/COUNT('Tỷ lệ'!B28:BR28) -> 0 | I28: =SUM('Tỷ lệ'!B28:BS28)/COUNT('Tỷ lệ'!B28:BS28) -> 0 | J28: =SUM('Tỷ lệ'!B28:BT28)/COUNT('Tỷ lệ'!B28:BT28) -> 0 | K28: =SUM('Tỷ lệ'!B28:BU28)/COUNT('Tỷ lệ'!B28:BU28) -> 0 | L28: =SUM('Tỷ lệ'!B28:BV28)/COUNT('Tỷ lệ'!B28:BV28) -> 0 | M28: =SUM('Tỷ lệ'!B28:BW28)/COUNT('Tỷ lệ'!B28:BW28) -> 0 | N28: =SUM('Tỷ lệ'!B28:BX28)/COUNT('Tỷ lệ'!B28:BX28) -> 0 | O28: =SUM('Tỷ lệ'!B28:BY28)/COUNT('Tỷ lệ'!B28:BY28) -> 0 | P28: =SUM('Tỷ lệ'!B28:BZ28)/COUNT('Tỷ lệ'!B28:BZ28) -> 0 | Q28: =SUM('Tỷ lệ'!B28:CA28)/COUNT('Tỷ lệ'!B28:CA28) -> 0 | R28: =SUM('Tỷ lệ'!B28:CB28)/COUNT('Tỷ lệ'!B28:CB28) -> 0 | S28: 0 | T28: 0 | U28: 0 | V28: 0 | W28: 0 | X28: 0 | Y28: 0 | Z28: 0 | AA28: 0 | AB28: 0 | AC28: 0 | AD28: 0 | AE28: 0 | AF28: 0 | AG28: 0 | AH28: 0 | AI28: 0 | AJ28: 0 | AK28: 0 | AL28: =SUM('Tỷ lệ'!B28:AK28)/COUNT('Tỷ lệ'!B28:AK28) -> 0 | AM28: 0 | AN28: 0 | AO28: =SUM('Tỷ lệ'!$BK$3:CX28)/COUNT('Tỷ lệ'!$BK$3:CX28) -> 0 | AP28: =SUM('Tỷ lệ'!$BK$3:CY28)/COUNT('Tỷ lệ'!$BK$3:CY28) -> 0 | AQ28: =SUM('Tỷ lệ'!$BK$3:CZ28)/COUNT('Tỷ lệ'!$BK$3:CZ28) -> 0 | AR28: =SUM('Tỷ lệ'!$BK$3:DA28)/COUNT('Tỷ lệ'!$BK$3:DA28) -> 0 | AS28: =SUM('Tỷ lệ'!$BK$3:DB28)/COUNT('Tỷ lệ'!$BK$3:DB28) -> 0 | AT28: =SUM('Tỷ lệ'!$BK$3:DC28)/COUNT('Tỷ lệ'!$BK$3:DC28) -> 0 | AU28: =SUM('Tỷ lệ'!$BK$3:DD28)/COUNT('Tỷ lệ'!$BK$3:DD28) -> 0 | AV28: =SUM('Tỷ lệ'!$BK$3:DE28)/COUNT('Tỷ lệ'!$BK$3:DE28) -> 0 | ... BF28: =SUM('Tỷ lệ'!$BK$3:DO28)/COUNT('Tỷ lệ'!$BK$3:DO28) -> 0 | BG28: 0 | BH28: 0 | BI28: 0 | BJ28: 0 | BK28: 0 | BL28: 0 | BM28: 0 | BN28: 0 | BO28: 0 | BP28: 0 | BQ28: 0
A29: NH TMCP VN Thịnh Vượng (VPB) | B29: =SUM('Tỷ lệ'!B29:BL29)/COUNT('Tỷ lệ'!B29:BL29) -> 0 | C29: =SUM('Tỷ lệ'!B29:BM29)/COUNT('Tỷ lệ'!B29:BM29) -> 0 | D29: =SUM('Tỷ lệ'!B29:BN29)/COUNT('Tỷ lệ'!B29:BN29) -> 0 | E29: =SUM('Tỷ lệ'!B29:BO29)/COUNT('Tỷ lệ'!B29:BO29) -> 0 | F29: =SUM('Tỷ lệ'!B29:BP29)/COUNT('Tỷ lệ'!B29:BP29) -> 0 | G29: =SUM('Tỷ lệ'!B29:BQ29)/COUNT('Tỷ lệ'!B29:BQ29) -> 0 | H29: =SUM('Tỷ lệ'!B29:BR29)/COUNT('Tỷ lệ'!B29:BR29) -> 0 | I29: =SUM('Tỷ lệ'!B29:BS29)/COUNT('Tỷ lệ'!B29:BS29) -> 0 | J29: =SUM('Tỷ lệ'!B29:BT29)/COUNT('Tỷ lệ'!B29:BT29) -> 0 | K29: =SUM('Tỷ lệ'!B29:BU29)/COUNT('Tỷ lệ'!B29:BU29) -> 0 | L29: =SUM('Tỷ lệ'!B29:BV29)/COUNT('Tỷ lệ'!B29:BV29) -> 0 | M29: =SUM('Tỷ lệ'!B29:BW29)/COUNT('Tỷ lệ'!B29:BW29) -> 0 | N29: =SUM('Tỷ lệ'!B29:BX29)/COUNT('Tỷ lệ'!B29:BX29) -> 0 | O29: =SUM('Tỷ lệ'!B29:BY29)/COUNT('Tỷ lệ'!B29:BY29) -> 0 | P29: =SUM('Tỷ lệ'!B29:BZ29)/COUNT('Tỷ lệ'!B29:BZ29) -> 0 | Q29: =SUM('Tỷ lệ'!B29:CA29)/COUNT('Tỷ lệ'!B29:CA29) -> 0 | R29: =SUM('Tỷ lệ'!B29:CB29)/COUNT('Tỷ lệ'!B29:CB29) -> 0 | S29: 0 | T29: 0 | U29: 0 | V29: 0 | W29: 0 | X29: 0 | Y29: 0 | Z29: 0 | AA29: 0 | AB29: 0 | AC29: 0 | AD29: 0 | AE29: 0 | AF29: 0 | AG29: 0 | AH29: 0 | AI29: 0 | AJ29: 0 | AK29: 0 | AL29: =SUM('Tỷ lệ'!B29:AK29)/COUNT('Tỷ lệ'!B29:AK29) -> 0 | AM29: 0 | AN29: 0 | AO29: =SUM('Tỷ lệ'!$BK$3:CX29)/COUNT('Tỷ lệ'!$BK$3:CX29) -> 0 | AP29: =SUM('Tỷ lệ'!$BK$3:CY29)/COUNT('Tỷ lệ'!$BK$3:CY29) -> 0 | AQ29: =SUM('Tỷ lệ'!$BK$3:CZ29)/COUNT('Tỷ lệ'!$BK$3:CZ29) -> 0 | AR29: =SUM('Tỷ lệ'!$BK$3:DA29)/COUNT('Tỷ lệ'!$BK$3:DA29) -> 0 | AS29: =SUM('Tỷ lệ'!$BK$3:DB29)/COUNT('Tỷ lệ'!$BK$3:DB29) -> 0 | AT29: =SUM('Tỷ lệ'!$BK$3:DC29)/COUNT('Tỷ lệ'!$BK$3:DC29) -> 0 | AU29: =SUM('Tỷ lệ'!$BK$3:DD29)/COUNT('Tỷ lệ'!$BK$3:DD29) -> 0 | AV29: =SUM('Tỷ lệ'!$BK$3:DE29)/COUNT('Tỷ lệ'!$BK$3:DE29) -> 0 | ... BF29: =SUM('Tỷ lệ'!$BK$3:DO29)/COUNT('Tỷ lệ'!$BK$3:DO29) -> 0 | BG29: 0 | BH29: 0 | BI29: 0 | BJ29: 0 | BK29: 0 | BL29: 0 | BM29: 0 | BN29: 0 | BO29: 0 | BP29: 0 | BQ29: 0
A30: NH TMCP Tiên Phong (TPB) | B30: =SUM('Tỷ lệ'!B30:BL30)/COUNT('Tỷ lệ'!B30:BL30) -> 0 | C30: =SUM('Tỷ lệ'!B30:BM30)/COUNT('Tỷ lệ'!B30:BM30) -> 0 | D30: =SUM('Tỷ lệ'!B30:BN30)/COUNT('Tỷ lệ'!B30:BN30) -> 0 | E30: =SUM('Tỷ lệ'!B30:BO30)/COUNT('Tỷ lệ'!B30:BO30) -> 0 | F30: =SUM('Tỷ lệ'!B30:BP30)/COUNT('Tỷ lệ'!B30:BP30) -> 0 | G30: =SUM('Tỷ lệ'!B30:BQ30)/COUNT('Tỷ lệ'!B30:BQ30) -> 0 | H30: =SUM('Tỷ lệ'!B30:BR30)/COUNT('Tỷ lệ'!B30:BR30) -> 0 | I30: =SUM('Tỷ lệ'!B30:BS30)/COUNT('Tỷ lệ'!B30:BS30) -> 0 | J30: =SUM('Tỷ lệ'!B30:BT30)/COUNT('Tỷ lệ'!B30:BT30) -> 0 | K30: =SUM('Tỷ lệ'!B30:BU30)/COUNT('Tỷ lệ'!B30:BU30) -> 0 | L30: =SUM('Tỷ lệ'!B30:BV30)/COUNT('Tỷ lệ'!B30:BV30) -> 0 | M30: =SUM('Tỷ lệ'!B30:BW30)/COUNT('Tỷ lệ'!B30:BW30) -> 0 | N30: =SUM('Tỷ lệ'!B30:BX30)/COUNT('Tỷ lệ'!B30:BX30) -> 0 | O30: =SUM('Tỷ lệ'!B30:BY30)/COUNT('Tỷ lệ'!B30:BY30) -> 0 | P30: =SUM('Tỷ lệ'!B30:BZ30)/COUNT('Tỷ lệ'!B30:BZ30) -> 0 | Q30: =SUM('Tỷ lệ'!B30:CA30)/COUNT('Tỷ lệ'!B30:CA30) -> 0 | R30: =SUM('Tỷ lệ'!B30:CB30)/COUNT('Tỷ lệ'!B30:CB30) -> 0 | S30: 0 | T30: 0 | U30: 0 | V30: 0 | W30: 0 | X30: 0 | Y30: 0 | Z30: 0 | AA30: 0 | AB30: 0 | AC30: 0 | AD30: 0 | AE30: 0 | AF30: 0 | AG30: 0 | AH30: 0 | AI30: 0 | AJ30: 0 | AK30: 0 | AL30: =SUM('Tỷ lệ'!B30:AK30)/COUNT('Tỷ lệ'!B30:AK30) -> 0 | AM30: 0 | AN30: 0 | AO30: =SUM('Tỷ lệ'!$BK$3:CX30)/COUNT('Tỷ lệ'!$BK$3:CX30) -> 0 | AP30: =SUM('Tỷ lệ'!$BK$3:CY30)/COUNT('Tỷ lệ'!$BK$3:CY30) -> 0 | AQ30: =SUM('Tỷ lệ'!$BK$3:CZ30)/COUNT('Tỷ lệ'!$BK$3:CZ30) -> 0 | AR30: =SUM('Tỷ lệ'!$BK$3:DA30)/COUNT('Tỷ lệ'!$BK$3:DA30) -> 0 | AS30: =SUM('Tỷ lệ'!$BK$3:DB30)/COUNT('Tỷ lệ'!$BK$3:DB30) -> 0 | AT30: =SUM('Tỷ lệ'!$BK$3:DC30)/COUNT('Tỷ lệ'!$BK$3:DC30) -> 0 | AU30: =SUM('Tỷ lệ'!$BK$3:DD30)/COUNT('Tỷ lệ'!$BK$3:DD30) -> 0 | AV30: =SUM('Tỷ lệ'!$BK$3:DE30)/COUNT('Tỷ lệ'!$BK$3:DE30) -> 0 | ... BF30: =SUM('Tỷ lệ'!$BK$3:DO30)/COUNT('Tỷ lệ'!$BK$3:DO30) -> 0 | BG30: 0 | BH30: 0 | BI30: 0 | BJ30: 0 | BK30: 0 | BL30: 0 | BM30: 0 | BN30: 0 | BO30: 0 | BP30: 0 | BQ30: 0
A31: NH TMCP Ngoại thương VN (VCB) | B31: =SUM('Tỷ lệ'!B31:BL31)/COUNT('Tỷ lệ'!B31:BL31) -> 0 | C31: =SUM('Tỷ lệ'!B31:BM31)/COUNT('Tỷ lệ'!B31:BM31) -> 0 | D31: =SUM('Tỷ lệ'!B31:BN31)/COUNT('Tỷ lệ'!B31:BN31) -> 0 | E31: =SUM('Tỷ lệ'!B31:BO31)/COUNT('Tỷ lệ'!B31:BO31) -> 0 | F31: =SUM('Tỷ lệ'!B31:BP31)/COUNT('Tỷ lệ'!B31:BP31) -> 0 | G31: =SUM('Tỷ lệ'!B31:BQ31)/COUNT('Tỷ lệ'!B31:BQ31) -> 0 | H31: =SUM('Tỷ lệ'!B31:BR31)/COUNT('Tỷ lệ'!B31:BR31) -> 0 | I31: =SUM('Tỷ lệ'!B31:BS31)/COUNT('Tỷ lệ'!B31:BS31) -> 0 | J31: =SUM('Tỷ lệ'!B31:BT31)/COUNT('Tỷ lệ'!B31:BT31) -> 0 | K31: =SUM('Tỷ lệ'!B31:BU31)/COUNT('Tỷ lệ'!B31:BU31) -> 0 | L31: =SUM('Tỷ lệ'!B31:BV31)/COUNT('Tỷ lệ'!B31:BV31) -> 0 | M31: =SUM('Tỷ lệ'!B31:BW31)/COUNT('Tỷ lệ'!B31:BW31) -> 0 | N31: =SUM('Tỷ lệ'!B31:BX31)/COUNT('Tỷ lệ'!B31:BX31) -> 0 | O31: =SUM('Tỷ lệ'!B31:BY31)/COUNT('Tỷ lệ'!B31:BY31) -> 0 | P31: =SUM('Tỷ lệ'!B31:BZ31)/COUNT('Tỷ lệ'!B31:BZ31) -> 0 | Q31: =SUM('Tỷ lệ'!B31:CA31)/COUNT('Tỷ lệ'!B31:CA31) -> 0 | R31: =SUM('Tỷ lệ'!B31:CB31)/COUNT('Tỷ lệ'!B31:CB31) -> 0 | S31: 0 | T31: 0 | U31: 0 | V31: 0 | W31: 0 | X31: 0 | Y31: 0 | Z31: 0 | AA31: 0 | AB31: 0 | AC31: 0 | AD31: 0 | AE31: 0 | AF31: 0 | AG31: 0 | AH31: 0 | AI31: 0 | AJ31: 0 | AK31: 0 | AL31: =SUM('Tỷ lệ'!B31:AK31)/COUNT('Tỷ lệ'!B31:AK31) -> 0 | AM31: 0 | AN31: 0 | AO31: =SUM('Tỷ lệ'!$BK$3:CX31)/COUNT('Tỷ lệ'!$BK$3:CX31) -> 0 | AP31: =SUM('Tỷ lệ'!$BK$3:CY31)/COUNT('Tỷ lệ'!$BK$3:CY31) -> 0 | AQ31: =SUM('Tỷ lệ'!$BK$3:CZ31)/COUNT('Tỷ lệ'!$BK$3:CZ31) -> 0 | AR31: =SUM('Tỷ lệ'!$BK$3:DA31)/COUNT('Tỷ lệ'!$BK$3:DA31) -> 0 | AS31: =SUM('Tỷ lệ'!$BK$3:DB31)/COUNT('Tỷ lệ'!$BK$3:DB31) -> 0 | AT31: =SUM('Tỷ lệ'!$BK$3:DC31)/COUNT('Tỷ lệ'!$BK$3:DC31) -> 0 | AU31: =SUM('Tỷ lệ'!$BK$3:DD31)/COUNT('Tỷ lệ'!$BK$3:DD31) -> 0 | AV31: =SUM('Tỷ lệ'!$BK$3:DE31)/COUNT('Tỷ lệ'!$BK$3:DE31) -> 0 | ... BF31: =SUM('Tỷ lệ'!$BK$3:DO31)/COUNT('Tỷ lệ'!$BK$3:DO31) -> 0 | BG31: 0 | BH31: 0 | BI31: 0 | BJ31: 0 | BK31: 0 | BL31: 0 | BM31: 0 | BN31: 0 | BO31: 0 | BP31: 0 | BQ31: 0
A32: NH TMCP Việt Á | B32: =SUM('Tỷ lệ'!B32:BL32)/COUNT('Tỷ lệ'!B32:BL32) -> 0 | C32: =SUM('Tỷ lệ'!B32:BM32)/COUNT('Tỷ lệ'!B32:BM32) -> 0 | D32: =SUM('Tỷ lệ'!B32:BN32)/COUNT('Tỷ lệ'!B32:BN32) -> 0 | E32: =SUM('Tỷ lệ'!B32:BO32)/COUNT('Tỷ lệ'!B32:BO32) -> 0 | F32: =SUM('Tỷ lệ'!B32:BP32)/COUNT('Tỷ lệ'!B32:BP32) -> 0 | G32: =SUM('Tỷ lệ'!B32:BQ32)/COUNT('Tỷ lệ'!B32:BQ32) -> 0 | H32: =SUM('Tỷ lệ'!B32:BR32)/COUNT('Tỷ lệ'!B32:BR32) -> 0 | I32: =SUM('Tỷ lệ'!B32:BS32)/COUNT('Tỷ lệ'!B32:BS32) -> 0 | J32: =SUM('Tỷ lệ'!B32:BT32)/COUNT('Tỷ lệ'!B32:BT32) -> 0 | K32: =SUM('Tỷ lệ'!B32:BU32)/COUNT('Tỷ lệ'!B32:BU32) -> 0 | L32: =SUM('Tỷ lệ'!B32:BV32)/COUNT('Tỷ lệ'!B32:BV32) -> 0 | M32: =SUM('Tỷ lệ'!B32:BW32)/COUNT('Tỷ lệ'!B32:BW32) -> 0 | N32: =SUM('Tỷ lệ'!B32:BX32)/COUNT('Tỷ lệ'!B32:BX32) -> 0 | O32: =SUM('Tỷ lệ'!B32:BY32)/COUNT('Tỷ lệ'!B32:BY32) -> 0 | P32: =SUM('Tỷ lệ'!B32:BZ32)/COUNT('Tỷ lệ'!B32:BZ32) -> 0 | Q32: =SUM('Tỷ lệ'!B32:CA32)/COUNT('Tỷ lệ'!B32:CA32) -> 0 | R32: =SUM('Tỷ lệ'!B32:CB32)/COUNT('Tỷ lệ'!B32:CB32) -> 0 | S32: 0 | T32: 0 | U32: 0 | V32: 0 | W32: 0 | X32: 0 | Y32: 0 | Z32: 0 | AA32: 0 | AB32: 0 | AC32: 0 | AD32: 0 | AE32: 0 | AF32: 0 | AG32: 0 | AH32: 0 | AI32: 0 | AJ32: 0 | AK32: 0 | AL32: =SUM('Tỷ lệ'!B32:AK32)/COUNT('Tỷ lệ'!B32:AK32) -> 0 | AM32: 0 | AN32: 0 | AO32: =SUM('Tỷ lệ'!$BK$3:CX32)/COUNT('Tỷ lệ'!$BK$3:CX32) -> 0 | AP32: =SUM('Tỷ lệ'!$BK$3:CY32)/COUNT('Tỷ lệ'!$BK$3:CY32) -> 0 | AQ32: =SUM('Tỷ lệ'!$BK$3:CZ32)/COUNT('Tỷ lệ'!$BK$3:CZ32) -> 0 | AR32: =SUM('Tỷ lệ'!$BK$3:DA32)/COUNT('Tỷ lệ'!$BK$3:DA32) -> 0 | AS32: =SUM('Tỷ lệ'!$BK$3:DB32)/COUNT('Tỷ lệ'!$BK$3:DB32) -> 0 | AT32: =SUM('Tỷ lệ'!$BK$3:DC32)/COUNT('Tỷ lệ'!$BK$3:DC32) -> 0 | AU32: =SUM('Tỷ lệ'!$BK$3:DD32)/COUNT('Tỷ lệ'!$BK$3:DD32) -> 0 | AV32: =SUM('Tỷ lệ'!$BK$3:DE32)/COUNT('Tỷ lệ'!$BK$3:DE32) -> 0 | ... BF32: =SUM('Tỷ lệ'!$BK$3:DO32)/COUNT('Tỷ lệ'!$BK$3:DO32) -> 0 | BG32: 0 | BH32: 0 | BI32: 0 | BJ32: 0 | BK32: 0 | BL32: 0 | BM32: 0 | BN32: 0 | BO32: 0 | BP32: 0 | BQ32: 0
A33: NH TMCP Việt Nam Thương Tín | B33: =SUM('Tỷ lệ'!B33:BL33)/COUNT('Tỷ lệ'!B33:BL33) -> 0 | C33: =SUM('Tỷ lệ'!B33:BM33)/COUNT('Tỷ lệ'!B33:BM33) -> 0 | D33: =SUM('Tỷ lệ'!B33:BN33)/COUNT('Tỷ lệ'!B33:BN33) -> 0 | E33: =SUM('Tỷ lệ'!B33:BO33)/COUNT('Tỷ lệ'!B33:BO33) -> 0 | F33: =SUM('Tỷ lệ'!B33:BP33)/COUNT('Tỷ lệ'!B33:BP33) -> 0 | G33: =SUM('Tỷ lệ'!B33:BQ33)/COUNT('Tỷ lệ'!B33:BQ33) -> 0 | H33: =SUM('Tỷ lệ'!B33:BR33)/COUNT('Tỷ lệ'!B33:BR33) -> 0 | I33: =SUM('Tỷ lệ'!B33:BS33)/COUNT('Tỷ lệ'!B33:BS33) -> 0 | J33: =SUM('Tỷ lệ'!B33:BT33)/COUNT('Tỷ lệ'!B33:BT33) -> 0 | K33: =SUM('Tỷ lệ'!B33:BU33)/COUNT('Tỷ lệ'!B33:BU33) -> 0 | L33: =SUM('Tỷ lệ'!B33:BV33)/COUNT('Tỷ lệ'!B33:BV33) -> 0 | M33: =SUM('Tỷ lệ'!B33:BW33)/COUNT('Tỷ lệ'!B33:BW33) -> 0 | N33: =SUM('Tỷ lệ'!B33:BX33)/COUNT('Tỷ lệ'!B33:BX33) -> 0 | O33: =SUM('Tỷ lệ'!B33:BY33)/COUNT('Tỷ lệ'!B33:BY33) -> 0 | P33: =SUM('Tỷ lệ'!B33:BZ33)/COUNT('Tỷ lệ'!B33:BZ33) -> 0 | Q33: =SUM('Tỷ lệ'!B33:CA33)/COUNT('Tỷ lệ'!B33:CA33) -> 0 | R33: =SUM('Tỷ lệ'!B33:CB33)/COUNT('Tỷ lệ'!B33:CB33) -> 0 | S33: 0 | T33: 0 | U33: 0 | V33: 0 | W33: 0 | X33: 0 | Y33: 0 | Z33: 0 | AA33: 0 | AB33: 0 | AC33: 0 | AD33: 0 | AE33: 0 | AF33: 0 | AG33: 0 | AH33: 0 | AI33: 0 | AJ33: 0 | AK33: 0 | AL33: =SUM('Tỷ lệ'!B33:AK33)/COUNT('Tỷ lệ'!B33:AK33) -> 0 | AM33: 0 | AN33: 0 | AO33: =SUM('Tỷ lệ'!$BK$3:CX33)/COUNT('Tỷ lệ'!$BK$3:CX33) -> 0 | AP33: =SUM('Tỷ lệ'!$BK$3:CY33)/COUNT('Tỷ lệ'!$BK$3:CY33) -> 0 | AQ33: =SUM('Tỷ lệ'!$BK$3:CZ33)/COUNT('Tỷ lệ'!$BK$3:CZ33) -> 0 | AR33: =SUM('Tỷ lệ'!$BK$3:DA33)/COUNT('Tỷ lệ'!$BK$3:DA33) -> 0 | AS33: =SUM('Tỷ lệ'!$BK$3:DB33)/COUNT('Tỷ lệ'!$BK$3:DB33) -> 0 | AT33: =SUM('Tỷ lệ'!$BK$3:DC33)/COUNT('Tỷ lệ'!$BK$3:DC33) -> 0 | AU33: =SUM('Tỷ lệ'!$BK$3:DD33)/COUNT('Tỷ lệ'!$BK$3:DD33) -> 0 | AV33: =SUM('Tỷ lệ'!$BK$3:DE33)/COUNT('Tỷ lệ'!$BK$3:DE33) -> 0 | ... BF33: =SUM('Tỷ lệ'!$BK$3:DO33)/COUNT('Tỷ lệ'!$BK$3:DO33) -> 0 | BG33: 0 | BH33: 0 | BI33: 0 | BJ33: 0 | BK33: 0 | BL33: 0 | BM33: 0 | BN33: 0 | BO33: 0 | BP33: 0 | BQ33: 0
A34: NH TMCP Công thương VN (Vietinbank) | B34: =SUM('Tỷ lệ'!B34:BL34)/COUNT('Tỷ lệ'!B34:BL34) -> 0 | C34: =SUM('Tỷ lệ'!B34:BM34)/COUNT('Tỷ lệ'!B34:BM34) -> 0 | D34: =SUM('Tỷ lệ'!B34:BN34)/COUNT('Tỷ lệ'!B34:BN34) -> 0 | E34: =SUM('Tỷ lệ'!B34:BO34)/COUNT('Tỷ lệ'!B34:BO34) -> 0 | F34: =SUM('Tỷ lệ'!B34:BP34)/COUNT('Tỷ lệ'!B34:BP34) -> 0 | G34: =SUM('Tỷ lệ'!B34:BQ34)/COUNT('Tỷ lệ'!B34:BQ34) -> 0 | H34: =SUM('Tỷ lệ'!B34:BR34)/COUNT('Tỷ lệ'!B34:BR34) -> 0 | I34: =SUM('Tỷ lệ'!B34:BS34)/COUNT('Tỷ lệ'!B34:BS34) -> 0 | J34: =SUM('Tỷ lệ'!B34:BT34)/COUNT('Tỷ lệ'!B34:BT34) -> 0 | K34: =SUM('Tỷ lệ'!B34:BU34)/COUNT('Tỷ lệ'!B34:BU34) -> 0 | L34: =SUM('Tỷ lệ'!B34:BV34)/COUNT('Tỷ lệ'!B34:BV34) -> 0 | M34: =SUM('Tỷ lệ'!B34:BW34)/COUNT('Tỷ lệ'!B34:BW34) -> 0 | N34: =SUM('Tỷ lệ'!B34:BX34)/COUNT('Tỷ lệ'!B34:BX34) -> 0 | O34: =SUM('Tỷ lệ'!B34:BY34)/COUNT('Tỷ lệ'!B34:BY34) -> 0 | P34: =SUM('Tỷ lệ'!B34:BZ34)/COUNT('Tỷ lệ'!B34:BZ34) -> 0 | Q34: =SUM('Tỷ lệ'!B34:CA34)/COUNT('Tỷ lệ'!B34:CA34) -> 0 | R34: =SUM('Tỷ lệ'!B34:CB34)/COUNT('Tỷ lệ'!B34:CB34) -> 0 | S34: 0 | T34: 0 | U34: 0 | V34: 0 | W34: 0 | X34: 0 | Y34: 0 | Z34: 0 | AA34: 0 | AB34: 0 | AC34: 0 | AD34: 0 | AE34: 0 | AF34: 0 | AG34: 0 | AH34: 0 | AI34: 0 | AJ34: 0 | AK34: 0 | AL34: =SUM('Tỷ lệ'!B34:AK34)/COUNT('Tỷ lệ'!B34:AK34) -> 0 | AM34: 0 | AN34: 0 | AO34: =SUM('Tỷ lệ'!$BK$3:CX34)/COUNT('Tỷ lệ'!$BK$3:CX34) -> 0 | AP34: =SUM('Tỷ lệ'!$BK$3:CY34)/COUNT('Tỷ lệ'!$BK$3:CY34) -> 0 | AQ34: =SUM('Tỷ lệ'!$BK$3:CZ34)/COUNT('Tỷ lệ'!$BK$3:CZ34) -> 0 | AR34: =SUM('Tỷ lệ'!$BK$3:DA34)/COUNT('Tỷ lệ'!$BK$3:DA34) -> 0 | AS34: =SUM('Tỷ lệ'!$BK$3:DB34)/COUNT('Tỷ lệ'!$BK$3:DB34) -> 0 | AT34: =SUM('Tỷ lệ'!$BK$3:DC34)/COUNT('Tỷ lệ'!$BK$3:DC34) -> 0 | AU34: =SUM('Tỷ lệ'!$BK$3:DD34)/COUNT('Tỷ lệ'!$BK$3:DD34) -> 0 | AV34: =SUM('Tỷ lệ'!$BK$3:DE34)/COUNT('Tỷ lệ'!$BK$3:DE34) -> 0 | ... BF34: =SUM('Tỷ lệ'!$BK$3:DO34)/COUNT('Tỷ lệ'!$BK$3:DO34) -> 0 | BG34: 0 | BH34: 0 | BI34: 0 | BJ34: 0 | BK34: 0 | BL34: 0 | BM34: 0 | BN34: 0 | BO34: 0 | BP34: 0 | BQ34: 0
A35: BaoViet Bank | B35: =SUM('Tỷ lệ'!B35:BL35)/COUNT('Tỷ lệ'!B35:BL35) -> 0 | C35: =SUM('Tỷ lệ'!B35:BM35)/COUNT('Tỷ lệ'!B35:BM35) -> 0 | D35: =SUM('Tỷ lệ'!B35:BN35)/COUNT('Tỷ lệ'!B35:BN35) -> 0 | E35: =SUM('Tỷ lệ'!B35:BO35)/COUNT('Tỷ lệ'!B35:BO35) -> 0 | F35: =SUM('Tỷ lệ'!B35:BP35)/COUNT('Tỷ lệ'!B35:BP35) -> 0 | G35: =SUM('Tỷ lệ'!B35:BQ35)/COUNT('Tỷ lệ'!B35:BQ35) -> 0 | H35: =SUM('Tỷ lệ'!B35:BR35)/COUNT('Tỷ lệ'!B35:BR35) -> 0 | I35: =SUM('Tỷ lệ'!B35:BS35)/COUNT('Tỷ lệ'!B35:BS35) -> 0 | J35: =SUM('Tỷ lệ'!B35:BT35)/COUNT('Tỷ lệ'!B35:BT35) -> 0 | K35: =SUM('Tỷ lệ'!B35:BU35)/COUNT('Tỷ lệ'!B35:BU35) -> 0 | L35: =SUM('Tỷ lệ'!B35:BV35)/COUNT('Tỷ lệ'!B35:BV35) -> 0 | M35: =SUM('Tỷ lệ'!B35:BW35)/COUNT('Tỷ lệ'!B35:BW35) -> 0 | N35: =SUM('Tỷ lệ'!B35:BX35)/COUNT('Tỷ lệ'!B35:BX35) -> 0 | O35: =SUM('Tỷ lệ'!B35:BY35)/COUNT('Tỷ lệ'!B35:BY35) -> 0 | P35: =SUM('Tỷ lệ'!B35:BZ35)/COUNT('Tỷ lệ'!B35:BZ35) -> 0 | Q35: =SUM('Tỷ lệ'!B35:CA35)/COUNT('Tỷ lệ'!B35:CA35) -> 0 | R35: =SUM('Tỷ lệ'!B35:CB35)/COUNT('Tỷ lệ'!B35:CB35) -> 0 | S35: 0 | T35: 0 | U35: 0 | V35: 0 | W35: 0 | X35: 0 | Y35: 0 | Z35: 0 | AA35: 0 | AB35: 0 | AC35: 0 | AD35: 0 | AE35: 0 | AF35: 0 | AG35: 0 | AH35: 0 | AI35: 0 | AJ35: 0 | AK35: 0 | AL35: =SUM('Tỷ lệ'!B35:AK35)/COUNT('Tỷ lệ'!B35:AK35) -> 0 | AM35: 0 | AN35: 0 | AO35: =SUM('Tỷ lệ'!$BK$3:CX35)/COUNT('Tỷ lệ'!$BK$3:CX35) -> 0 | AP35: =SUM('Tỷ lệ'!$BK$3:CY35)/COUNT('Tỷ lệ'!$BK$3:CY35) -> 0 | AQ35: =SUM('Tỷ lệ'!$BK$3:CZ35)/COUNT('Tỷ lệ'!$BK$3:CZ35) -> 0 | AR35: =SUM('Tỷ lệ'!$BK$3:DA35)/COUNT('Tỷ lệ'!$BK$3:DA35) -> 0 | AS35: =SUM('Tỷ lệ'!$BK$3:DB35)/COUNT('Tỷ lệ'!$BK$3:DB35) -> 0 | AT35: =SUM('Tỷ lệ'!$BK$3:DC35)/COUNT('Tỷ lệ'!$BK$3:DC35) -> 0 | AU35: =SUM('Tỷ lệ'!$BK$3:DD35)/COUNT('Tỷ lệ'!$BK$3:DD35) -> 0 | AV35: =SUM('Tỷ lệ'!$BK$3:DE35)/COUNT('Tỷ lệ'!$BK$3:DE35) -> 0 | ... BF35: =SUM('Tỷ lệ'!$BK$3:DO35)/COUNT('Tỷ lệ'!$BK$3:DO35) -> 0 | BG35: 0 | BH35: 0 | BI35: 0 | BJ35: 0 | BK35: 0 | BL35: 0 | BM35: 0 | BN35: 0 | BO35: 0 | BP35: 0 | BQ35: 0

Sheet Tỷ lệ
A1: Tên khách hàng
B2: 45597 | C2: 45598 | D2: 45599 | E2: 45600 | F2: 45601 | G2: 45602 | H2: 45603 | I2: 45604 | J2: 45605 | K2: 45606 | L2: 45607 | M2: 45608 | N2: 45609 | O2: 45610 | P2: 45611 | Q2: 45612 | R2: 45613 | S2: 45614 | T2: 45615 | U2: 45616 | V2: 45617 | W2: 45618 | X2: 45619 | Y2: 45620 | Z2: 45621 | AA2: 45622 | AB2: 45623 | AC2: 45624 | AD2: 45625 | AE2: 45626 | AF2: 45627 | AG2: 45628 | AH2: 45629 | AI2: 45630 | AJ2: 45631 | AK2: 45632 | AL2: 45633 | AM2: 45634 | AN2: 45635 | AO2: 45636 | AP2: 45637 | AQ2: 45638 | AR2: 45639 | AS2: 45640 | AT2: 45641 | AU2: 45642 | AV2: 45643 | AW2: 45644 | AX2: 45645 | AY2: 45646 | AZ2: 45647 | BA2: 45648 | BB2: 45649 | BC2: 45650 | BD2: 45651 | BE2: 45652 | BF2: 45653 | BG2: 45654 | BH2: 45655 | BI2: 45656 | BJ2: 45657 | BK2: ='Giá trị'!BK2 -> 45659 | BL2: ='Giá trị'!BL2 -> 45660 | BM2: ='Giá trị'!BM2 -> 45663 | BN2: ='Giá trị'!BN2 -> 45664 | BO2: ='Giá trị'!BO2 -> 45665 | BP2: ='Giá trị'!BP2 -> 45666 | BQ2: ='Giá trị'!BQ2 -> 45667 | BR2: ='Giá trị'!BR2 -> 45670 | ... DZ2: ='Giá trị'!DZ2 -> 45763 | EA2: Ngày báo cáo (T-1)
A3: NH NN&PTNT VN (Agribank) | B3: =IF('Giá trị'!B3=0,0%,'Giá trị'!B3/'Giá trị'!B$36) -> 0 | C3: =IF('Giá trị'!C3=0,0%,'Giá trị'!C3/'Giá trị'!C$36) -> 0 | D3: =IF('Giá trị'!D3=0,0%,'Giá trị'!D3/'Giá trị'!D$36) -> 0 | E3: =IF('Giá trị'!E3=0,0%,'Giá trị'!E3/'Giá trị'!E$36) -> 0 | F3: =IF('Giá trị'!F3=0,0%,'Giá trị'!F3/'Giá trị'!F$36) -> 0 | G3: =IF('Giá trị'!G3=0,0%,'Giá trị'!G3/'Giá trị'!G$36) -> 0 | H3: =IF('Giá trị'!H3=0,0%,'Giá trị'!H3/'Giá trị'!H$36) -> 0 | I3: =IF('Giá trị'!I3=0,0%,'Giá trị'!I3/'Giá trị'!I$36) -> 0 | ... DZ3: =IF('Giá trị'!DZ3=0,0%,'Giá trị'!DZ3/'Giá trị'!DZ$36) -> 0 | EA3: = Giá trị giao dịch tại Sheet "Giá trị" của từng đối tác / Tổng giá trị giao dịch trong ngày
